22:36 08-09-2025

# Get in right directory

# Get up to date
Already up to date.

# Run main file
Done


23:01 08-09-2025

# Get in right directory

# Get up to date
Already up to date.

# Run main file
Traceback (most recent call last):
  File "/usr/lib/python3/dist-packages/urllib3/connectionpool.py", line 666, in urlopen
    httplib_response = self._make_request(
  File "/usr/lib/python3/dist-packages/urllib3/connectionpool.py", line 377, in _make_request
    self._validate_conn(conn)
  File "/usr/lib/python3/dist-packages/urllib3/connectionpool.py", line 1001, in _validate_conn
    conn.connect()
  File "/usr/lib/python3/dist-packages/urllib3/connection.py", line 366, in connect
    self.sock = ssl_wrap_socket(
  File "/usr/lib/python3/dist-packages/urllib3/util/ssl_.py", line 370, in ssl_wrap_socket
    return context.wrap_socket(sock, server_hostname=server_hostname)
  File "/usr/lib/python3.8/ssl.py", line 500, in wrap_socket
    return self.sslsocket_class._create(
  File "/usr/lib/python3.8/ssl.py", line 1069, in _create
    self.do_handshake()
  File "/usr/lib/python3.8/ssl.py", line 1338, in do_handshake
    self._sslobj.do_handshake()
ssl.SSLEOFError: EOF occurred in violation of protocol (_ssl.c:1145)

During handling of the above exception, another exception occurred:

Traceback (most recent call last):
  File "/usr/lib/python3/dist-packages/requests/adapters.py", line 439, in send
    resp = conn.urlopen(
  File "/usr/lib/python3/dist-packages/urllib3/connectionpool.py", line 720, in urlopen
    retries = retries.increment(
  File "/usr/lib/python3/dist-packages/urllib3/util/retry.py", line 438, in increment
    raise MaxRetryError(_pool, url, error or ResponseError(cause))
urllib3.exceptions.MaxRetryError: HTTPSConnectionPool(host='elo.somtoday.nl', port=443): Max retries exceeded with url: /services/webdav/calendarfeed/58405be0-5611-4aba-be66-9894a1009f12/4fc988ad-6d4d-4c2a-aaf0-8207665bf69b (Caused by SSLError(SSLEOFError(8, 'EOF occurred in violation of protocol (_ssl.c:1145)')))

During handling of the above exception, another exception occurred:

Traceback (most recent call last):
  File "/home/laurens/Somtoday_Agendas/Laurens/main.py", line 22, in <module>
    r = requests.get(url, allow_redirects=True)
  File "/usr/lib/python3/dist-packages/requests/api.py", line 75, in get
    return request('get', url, params=params, **kwargs)
  File "/usr/lib/python3/dist-packages/requests/api.py", line 60, in request
    return session.request(method=method, url=url, **kwargs)
  File "/usr/lib/python3/dist-packages/requests/sessions.py", line 535, in request
    resp = self.send(prep, **send_kwargs)
  File "/usr/lib/python3/dist-packages/requests/sessions.py", line 648, in send
    r = adapter.send(request, **kwargs)
  File "/usr/lib/python3/dist-packages/requests/adapters.py", line 514, in send
    raise SSLError(e, request=request)
requests.exceptions.SSLError: HTTPSConnectionPool(host='elo.somtoday.nl', port=443): Max retries exceeded with url: /services/webdav/calendarfeed/58405be0-5611-4aba-be66-9894a1009f12/4fc988ad-6d4d-4c2a-aaf0-8207665bf69b (Caused by SSLError(SSLEOFError(8, 'EOF occurred in violation of protocol (_ssl.c:1145)')))
Done


