22:36 08-09-2025

# Get in right directory

# Get up to date
Already up to date.

# Run main file
Done


23:01 08-09-2025

# Get in right directory

# Get up to date
Already up to date.

# Run main file
Traceback (most recent call last):
  File "/usr/lib/python3/dist-packages/urllib3/connectionpool.py", line 666, in urlopen
    httplib_response = self._make_request(
  File "/usr/lib/python3/dist-packages/urllib3/connectionpool.py", line 377, in _make_request
    self._validate_conn(conn)
  File "/usr/lib/python3/dist-packages/urllib3/connectionpool.py", line 1001, in _validate_conn
    conn.connect()
  File "/usr/lib/python3/dist-packages/urllib3/connection.py", line 366, in connect
    self.sock = ssl_wrap_socket(
  File "/usr/lib/python3/dist-packages/urllib3/util/ssl_.py", line 370, in ssl_wrap_socket
    return context.wrap_socket(sock, server_hostname=server_hostname)
  File "/usr/lib/python3.8/ssl.py", line 500, in wrap_socket
    return self.sslsocket_class._create(
  File "/usr/lib/python3.8/ssl.py", line 1069, in _create
    self.do_handshake()
  File "/usr/lib/python3.8/ssl.py", line 1338, in do_handshake
    self._sslobj.do_handshake()
ssl.SSLEOFError: EOF occurred in violation of protocol (_ssl.c:1145)

During handling of the above exception, another exception occurred:

Traceback (most recent call last):
  File "/usr/lib/python3/dist-packages/requests/adapters.py", line 439, in send
    resp = conn.urlopen(
  File "/usr/lib/python3/dist-packages/urllib3/connectionpool.py", line 720, in urlopen
    retries = retries.increment(
  File "/usr/lib/python3/dist-packages/urllib3/util/retry.py", line 438, in increment
    raise MaxRetryError(_pool, url, error or ResponseError(cause))
urllib3.exceptions.MaxRetryError: HTTPSConnectionPool(host='elo.somtoday.nl', port=443): Max retries exceeded with url: /services/webdav/calendarfeed/58405be0-5611-4aba-be66-9894a1009f12/4fc988ad-6d4d-4c2a-aaf0-8207665bf69b (Caused by SSLError(SSLEOFError(8, 'EOF occurred in violation of protocol (_ssl.c:1145)')))

During handling of the above exception, another exception occurred:

Traceback (most recent call last):
  File "/home/laurens/Somtoday_Agendas/Laurens/main.py", line 22, in <module>
    r = requests.get(url, allow_redirects=True)
  File "/usr/lib/python3/dist-packages/requests/api.py", line 75, in get
    return request('get', url, params=params, **kwargs)
  File "/usr/lib/python3/dist-packages/requests/api.py", line 60, in request
    return session.request(method=method, url=url, **kwargs)
  File "/usr/lib/python3/dist-packages/requests/sessions.py", line 535, in request
    resp = self.send(prep, **send_kwargs)
  File "/usr/lib/python3/dist-packages/requests/sessions.py", line 648, in send
    r = adapter.send(request, **kwargs)
  File "/usr/lib/python3/dist-packages/requests/adapters.py", line 514, in send
    raise SSLError(e, request=request)
requests.exceptions.SSLError: HTTPSConnectionPool(host='elo.somtoday.nl', port=443): Max retries exceeded with url: /services/webdav/calendarfeed/58405be0-5611-4aba-be66-9894a1009f12/4fc988ad-6d4d-4c2a-aaf0-8207665bf69b (Caused by SSLError(SSLEOFError(8, 'EOF occurred in violation of protocol (_ssl.c:1145)')))
Done


23:30 08-09-2025

# Get in right directory

# Get up to date
Already up to date.

# Run main file
The file does not exist
Done


00:00 09-09-2025

# Get in right directory

# Get up to date
Already up to date.

# Run main file
Done


00:30 09-09-2025

# Get in right directory

# Get up to date
Already up to date.

# Run main file
Done


01:00 09-09-2025

# Get in right directory

# Get up to date
Already up to date.

# Run main file
Done


01:30 09-09-2025

# Get in right directory

# Get up to date
Already up to date.

# Run main file
Done


02:00 09-09-2025

# Get in right directory

# Get up to date
Already up to date.

# Run main file
Done


02:30 09-09-2025

# Get in right directory

# Get up to date
Already up to date.

# Run main file
Done


03:00 09-09-2025

# Get in right directory

# Get up to date
Already up to date.

# Run main file
Done


03:30 09-09-2025

# Get in right directory

# Get up to date
Already up to date.

# Run main file
Done


04:00 09-09-2025

# Get in right directory

# Get up to date
Already up to date.

# Run main file
Done


04:30 09-09-2025

# Get in right directory

# Get up to date
Already up to date.

# Run main file
Done


05:00 09-09-2025

# Get in right directory

# Get up to date
Already up to date.

# Run main file
Done


05:30 09-09-2025

# Get in right directory

# Get up to date
Already up to date.

# Run main file
Done


06:00 09-09-2025

# Get in right directory

# Get up to date
Already up to date.

# Run main file
Done


06:30 09-09-2025

# Get in right directory

# Get up to date
Already up to date.

# Run main file
Done


07:00 09-09-2025

# Get in right directory

# Get up to date
Already up to date.

# Run main file
Done


07:30 09-09-2025

# Get in right directory

# Get up to date
Already up to date.

# Run main file
Done


08:00 09-09-2025

# Get in right directory

# Get up to date
Already up to date.

# Run main file
Done


08:30 09-09-2025

# Get in right directory

# Get up to date
Already up to date.

# Run main file
Done


09:00 09-09-2025

# Get in right directory

# Get up to date
Already up to date.

# Run main file
Done


09:30 09-09-2025

# Get in right directory

# Get up to date
Already up to date.

# Run main file
Done


10:00 09-09-2025

# Get in right directory

# Get up to date
Already up to date.

# Run main file
Done


10:30 09-09-2025

# Get in right directory

# Get up to date
fatal: unable to access 'https://github.com/LaurensGamet/Somtoday_Agendas/': Could not resolve host: github.com

# Run main file
Traceback (most recent call last):
  File "/usr/lib/python3/dist-packages/urllib3/connection.py", line 159, in _new_conn
    conn = connection.create_connection(
  File "/usr/lib/python3/dist-packages/urllib3/util/connection.py", line 61, in create_connection
    for res in socket.getaddrinfo(host, port, family, socket.SOCK_STREAM):
  File "/usr/lib/python3.8/socket.py", line 918, in getaddrinfo
    for res in _socket.getaddrinfo(host, port, family, type, proto, flags):
socket.gaierror: [Errno -3] Temporary failure in name resolution

During handling of the above exception, another exception occurred:

Traceback (most recent call last):
  File "/usr/lib/python3/dist-packages/urllib3/connectionpool.py", line 666, in urlopen
    httplib_response = self._make_request(
  File "/usr/lib/python3/dist-packages/urllib3/connectionpool.py", line 377, in _make_request
    self._validate_conn(conn)
  File "/usr/lib/python3/dist-packages/urllib3/connectionpool.py", line 1001, in _validate_conn
    conn.connect()
  File "/usr/lib/python3/dist-packages/urllib3/connection.py", line 314, in connect
    conn = self._new_conn()
  File "/usr/lib/python3/dist-packages/urllib3/connection.py", line 171, in _new_conn
    raise NewConnectionError(
urllib3.exceptions.NewConnectionError: <urllib3.connection.VerifiedHTTPSConnection object at 0x7f9111d4f940>: Failed to establish a new connection: [Errno -3] Temporary failure in name resolution

During handling of the above exception, another exception occurred:

Traceback (most recent call last):
  File "/usr/lib/python3/dist-packages/requests/adapters.py", line 439, in send
    resp = conn.urlopen(
  File "/usr/lib/python3/dist-packages/urllib3/connectionpool.py", line 720, in urlopen
    retries = retries.increment(
  File "/usr/lib/python3/dist-packages/urllib3/util/retry.py", line 438, in increment
    raise MaxRetryError(_pool, url, error or ResponseError(cause))
urllib3.exceptions.MaxRetryError: HTTPSConnectionPool(host='elo.somtoday.nl', port=443): Max retries exceeded with url: /services/webdav/calendarfeed/58405be0-5611-4aba-be66-9894a1009f12/4fc988ad-6d4d-4c2a-aaf0-8207665bf69b (Caused by NewConnectionError('<urllib3.connection.VerifiedHTTPSConnection object at 0x7f9111d4f940>: Failed to establish a new connection: [Errno -3] Temporary failure in name resolution'))

During handling of the above exception, another exception occurred:

Traceback (most recent call last):
  File "/home/laurens/Somtoday_Agendas/Laurens/main.py", line 22, in <module>
    r = requests.get(url, allow_redirects=True)
  File "/usr/lib/python3/dist-packages/requests/api.py", line 75, in get
    return request('get', url, params=params, **kwargs)
  File "/usr/lib/python3/dist-packages/requests/api.py", line 60, in request
    return session.request(method=method, url=url, **kwargs)
  File "/usr/lib/python3/dist-packages/requests/sessions.py", line 535, in request
    resp = self.send(prep, **send_kwargs)
  File "/usr/lib/python3/dist-packages/requests/sessions.py", line 648, in send
    r = adapter.send(request, **kwargs)
  File "/usr/lib/python3/dist-packages/requests/adapters.py", line 516, in send
    raise ConnectionError(e, request=request)
requests.exceptions.ConnectionError: HTTPSConnectionPool(host='elo.somtoday.nl', port=443): Max retries exceeded with url: /services/webdav/calendarfeed/58405be0-5611-4aba-be66-9894a1009f12/4fc988ad-6d4d-4c2a-aaf0-8207665bf69b (Caused by NewConnectionError('<urllib3.connection.VerifiedHTTPSConnection object at 0x7f9111d4f940>: Failed to establish a new connection: [Errno -3] Temporary failure in name resolution'))
Done


11:00 09-09-2025

# Get in right directory

# Get up to date
fatal: unable to access 'https://github.com/LaurensGamet/Somtoday_Agendas/': Could not resolve host: github.com

# Run main file
The file does not exist
Traceback (most recent call last):
  File "/usr/lib/python3/dist-packages/urllib3/connection.py", line 159, in _new_conn
    conn = connection.create_connection(
  File "/usr/lib/python3/dist-packages/urllib3/util/connection.py", line 61, in create_connection
    for res in socket.getaddrinfo(host, port, family, socket.SOCK_STREAM):
  File "/usr/lib/python3.8/socket.py", line 918, in getaddrinfo
    for res in _socket.getaddrinfo(host, port, family, type, proto, flags):
socket.gaierror: [Errno -3] Temporary failure in name resolution

During handling of the above exception, another exception occurred:

Traceback (most recent call last):
  File "/usr/lib/python3/dist-packages/urllib3/connectionpool.py", line 666, in urlopen
    httplib_response = self._make_request(
  File "/usr/lib/python3/dist-packages/urllib3/connectionpool.py", line 377, in _make_request
    self._validate_conn(conn)
  File "/usr/lib/python3/dist-packages/urllib3/connectionpool.py", line 1001, in _validate_conn
    conn.connect()
  File "/usr/lib/python3/dist-packages/urllib3/connection.py", line 314, in connect
    conn = self._new_conn()
  File "/usr/lib/python3/dist-packages/urllib3/connection.py", line 171, in _new_conn
    raise NewConnectionError(
urllib3.exceptions.NewConnectionError: <urllib3.connection.VerifiedHTTPSConnection object at 0x7f58e2ca9940>: Failed to establish a new connection: [Errno -3] Temporary failure in name resolution

During handling of the above exception, another exception occurred:

Traceback (most recent call last):
  File "/usr/lib/python3/dist-packages/requests/adapters.py", line 439, in send
    resp = conn.urlopen(
  File "/usr/lib/python3/dist-packages/urllib3/connectionpool.py", line 720, in urlopen
    retries = retries.increment(
  File "/usr/lib/python3/dist-packages/urllib3/util/retry.py", line 438, in increment
    raise MaxRetryError(_pool, url, error or ResponseError(cause))
urllib3.exceptions.MaxRetryError: HTTPSConnectionPool(host='elo.somtoday.nl', port=443): Max retries exceeded with url: /services/webdav/calendarfeed/58405be0-5611-4aba-be66-9894a1009f12/4fc988ad-6d4d-4c2a-aaf0-8207665bf69b (Caused by NewConnectionError('<urllib3.connection.VerifiedHTTPSConnection object at 0x7f58e2ca9940>: Failed to establish a new connection: [Errno -3] Temporary failure in name resolution'))

During handling of the above exception, another exception occurred:

Traceback (most recent call last):
  File "/home/laurens/Somtoday_Agendas/Laurens/main.py", line 22, in <module>
    r = requests.get(url, allow_redirects=True)
  File "/usr/lib/python3/dist-packages/requests/api.py", line 75, in get
    return request('get', url, params=params, **kwargs)
  File "/usr/lib/python3/dist-packages/requests/api.py", line 60, in request
    return session.request(method=method, url=url, **kwargs)
  File "/usr/lib/python3/dist-packages/requests/sessions.py", line 535, in request
    resp = self.send(prep, **send_kwargs)
  File "/usr/lib/python3/dist-packages/requests/sessions.py", line 648, in send
    r = adapter.send(request, **kwargs)
  File "/usr/lib/python3/dist-packages/requests/adapters.py", line 516, in send
    raise ConnectionError(e, request=request)
requests.exceptions.ConnectionError: HTTPSConnectionPool(host='elo.somtoday.nl', port=443): Max retries exceeded with url: /services/webdav/calendarfeed/58405be0-5611-4aba-be66-9894a1009f12/4fc988ad-6d4d-4c2a-aaf0-8207665bf69b (Caused by NewConnectionError('<urllib3.connection.VerifiedHTTPSConnection object at 0x7f58e2ca9940>: Failed to establish a new connection: [Errno -3] Temporary failure in name resolution'))
Done


11:30 09-09-2025

# Get in right directory

# Get up to date
fatal: unable to access 'https://github.com/LaurensGamet/Somtoday_Agendas/': Could not resolve host: github.com

# Run main file
The file does not exist
Traceback (most recent call last):
  File "/usr/lib/python3/dist-packages/urllib3/connection.py", line 159, in _new_conn
    conn = connection.create_connection(
  File "/usr/lib/python3/dist-packages/urllib3/util/connection.py", line 61, in create_connection
    for res in socket.getaddrinfo(host, port, family, socket.SOCK_STREAM):
  File "/usr/lib/python3.8/socket.py", line 918, in getaddrinfo
    for res in _socket.getaddrinfo(host, port, family, type, proto, flags):
socket.gaierror: [Errno -3] Temporary failure in name resolution

During handling of the above exception, another exception occurred:

Traceback (most recent call last):
  File "/usr/lib/python3/dist-packages/urllib3/connectionpool.py", line 666, in urlopen
    httplib_response = self._make_request(
  File "/usr/lib/python3/dist-packages/urllib3/connectionpool.py", line 377, in _make_request
    self._validate_conn(conn)
  File "/usr/lib/python3/dist-packages/urllib3/connectionpool.py", line 1001, in _validate_conn
    conn.connect()
  File "/usr/lib/python3/dist-packages/urllib3/connection.py", line 314, in connect
    conn = self._new_conn()
  File "/usr/lib/python3/dist-packages/urllib3/connection.py", line 171, in _new_conn
    raise NewConnectionError(
urllib3.exceptions.NewConnectionError: <urllib3.connection.VerifiedHTTPSConnection object at 0x7fc25189b940>: Failed to establish a new connection: [Errno -3] Temporary failure in name resolution

During handling of the above exception, another exception occurred:

Traceback (most recent call last):
  File "/usr/lib/python3/dist-packages/requests/adapters.py", line 439, in send
    resp = conn.urlopen(
  File "/usr/lib/python3/dist-packages/urllib3/connectionpool.py", line 720, in urlopen
    retries = retries.increment(
  File "/usr/lib/python3/dist-packages/urllib3/util/retry.py", line 438, in increment
    raise MaxRetryError(_pool, url, error or ResponseError(cause))
urllib3.exceptions.MaxRetryError: HTTPSConnectionPool(host='elo.somtoday.nl', port=443): Max retries exceeded with url: /services/webdav/calendarfeed/58405be0-5611-4aba-be66-9894a1009f12/4fc988ad-6d4d-4c2a-aaf0-8207665bf69b (Caused by NewConnectionError('<urllib3.connection.VerifiedHTTPSConnection object at 0x7fc25189b940>: Failed to establish a new connection: [Errno -3] Temporary failure in name resolution'))

During handling of the above exception, another exception occurred:

Traceback (most recent call last):
  File "/home/laurens/Somtoday_Agendas/Laurens/main.py", line 22, in <module>
    r = requests.get(url, allow_redirects=True)
  File "/usr/lib/python3/dist-packages/requests/api.py", line 75, in get
    return request('get', url, params=params, **kwargs)
  File "/usr/lib/python3/dist-packages/requests/api.py", line 60, in request
    return session.request(method=method, url=url, **kwargs)
  File "/usr/lib/python3/dist-packages/requests/sessions.py", line 535, in request
    resp = self.send(prep, **send_kwargs)
  File "/usr/lib/python3/dist-packages/requests/sessions.py", line 648, in send
    r = adapter.send(request, **kwargs)
  File "/usr/lib/python3/dist-packages/requests/adapters.py", line 516, in send
    raise ConnectionError(e, request=request)
requests.exceptions.ConnectionError: HTTPSConnectionPool(host='elo.somtoday.nl', port=443): Max retries exceeded with url: /services/webdav/calendarfeed/58405be0-5611-4aba-be66-9894a1009f12/4fc988ad-6d4d-4c2a-aaf0-8207665bf69b (Caused by NewConnectionError('<urllib3.connection.VerifiedHTTPSConnection object at 0x7fc25189b940>: Failed to establish a new connection: [Errno -3] Temporary failure in name resolution'))
Done


