22:36 08-09-2025

# Get in right directory

# Get up to date
Already up to date.

# Run main file
Done


23:01 08-09-2025

# Get in right directory

# Get up to date
Already up to date.

# Run main file
Traceback (most recent call last):
  File "/usr/lib/python3/dist-packages/urllib3/connectionpool.py", line 666, in urlopen
    httplib_response = self._make_request(
  File "/usr/lib/python3/dist-packages/urllib3/connectionpool.py", line 377, in _make_request
    self._validate_conn(conn)
  File "/usr/lib/python3/dist-packages/urllib3/connectionpool.py", line 1001, in _validate_conn
    conn.connect()
  File "/usr/lib/python3/dist-packages/urllib3/connection.py", line 366, in connect
    self.sock = ssl_wrap_socket(
  File "/usr/lib/python3/dist-packages/urllib3/util/ssl_.py", line 370, in ssl_wrap_socket
    return context.wrap_socket(sock, server_hostname=server_hostname)
  File "/usr/lib/python3.8/ssl.py", line 500, in wrap_socket
    return self.sslsocket_class._create(
  File "/usr/lib/python3.8/ssl.py", line 1069, in _create
    self.do_handshake()
  File "/usr/lib/python3.8/ssl.py", line 1338, in do_handshake
    self._sslobj.do_handshake()
ssl.SSLEOFError: EOF occurred in violation of protocol (_ssl.c:1145)

During handling of the above exception, another exception occurred:

Traceback (most recent call last):
  File "/usr/lib/python3/dist-packages/requests/adapters.py", line 439, in send
    resp = conn.urlopen(
  File "/usr/lib/python3/dist-packages/urllib3/connectionpool.py", line 720, in urlopen
    retries = retries.increment(
  File "/usr/lib/python3/dist-packages/urllib3/util/retry.py", line 438, in increment
    raise MaxRetryError(_pool, url, error or ResponseError(cause))
urllib3.exceptions.MaxRetryError: HTTPSConnectionPool(host='elo.somtoday.nl', port=443): Max retries exceeded with url: /services/webdav/calendarfeed/58405be0-5611-4aba-be66-9894a1009f12/4fc988ad-6d4d-4c2a-aaf0-8207665bf69b (Caused by SSLError(SSLEOFError(8, 'EOF occurred in violation of protocol (_ssl.c:1145)')))

During handling of the above exception, another exception occurred:

Traceback (most recent call last):
  File "/home/laurens/Somtoday_Agendas/Laurens/main.py", line 22, in <module>
    r = requests.get(url, allow_redirects=True)
  File "/usr/lib/python3/dist-packages/requests/api.py", line 75, in get
    return request('get', url, params=params, **kwargs)
  File "/usr/lib/python3/dist-packages/requests/api.py", line 60, in request
    return session.request(method=method, url=url, **kwargs)
  File "/usr/lib/python3/dist-packages/requests/sessions.py", line 535, in request
    resp = self.send(prep, **send_kwargs)
  File "/usr/lib/python3/dist-packages/requests/sessions.py", line 648, in send
    r = adapter.send(request, **kwargs)
  File "/usr/lib/python3/dist-packages/requests/adapters.py", line 514, in send
    raise SSLError(e, request=request)
requests.exceptions.SSLError: HTTPSConnectionPool(host='elo.somtoday.nl', port=443): Max retries exceeded with url: /services/webdav/calendarfeed/58405be0-5611-4aba-be66-9894a1009f12/4fc988ad-6d4d-4c2a-aaf0-8207665bf69b (Caused by SSLError(SSLEOFError(8, 'EOF occurred in violation of protocol (_ssl.c:1145)')))
Done


23:30 08-09-2025

# Get in right directory

# Get up to date
Already up to date.

# Run main file
The file does not exist
Done


00:00 09-09-2025

# Get in right directory

# Get up to date
Already up to date.

# Run main file
Done


00:30 09-09-2025

# Get in right directory

# Get up to date
Already up to date.

# Run main file
Done


01:00 09-09-2025

# Get in right directory

# Get up to date
Already up to date.

# Run main file
Done


01:30 09-09-2025

# Get in right directory

# Get up to date
Already up to date.

# Run main file
Done


02:00 09-09-2025

# Get in right directory

# Get up to date
Already up to date.

# Run main file
Done


02:30 09-09-2025

# Get in right directory

# Get up to date
Already up to date.

# Run main file
Done


03:00 09-09-2025

# Get in right directory

# Get up to date
Already up to date.

# Run main file
Done


03:30 09-09-2025

# Get in right directory

# Get up to date
Already up to date.

# Run main file
Done


04:00 09-09-2025

# Get in right directory

# Get up to date
Already up to date.

# Run main file
Done


04:30 09-09-2025

# Get in right directory

# Get up to date
Already up to date.

# Run main file
Done


05:00 09-09-2025

# Get in right directory

# Get up to date
Already up to date.

# Run main file
Done


05:30 09-09-2025

# Get in right directory

# Get up to date
Already up to date.

# Run main file
Done


06:00 09-09-2025

# Get in right directory

# Get up to date
Already up to date.

# Run main file
Done


06:30 09-09-2025

# Get in right directory

# Get up to date
Already up to date.

# Run main file
Done


07:00 09-09-2025

# Get in right directory

# Get up to date
Already up to date.

# Run main file
Done


07:30 09-09-2025

# Get in right directory

# Get up to date
Already up to date.

# Run main file
Done


08:00 09-09-2025

# Get in right directory

# Get up to date
Already up to date.

# Run main file
Done


08:30 09-09-2025

# Get in right directory

# Get up to date
Already up to date.

# Run main file
Done


09:00 09-09-2025

# Get in right directory

# Get up to date
Already up to date.

# Run main file
Done


09:30 09-09-2025

# Get in right directory

# Get up to date
Already up to date.

# Run main file
Done


10:00 09-09-2025

# Get in right directory

# Get up to date
Already up to date.

# Run main file
Done


10:30 09-09-2025

# Get in right directory

# Get up to date
fatal: unable to access 'https://github.com/LaurensGamet/Somtoday_Agendas/': Could not resolve host: github.com

# Run main file
Traceback (most recent call last):
  File "/usr/lib/python3/dist-packages/urllib3/connection.py", line 159, in _new_conn
    conn = connection.create_connection(
  File "/usr/lib/python3/dist-packages/urllib3/util/connection.py", line 61, in create_connection
    for res in socket.getaddrinfo(host, port, family, socket.SOCK_STREAM):
  File "/usr/lib/python3.8/socket.py", line 918, in getaddrinfo
    for res in _socket.getaddrinfo(host, port, family, type, proto, flags):
socket.gaierror: [Errno -3] Temporary failure in name resolution

During handling of the above exception, another exception occurred:

Traceback (most recent call last):
  File "/usr/lib/python3/dist-packages/urllib3/connectionpool.py", line 666, in urlopen
    httplib_response = self._make_request(
  File "/usr/lib/python3/dist-packages/urllib3/connectionpool.py", line 377, in _make_request
    self._validate_conn(conn)
  File "/usr/lib/python3/dist-packages/urllib3/connectionpool.py", line 1001, in _validate_conn
    conn.connect()
  File "/usr/lib/python3/dist-packages/urllib3/connection.py", line 314, in connect
    conn = self._new_conn()
  File "/usr/lib/python3/dist-packages/urllib3/connection.py", line 171, in _new_conn
    raise NewConnectionError(
urllib3.exceptions.NewConnectionError: <urllib3.connection.VerifiedHTTPSConnection object at 0x7f9111d4f940>: Failed to establish a new connection: [Errno -3] Temporary failure in name resolution

During handling of the above exception, another exception occurred:

Traceback (most recent call last):
  File "/usr/lib/python3/dist-packages/requests/adapters.py", line 439, in send
    resp = conn.urlopen(
  File "/usr/lib/python3/dist-packages/urllib3/connectionpool.py", line 720, in urlopen
    retries = retries.increment(
  File "/usr/lib/python3/dist-packages/urllib3/util/retry.py", line 438, in increment
    raise MaxRetryError(_pool, url, error or ResponseError(cause))
urllib3.exceptions.MaxRetryError: HTTPSConnectionPool(host='elo.somtoday.nl', port=443): Max retries exceeded with url: /services/webdav/calendarfeed/58405be0-5611-4aba-be66-9894a1009f12/4fc988ad-6d4d-4c2a-aaf0-8207665bf69b (Caused by NewConnectionError('<urllib3.connection.VerifiedHTTPSConnection object at 0x7f9111d4f940>: Failed to establish a new connection: [Errno -3] Temporary failure in name resolution'))

During handling of the above exception, another exception occurred:

Traceback (most recent call last):
  File "/home/laurens/Somtoday_Agendas/Laurens/main.py", line 22, in <module>
    r = requests.get(url, allow_redirects=True)
  File "/usr/lib/python3/dist-packages/requests/api.py", line 75, in get
    return request('get', url, params=params, **kwargs)
  File "/usr/lib/python3/dist-packages/requests/api.py", line 60, in request
    return session.request(method=method, url=url, **kwargs)
  File "/usr/lib/python3/dist-packages/requests/sessions.py", line 535, in request
    resp = self.send(prep, **send_kwargs)
  File "/usr/lib/python3/dist-packages/requests/sessions.py", line 648, in send
    r = adapter.send(request, **kwargs)
  File "/usr/lib/python3/dist-packages/requests/adapters.py", line 516, in send
    raise ConnectionError(e, request=request)
requests.exceptions.ConnectionError: HTTPSConnectionPool(host='elo.somtoday.nl', port=443): Max retries exceeded with url: /services/webdav/calendarfeed/58405be0-5611-4aba-be66-9894a1009f12/4fc988ad-6d4d-4c2a-aaf0-8207665bf69b (Caused by NewConnectionError('<urllib3.connection.VerifiedHTTPSConnection object at 0x7f9111d4f940>: Failed to establish a new connection: [Errno -3] Temporary failure in name resolution'))
Done


11:00 09-09-2025

# Get in right directory

# Get up to date
fatal: unable to access 'https://github.com/LaurensGamet/Somtoday_Agendas/': Could not resolve host: github.com

# Run main file
The file does not exist
Traceback (most recent call last):
  File "/usr/lib/python3/dist-packages/urllib3/connection.py", line 159, in _new_conn
    conn = connection.create_connection(
  File "/usr/lib/python3/dist-packages/urllib3/util/connection.py", line 61, in create_connection
    for res in socket.getaddrinfo(host, port, family, socket.SOCK_STREAM):
  File "/usr/lib/python3.8/socket.py", line 918, in getaddrinfo
    for res in _socket.getaddrinfo(host, port, family, type, proto, flags):
socket.gaierror: [Errno -3] Temporary failure in name resolution

During handling of the above exception, another exception occurred:

Traceback (most recent call last):
  File "/usr/lib/python3/dist-packages/urllib3/connectionpool.py", line 666, in urlopen
    httplib_response = self._make_request(
  File "/usr/lib/python3/dist-packages/urllib3/connectionpool.py", line 377, in _make_request
    self._validate_conn(conn)
  File "/usr/lib/python3/dist-packages/urllib3/connectionpool.py", line 1001, in _validate_conn
    conn.connect()
  File "/usr/lib/python3/dist-packages/urllib3/connection.py", line 314, in connect
    conn = self._new_conn()
  File "/usr/lib/python3/dist-packages/urllib3/connection.py", line 171, in _new_conn
    raise NewConnectionError(
urllib3.exceptions.NewConnectionError: <urllib3.connection.VerifiedHTTPSConnection object at 0x7f58e2ca9940>: Failed to establish a new connection: [Errno -3] Temporary failure in name resolution

During handling of the above exception, another exception occurred:

Traceback (most recent call last):
  File "/usr/lib/python3/dist-packages/requests/adapters.py", line 439, in send
    resp = conn.urlopen(
  File "/usr/lib/python3/dist-packages/urllib3/connectionpool.py", line 720, in urlopen
    retries = retries.increment(
  File "/usr/lib/python3/dist-packages/urllib3/util/retry.py", line 438, in increment
    raise MaxRetryError(_pool, url, error or ResponseError(cause))
urllib3.exceptions.MaxRetryError: HTTPSConnectionPool(host='elo.somtoday.nl', port=443): Max retries exceeded with url: /services/webdav/calendarfeed/58405be0-5611-4aba-be66-9894a1009f12/4fc988ad-6d4d-4c2a-aaf0-8207665bf69b (Caused by NewConnectionError('<urllib3.connection.VerifiedHTTPSConnection object at 0x7f58e2ca9940>: Failed to establish a new connection: [Errno -3] Temporary failure in name resolution'))

During handling of the above exception, another exception occurred:

Traceback (most recent call last):
  File "/home/laurens/Somtoday_Agendas/Laurens/main.py", line 22, in <module>
    r = requests.get(url, allow_redirects=True)
  File "/usr/lib/python3/dist-packages/requests/api.py", line 75, in get
    return request('get', url, params=params, **kwargs)
  File "/usr/lib/python3/dist-packages/requests/api.py", line 60, in request
    return session.request(method=method, url=url, **kwargs)
  File "/usr/lib/python3/dist-packages/requests/sessions.py", line 535, in request
    resp = self.send(prep, **send_kwargs)
  File "/usr/lib/python3/dist-packages/requests/sessions.py", line 648, in send
    r = adapter.send(request, **kwargs)
  File "/usr/lib/python3/dist-packages/requests/adapters.py", line 516, in send
    raise ConnectionError(e, request=request)
requests.exceptions.ConnectionError: HTTPSConnectionPool(host='elo.somtoday.nl', port=443): Max retries exceeded with url: /services/webdav/calendarfeed/58405be0-5611-4aba-be66-9894a1009f12/4fc988ad-6d4d-4c2a-aaf0-8207665bf69b (Caused by NewConnectionError('<urllib3.connection.VerifiedHTTPSConnection object at 0x7f58e2ca9940>: Failed to establish a new connection: [Errno -3] Temporary failure in name resolution'))
Done


11:30 09-09-2025

# Get in right directory

# Get up to date
fatal: unable to access 'https://github.com/LaurensGamet/Somtoday_Agendas/': Could not resolve host: github.com

# Run main file
The file does not exist
Traceback (most recent call last):
  File "/usr/lib/python3/dist-packages/urllib3/connection.py", line 159, in _new_conn
    conn = connection.create_connection(
  File "/usr/lib/python3/dist-packages/urllib3/util/connection.py", line 61, in create_connection
    for res in socket.getaddrinfo(host, port, family, socket.SOCK_STREAM):
  File "/usr/lib/python3.8/socket.py", line 918, in getaddrinfo
    for res in _socket.getaddrinfo(host, port, family, type, proto, flags):
socket.gaierror: [Errno -3] Temporary failure in name resolution

During handling of the above exception, another exception occurred:

Traceback (most recent call last):
  File "/usr/lib/python3/dist-packages/urllib3/connectionpool.py", line 666, in urlopen
    httplib_response = self._make_request(
  File "/usr/lib/python3/dist-packages/urllib3/connectionpool.py", line 377, in _make_request
    self._validate_conn(conn)
  File "/usr/lib/python3/dist-packages/urllib3/connectionpool.py", line 1001, in _validate_conn
    conn.connect()
  File "/usr/lib/python3/dist-packages/urllib3/connection.py", line 314, in connect
    conn = self._new_conn()
  File "/usr/lib/python3/dist-packages/urllib3/connection.py", line 171, in _new_conn
    raise NewConnectionError(
urllib3.exceptions.NewConnectionError: <urllib3.connection.VerifiedHTTPSConnection object at 0x7fc25189b940>: Failed to establish a new connection: [Errno -3] Temporary failure in name resolution

During handling of the above exception, another exception occurred:

Traceback (most recent call last):
  File "/usr/lib/python3/dist-packages/requests/adapters.py", line 439, in send
    resp = conn.urlopen(
  File "/usr/lib/python3/dist-packages/urllib3/connectionpool.py", line 720, in urlopen
    retries = retries.increment(
  File "/usr/lib/python3/dist-packages/urllib3/util/retry.py", line 438, in increment
    raise MaxRetryError(_pool, url, error or ResponseError(cause))
urllib3.exceptions.MaxRetryError: HTTPSConnectionPool(host='elo.somtoday.nl', port=443): Max retries exceeded with url: /services/webdav/calendarfeed/58405be0-5611-4aba-be66-9894a1009f12/4fc988ad-6d4d-4c2a-aaf0-8207665bf69b (Caused by NewConnectionError('<urllib3.connection.VerifiedHTTPSConnection object at 0x7fc25189b940>: Failed to establish a new connection: [Errno -3] Temporary failure in name resolution'))

During handling of the above exception, another exception occurred:

Traceback (most recent call last):
  File "/home/laurens/Somtoday_Agendas/Laurens/main.py", line 22, in <module>
    r = requests.get(url, allow_redirects=True)
  File "/usr/lib/python3/dist-packages/requests/api.py", line 75, in get
    return request('get', url, params=params, **kwargs)
  File "/usr/lib/python3/dist-packages/requests/api.py", line 60, in request
    return session.request(method=method, url=url, **kwargs)
  File "/usr/lib/python3/dist-packages/requests/sessions.py", line 535, in request
    resp = self.send(prep, **send_kwargs)
  File "/usr/lib/python3/dist-packages/requests/sessions.py", line 648, in send
    r = adapter.send(request, **kwargs)
  File "/usr/lib/python3/dist-packages/requests/adapters.py", line 516, in send
    raise ConnectionError(e, request=request)
requests.exceptions.ConnectionError: HTTPSConnectionPool(host='elo.somtoday.nl', port=443): Max retries exceeded with url: /services/webdav/calendarfeed/58405be0-5611-4aba-be66-9894a1009f12/4fc988ad-6d4d-4c2a-aaf0-8207665bf69b (Caused by NewConnectionError('<urllib3.connection.VerifiedHTTPSConnection object at 0x7fc25189b940>: Failed to establish a new connection: [Errno -3] Temporary failure in name resolution'))
Done


12:00 09-09-2025

# Get in right directory

# Get up to date
fatal: unable to access 'https://github.com/LaurensGamet/Somtoday_Agendas/': Could not resolve host: github.com

# Run main file
The file does not exist
Traceback (most recent call last):
  File "/usr/lib/python3/dist-packages/urllib3/connection.py", line 159, in _new_conn
    conn = connection.create_connection(
  File "/usr/lib/python3/dist-packages/urllib3/util/connection.py", line 61, in create_connection
    for res in socket.getaddrinfo(host, port, family, socket.SOCK_STREAM):
  File "/usr/lib/python3.8/socket.py", line 918, in getaddrinfo
    for res in _socket.getaddrinfo(host, port, family, type, proto, flags):
socket.gaierror: [Errno -3] Temporary failure in name resolution

During handling of the above exception, another exception occurred:

Traceback (most recent call last):
  File "/usr/lib/python3/dist-packages/urllib3/connectionpool.py", line 666, in urlopen
    httplib_response = self._make_request(
  File "/usr/lib/python3/dist-packages/urllib3/connectionpool.py", line 377, in _make_request
    self._validate_conn(conn)
  File "/usr/lib/python3/dist-packages/urllib3/connectionpool.py", line 1001, in _validate_conn
    conn.connect()
  File "/usr/lib/python3/dist-packages/urllib3/connection.py", line 314, in connect
    conn = self._new_conn()
  File "/usr/lib/python3/dist-packages/urllib3/connection.py", line 171, in _new_conn
    raise NewConnectionError(
urllib3.exceptions.NewConnectionError: <urllib3.connection.VerifiedHTTPSConnection object at 0x7fb5c7308940>: Failed to establish a new connection: [Errno -3] Temporary failure in name resolution

During handling of the above exception, another exception occurred:

Traceback (most recent call last):
  File "/usr/lib/python3/dist-packages/requests/adapters.py", line 439, in send
    resp = conn.urlopen(
  File "/usr/lib/python3/dist-packages/urllib3/connectionpool.py", line 720, in urlopen
    retries = retries.increment(
  File "/usr/lib/python3/dist-packages/urllib3/util/retry.py", line 438, in increment
    raise MaxRetryError(_pool, url, error or ResponseError(cause))
urllib3.exceptions.MaxRetryError: HTTPSConnectionPool(host='elo.somtoday.nl', port=443): Max retries exceeded with url: /services/webdav/calendarfeed/58405be0-5611-4aba-be66-9894a1009f12/4fc988ad-6d4d-4c2a-aaf0-8207665bf69b (Caused by NewConnectionError('<urllib3.connection.VerifiedHTTPSConnection object at 0x7fb5c7308940>: Failed to establish a new connection: [Errno -3] Temporary failure in name resolution'))

During handling of the above exception, another exception occurred:

Traceback (most recent call last):
  File "/home/laurens/Somtoday_Agendas/Laurens/main.py", line 22, in <module>
    r = requests.get(url, allow_redirects=True)
  File "/usr/lib/python3/dist-packages/requests/api.py", line 75, in get
    return request('get', url, params=params, **kwargs)
  File "/usr/lib/python3/dist-packages/requests/api.py", line 60, in request
    return session.request(method=method, url=url, **kwargs)
  File "/usr/lib/python3/dist-packages/requests/sessions.py", line 535, in request
    resp = self.send(prep, **send_kwargs)
  File "/usr/lib/python3/dist-packages/requests/sessions.py", line 648, in send
    r = adapter.send(request, **kwargs)
  File "/usr/lib/python3/dist-packages/requests/adapters.py", line 516, in send
    raise ConnectionError(e, request=request)
requests.exceptions.ConnectionError: HTTPSConnectionPool(host='elo.somtoday.nl', port=443): Max retries exceeded with url: /services/webdav/calendarfeed/58405be0-5611-4aba-be66-9894a1009f12/4fc988ad-6d4d-4c2a-aaf0-8207665bf69b (Caused by NewConnectionError('<urllib3.connection.VerifiedHTTPSConnection object at 0x7fb5c7308940>: Failed to establish a new connection: [Errno -3] Temporary failure in name resolution'))
Done


12:30 09-09-2025

# Get in right directory

# Get up to date
fatal: unable to access 'https://github.com/LaurensGamet/Somtoday_Agendas/': Could not resolve host: github.com

# Run main file
The file does not exist
Traceback (most recent call last):
  File "/usr/lib/python3/dist-packages/urllib3/connection.py", line 159, in _new_conn
    conn = connection.create_connection(
  File "/usr/lib/python3/dist-packages/urllib3/util/connection.py", line 61, in create_connection
    for res in socket.getaddrinfo(host, port, family, socket.SOCK_STREAM):
  File "/usr/lib/python3.8/socket.py", line 918, in getaddrinfo
    for res in _socket.getaddrinfo(host, port, family, type, proto, flags):
socket.gaierror: [Errno -3] Temporary failure in name resolution

During handling of the above exception, another exception occurred:

Traceback (most recent call last):
  File "/usr/lib/python3/dist-packages/urllib3/connectionpool.py", line 666, in urlopen
    httplib_response = self._make_request(
  File "/usr/lib/python3/dist-packages/urllib3/connectionpool.py", line 377, in _make_request
    self._validate_conn(conn)
  File "/usr/lib/python3/dist-packages/urllib3/connectionpool.py", line 1001, in _validate_conn
    conn.connect()
  File "/usr/lib/python3/dist-packages/urllib3/connection.py", line 314, in connect
    conn = self._new_conn()
  File "/usr/lib/python3/dist-packages/urllib3/connection.py", line 171, in _new_conn
    raise NewConnectionError(
urllib3.exceptions.NewConnectionError: <urllib3.connection.VerifiedHTTPSConnection object at 0x7f8e789a1940>: Failed to establish a new connection: [Errno -3] Temporary failure in name resolution

During handling of the above exception, another exception occurred:

Traceback (most recent call last):
  File "/usr/lib/python3/dist-packages/requests/adapters.py", line 439, in send
    resp = conn.urlopen(
  File "/usr/lib/python3/dist-packages/urllib3/connectionpool.py", line 720, in urlopen
    retries = retries.increment(
  File "/usr/lib/python3/dist-packages/urllib3/util/retry.py", line 438, in increment
    raise MaxRetryError(_pool, url, error or ResponseError(cause))
urllib3.exceptions.MaxRetryError: HTTPSConnectionPool(host='elo.somtoday.nl', port=443): Max retries exceeded with url: /services/webdav/calendarfeed/58405be0-5611-4aba-be66-9894a1009f12/4fc988ad-6d4d-4c2a-aaf0-8207665bf69b (Caused by NewConnectionError('<urllib3.connection.VerifiedHTTPSConnection object at 0x7f8e789a1940>: Failed to establish a new connection: [Errno -3] Temporary failure in name resolution'))

During handling of the above exception, another exception occurred:

Traceback (most recent call last):
  File "/home/laurens/Somtoday_Agendas/Laurens/main.py", line 22, in <module>
    r = requests.get(url, allow_redirects=True)
  File "/usr/lib/python3/dist-packages/requests/api.py", line 75, in get
    return request('get', url, params=params, **kwargs)
  File "/usr/lib/python3/dist-packages/requests/api.py", line 60, in request
    return session.request(method=method, url=url, **kwargs)
  File "/usr/lib/python3/dist-packages/requests/sessions.py", line 535, in request
    resp = self.send(prep, **send_kwargs)
  File "/usr/lib/python3/dist-packages/requests/sessions.py", line 648, in send
    r = adapter.send(request, **kwargs)
  File "/usr/lib/python3/dist-packages/requests/adapters.py", line 516, in send
    raise ConnectionError(e, request=request)
requests.exceptions.ConnectionError: HTTPSConnectionPool(host='elo.somtoday.nl', port=443): Max retries exceeded with url: /services/webdav/calendarfeed/58405be0-5611-4aba-be66-9894a1009f12/4fc988ad-6d4d-4c2a-aaf0-8207665bf69b (Caused by NewConnectionError('<urllib3.connection.VerifiedHTTPSConnection object at 0x7f8e789a1940>: Failed to establish a new connection: [Errno -3] Temporary failure in name resolution'))
Done


13:00 09-09-2025

# Get in right directory

# Get up to date
Already up to date.

# Run main file
The file does not exist
Done


13:30 09-09-2025

# Get in right directory

# Get up to date
Already up to date.

# Run main file
Done


14:00 09-09-2025

# Get in right directory

# Get up to date
Already up to date.

# Run main file
Done


14:30 09-09-2025

# Get in right directory

# Get up to date
Already up to date.

# Run main file
Done


15:00 09-09-2025

# Get in right directory

# Get up to date
Already up to date.

# Run main file
Done


15:30 09-09-2025

# Get in right directory

# Get up to date
Already up to date.

# Run main file
Done


16:00 09-09-2025

# Get in right directory

# Get up to date
From https://github.com/LaurensGamet/Somtoday_Agendas
   a5e649b3..59f9445b  main       -> origin/main
Updating a5e649b3..59f9445b
Fast-forward
 Custom.py | 1 +
 1 file changed, 1 insertion(+)

# Run main file
Done


16:30 09-09-2025

# Get in right directory

# Get up to date
Already up to date.

# Run main file
Done


17:00 09-09-2025

# Get in right directory

# Get up to date
Already up to date.

# Run main file
Done


17:30 09-09-2025

# Get in right directory

# Get up to date
Already up to date.

# Run main file
Done


18:00 09-09-2025

# Get in right directory

# Get up to date
Already up to date.

# Run main file
Done


18:30 09-09-2025

# Get in right directory

# Get up to date
Already up to date.

# Run main file
Done


19:00 09-09-2025

# Get in right directory

# Get up to date
Already up to date.

# Run main file
Done


19:30 09-09-2025

# Get in right directory

# Get up to date
Already up to date.

# Run main file
Done


20:00 09-09-2025

# Get in right directory

# Get up to date
Already up to date.

# Run main file
Done


20:30 09-09-2025

# Get in right directory

# Get up to date
Already up to date.

# Run main file
Done


21:00 09-09-2025

# Get in right directory

# Get up to date
From https://github.com/LaurensGamet/Somtoday_Agendas
   3972f82a..6222a41b  main       -> origin/main
Updating 3972f82a..6222a41b
Fast-forward
 Custom.py | 2 +-
 1 file changed, 1 insertion(+), 1 deletion(-)

# Run main file
Done


21:30 09-09-2025

# Get in right directory

# Get up to date
From https://github.com/LaurensGamet/Somtoday_Agendas
   5c5ce144..03a00949  main       -> origin/main
Updating 5c5ce144..03a00949
Fast-forward
 Custom.py | 2 +-
 1 file changed, 1 insertion(+), 1 deletion(-)

# Run main file
Done


22:00 09-09-2025

# Get in right directory

# Get up to date
Already up to date.

# Run main file
Done


22:30 09-09-2025

# Get in right directory

# Get up to date
Already up to date.

# Run main file
Done


23:00 09-09-2025

# Get in right directory

# Get up to date
Already up to date.

# Run main file
Done


23:30 09-09-2025

# Get in right directory

# Get up to date
Already up to date.

# Run main file
Done


00:00 10-09-2025

# Get in right directory

# Get up to date
Already up to date.

# Run main file
Done


00:30 10-09-2025

# Get in right directory

# Get up to date
Already up to date.

# Run main file
Done


01:00 10-09-2025

# Get in right directory

# Get up to date
Already up to date.

# Run main file
Done


09:05 10-09-2025

# Get in right directory

# Get up to date
From https://github.com/LaurensGamet/Somtoday_Agendas
   ad5e8804..1c1f01e2  main       -> origin/main
Updating ad5e8804..1c1f01e2
Fast-forward
 .Autostart.sh                         |   2 +
 .Reset.sh                             |   3 +-
 .gitignore.save.1                     |   0
 .run-updater.sh                       |   4 ++
 Custom_Loukas.py                      |  15 ++++
 Logs/.Checkers/Somtoday_Laurens.py    |   2 +-
 Logs/.Checkers/Somtoday_Loukas.py     |  47 +++++++++++++
 Logs/.Checkers/Somtoday_Madelief.py   |   2 +-
 .gitignore.save => Loukas/__init__.py |   0
 Loukas/main.py                        | 124 ++++++++++++++++++++++++++++++++++
 Loukas/run.sh                         |  27 ++++++++
 11 files changed, 223 insertions(+), 3 deletions(-)
 delete mode 100644 .gitignore.save.1
 create mode 100644 Custom_Loukas.py
 create mode 100644 Logs/.Checkers/Somtoday_Loukas.py
 rename .gitignore.save => Loukas/__init__.py (100%)
 create mode 100644 Loukas/main.py
 create mode 100644 Loukas/run.sh

# Run main file
Done


09:30 10-09-2025

# Get in right directory

# Get up to date
Already up to date.

# Run main file
Done


10:00 10-09-2025

# Get in right directory

# Get up to date
Already up to date.

# Run main file
Done


10:30 10-09-2025

# Get in right directory

# Get up to date
Already up to date.

# Run main file
Done


11:00 10-09-2025

# Get in right directory

# Get up to date
Already up to date.

# Run main file
Done


11:30 10-09-2025

# Get in right directory

# Get up to date
Already up to date.

# Run main file
Done


12:00 10-09-2025

# Get in right directory

# Get up to date
Already up to date.

# Run main file
Done


12:30 10-09-2025

# Get in right directory

# Get up to date
Already up to date.

# Run main file
Done


13:00 10-09-2025

# Get in right directory

# Get up to date
Already up to date.

# Run main file
Done


13:30 10-09-2025

# Get in right directory

# Get up to date
Already up to date.

# Run main file
Done


14:00 10-09-2025

# Get in right directory

# Get up to date
Already up to date.

# Run main file
Done


14:30 10-09-2025

# Get in right directory

# Get up to date
Already up to date.

# Run main file
Done


15:00 10-09-2025

# Get in right directory

# Get up to date
Already up to date.

# Run main file
Done


15:30 10-09-2025

# Get in right directory

# Get up to date
Already up to date.

# Run main file
Done


16:00 10-09-2025

# Get in right directory

# Get up to date
Already up to date.

# Run main file
Done


16:30 10-09-2025

# Get in right directory

# Get up to date
Already up to date.

# Run main file
Done


17:00 10-09-2025

# Get in right directory

# Get up to date
Already up to date.

# Run main file
Done


17:30 10-09-2025

# Get in right directory

# Get up to date
Already up to date.

# Run main file
Done


09:30 11-09-2025

# Get in right directory

# Get up to date
Already up to date.

# Run main file
Done


10:00 11-09-2025

# Get in right directory

# Get up to date
Already up to date.

# Run main file
Done


10:30 11-09-2025

# Get in right directory

# Get up to date
Already up to date.

# Run main file
Done


11:00 11-09-2025

# Get in right directory

# Get up to date
Already up to date.

# Run main file
Done


11:30 11-09-2025

# Get in right directory

# Get up to date
Already up to date.

# Run main file
Done


12:00 11-09-2025

# Get in right directory

# Get up to date
Already up to date.

# Run main file
Done


12:30 11-09-2025

# Get in right directory

# Get up to date
Already up to date.

# Run main file
Done


13:00 11-09-2025

# Get in right directory

# Get up to date
Already up to date.

# Run main file
Done


13:30 11-09-2025

# Get in right directory

# Get up to date
Already up to date.

# Run main file
Done


14:00 11-09-2025

# Get in right directory

# Get up to date
Already up to date.

# Run main file
Done


14:30 11-09-2025

# Get in right directory

# Get up to date
Already up to date.

# Run main file
Done


15:00 11-09-2025

# Get in right directory

# Get up to date
Already up to date.

# Run main file
Done


15:30 11-09-2025

# Get in right directory

# Get up to date
Already up to date.

# Run main file
Done


16:00 11-09-2025

# Get in right directory

# Get up to date
Already up to date.

# Run main file
Done


16:30 11-09-2025

# Get in right directory

# Get up to date
Already up to date.

# Run main file
Done


17:00 11-09-2025

# Get in right directory

# Get up to date
Already up to date.

# Run main file
Done


17:30 11-09-2025

# Get in right directory

# Get up to date
Already up to date.

# Run main file
Done


18:00 11-09-2025

# Get in right directory

# Get up to date
Already up to date.

# Run main file
Done


18:30 11-09-2025

# Get in right directory

# Get up to date
Already up to date.

# Run main file
Done


19:00 11-09-2025

# Get in right directory

# Get up to date
Already up to date.

# Run main file
Done


19:30 11-09-2025

# Get in right directory

# Get up to date
Already up to date.

# Run main file
Done


20:00 11-09-2025

# Get in right directory

# Get up to date
Already up to date.

# Run main file
Done


20:30 11-09-2025

# Get in right directory

# Get up to date
Already up to date.

# Run main file
Done


21:00 11-09-2025

# Get in right directory

# Get up to date
Already up to date.

# Run main file
Done


21:30 11-09-2025

# Get in right directory

# Get up to date
Already up to date.

# Run main file
Done


22:00 11-09-2025

# Get in right directory

# Get up to date
Already up to date.

# Run main file
Done


22:30 11-09-2025

# Get in right directory

# Get up to date
Already up to date.

# Run main file
Done


23:00 11-09-2025

# Get in right directory

# Get up to date
Already up to date.

# Run main file
Done


23:30 11-09-2025

# Get in right directory

# Get up to date
Already up to date.

# Run main file
Done


00:00 12-09-2025

# Get in right directory

# Get up to date
Already up to date.

# Run main file
Done


00:30 12-09-2025

# Get in right directory

# Get up to date
Already up to date.

# Run main file
Done


01:00 12-09-2025

# Get in right directory

# Get up to date
Already up to date.

# Run main file
Done


01:30 12-09-2025

# Get in right directory

# Get up to date
Already up to date.

# Run main file
Done


02:00 12-09-2025

# Get in right directory

# Get up to date
Already up to date.

# Run main file
Done


02:30 12-09-2025

# Get in right directory

# Get up to date
Already up to date.

# Run main file
Done


03:00 12-09-2025

# Get in right directory

# Get up to date
Already up to date.

# Run main file
Done


03:30 12-09-2025

# Get in right directory

# Get up to date
Already up to date.

# Run main file
Done


04:00 12-09-2025

# Get in right directory

# Get up to date
Already up to date.

# Run main file
Done


04:30 12-09-2025

# Get in right directory

# Get up to date
Already up to date.

# Run main file
Done


05:00 12-09-2025

# Get in right directory

# Get up to date
Already up to date.

# Run main file
Done


05:30 12-09-2025

# Get in right directory

# Get up to date
Already up to date.

# Run main file
Done


06:00 12-09-2025

# Get in right directory

# Get up to date
Already up to date.

# Run main file
Done


06:30 12-09-2025

# Get in right directory

# Get up to date
Already up to date.

# Run main file
Done


07:00 12-09-2025

# Get in right directory

# Get up to date
Already up to date.

# Run main file
Done


07:30 12-09-2025

# Get in right directory

# Get up to date
Already up to date.

# Run main file
Done


08:00 12-09-2025

# Get in right directory

# Get up to date
Already up to date.

# Run main file
Done


08:30 12-09-2025

# Get in right directory

# Get up to date
Already up to date.

# Run main file
Done


09:00 12-09-2025

# Get in right directory

# Get up to date
Already up to date.

# Run main file
Done


09:30 12-09-2025

# Get in right directory

# Get up to date
Already up to date.

# Run main file
Done


10:00 12-09-2025

# Get in right directory

# Get up to date
Already up to date.

# Run main file
Done


10:30 12-09-2025

# Get in right directory

# Get up to date
Already up to date.

# Run main file
Done


11:00 12-09-2025

# Get in right directory

# Get up to date
Already up to date.

# Run main file
Done


11:30 12-09-2025

# Get in right directory

# Get up to date
Already up to date.

# Run main file
Done


12:00 12-09-2025

# Get in right directory

# Get up to date
Already up to date.

# Run main file
Done


12:30 12-09-2025

# Get in right directory

# Get up to date
Already up to date.

# Run main file
Done


13:00 12-09-2025

# Get in right directory

# Get up to date
Already up to date.

# Run main file
Done


13:30 12-09-2025

# Get in right directory

# Get up to date
Already up to date.

# Run main file
Done


14:00 12-09-2025

# Get in right directory

# Get up to date
Already up to date.

# Run main file
Done


14:30 12-09-2025

# Get in right directory

# Get up to date
Already up to date.

# Run main file
Done


15:00 12-09-2025

# Get in right directory

# Get up to date
Already up to date.

# Run main file
Done


15:30 12-09-2025

# Get in right directory

# Get up to date
Already up to date.

# Run main file
Done


16:00 12-09-2025

# Get in right directory

# Get up to date
Already up to date.

# Run main file
Done


16:30 12-09-2025

# Get in right directory

# Get up to date
Already up to date.

# Run main file
Done


17:00 12-09-2025

# Get in right directory

# Get up to date
Already up to date.

# Run main file
Done


17:30 12-09-2025

# Get in right directory

# Get up to date
Already up to date.

# Run main file
Done


18:00 12-09-2025

# Get in right directory

# Get up to date
Already up to date.

# Run main file
Done


18:30 12-09-2025

# Get in right directory

# Get up to date
Already up to date.

# Run main file
Done


19:00 12-09-2025

# Get in right directory

# Get up to date
Already up to date.

# Run main file
Done


