00:15 21-10-2025

# Get in right directory

# Get up to date
Already up to date.

# Run main file
Done


00:30 21-10-2025

# Get in right directory

# Get up to date
Already up to date.

# Run main file
Done


01:00 21-10-2025

# Get in right directory

# Get up to date
Already up to date.

# Run main file
Done


01:30 21-10-2025

# Get in right directory

# Get up to date
Already up to date.

# Run main file
Done


02:00 21-10-2025

# Get in right directory

# Get up to date
Already up to date.

# Run main file
Done


02:30 21-10-2025

# Get in right directory

# Get up to date
Already up to date.

# Run main file
Done


03:00 21-10-2025

# Get in right directory

# Get up to date
Already up to date.

# Run main file
Done


03:30 21-10-2025

# Get in right directory

# Get up to date
Already up to date.

# Run main file
Done


04:00 21-10-2025

# Get in right directory

# Get up to date
Already up to date.

# Run main file
Done


04:30 21-10-2025

# Get in right directory

# Get up to date
Already up to date.

# Run main file
Done


05:00 21-10-2025

# Get in right directory

# Get up to date
Already up to date.

# Run main file
Done


05:30 21-10-2025

# Get in right directory

# Get up to date
Already up to date.

# Run main file
Done


06:00 21-10-2025

# Get in right directory

# Get up to date
Already up to date.

# Run main file
Done


06:30 21-10-2025

# Get in right directory

# Get up to date
Already up to date.

# Run main file
Done


07:00 21-10-2025

# Get in right directory

# Get up to date
Already up to date.

# Run main file
Done


07:30 21-10-2025

# Get in right directory

# Get up to date
Already up to date.

# Run main file
Done


08:00 21-10-2025

# Get in right directory

# Get up to date
Already up to date.

# Run main file
Done


08:30 21-10-2025

# Get in right directory

# Get up to date
Already up to date.

# Run main file
Done


09:00 21-10-2025

# Get in right directory

# Get up to date
Already up to date.

# Run main file
Done


09:30 21-10-2025

# Get in right directory

# Get up to date
Already up to date.

# Run main file
Done


10:00 21-10-2025

# Get in right directory

# Get up to date
Already up to date.

# Run main file
Done


10:30 21-10-2025

# Get in right directory

# Get up to date
Already up to date.

# Run main file
Done


11:00 21-10-2025

# Get in right directory

# Get up to date
Already up to date.

# Run main file
Done


11:30 21-10-2025

# Get in right directory

# Get up to date
Already up to date.

# Run main file
Done


12:00 21-10-2025

# Get in right directory

# Get up to date
Already up to date.

# Run main file
Done


12:30 21-10-2025

# Get in right directory

# Get up to date
Already up to date.

# Run main file
Done


13:00 21-10-2025

# Get in right directory

# Get up to date
Already up to date.

# Run main file
Done


13:30 21-10-2025

# Get in right directory

# Get up to date
Already up to date.

# Run main file
Done


14:00 21-10-2025

# Get in right directory

# Get up to date
Already up to date.

# Run main file
Done


14:30 21-10-2025

# Get in right directory

# Get up to date
Already up to date.

# Run main file
Done


15:00 21-10-2025

# Get in right directory

# Get up to date
Already up to date.

# Run main file
Done


15:30 21-10-2025

# Get in right directory

# Get up to date
Already up to date.

# Run main file
Done


16:00 21-10-2025

# Get in right directory

# Get up to date
Already up to date.

# Run main file
Done


16:30 21-10-2025

# Get in right directory

# Get up to date
Already up to date.

# Run main file
Done


17:00 21-10-2025

# Get in right directory

# Get up to date
Already up to date.

# Run main file
Done


17:30 21-10-2025

# Get in right directory

# Get up to date
Already up to date.

# Run main file
Done


18:00 21-10-2025

# Get in right directory

# Get up to date
Already up to date.

# Run main file
Done


18:30 21-10-2025

# Get in right directory

# Get up to date
Already up to date.

# Run main file
Done


19:00 21-10-2025

# Get in right directory

# Get up to date
Already up to date.

# Run main file
Done


19:30 21-10-2025

# Get in right directory

# Get up to date
Already up to date.

# Run main file
Done


20:00 21-10-2025

# Get in right directory

# Get up to date
Already up to date.

# Run main file
Done


20:30 21-10-2025

# Get in right directory

# Get up to date
Already up to date.

# Run main file
Done


21:00 21-10-2025

# Get in right directory

# Get up to date
Already up to date.

# Run main file
Done


21:30 21-10-2025

# Get in right directory

# Get up to date
Already up to date.

# Run main file
Done


22:00 21-10-2025

# Get in right directory

# Get up to date
Already up to date.

# Run main file
Done


22:30 21-10-2025

# Get in right directory

# Get up to date
Already up to date.

# Run main file
Done


23:00 21-10-2025

# Get in right directory

# Get up to date
Already up to date.

# Run main file
Done


23:30 21-10-2025

# Get in right directory

# Get up to date
Already up to date.

# Run main file
Done


00:00 22-10-2025

# Get in right directory

# Get up to date
Already up to date.

# Run main file
Done


00:30 22-10-2025

# Get in right directory

# Get up to date
Already up to date.

# Run main file
Done


01:00 22-10-2025

# Get in right directory

# Get up to date
Already up to date.

# Run main file
Done


01:30 22-10-2025

# Get in right directory

# Get up to date
Already up to date.

# Run main file
Done


02:00 22-10-2025

# Get in right directory

# Get up to date
Already up to date.

# Run main file
Done


02:30 22-10-2025

# Get in right directory

# Get up to date
Already up to date.

# Run main file
Done


03:00 22-10-2025

# Get in right directory

# Get up to date
Already up to date.

# Run main file
Done


03:30 22-10-2025

# Get in right directory

# Get up to date
Already up to date.

# Run main file
Done


04:00 22-10-2025

# Get in right directory

# Get up to date
Already up to date.

# Run main file
Done


04:30 22-10-2025

# Get in right directory

# Get up to date
Already up to date.

# Run main file
Done


05:00 22-10-2025

# Get in right directory

# Get up to date
Already up to date.

# Run main file
Done


05:30 22-10-2025

# Get in right directory

# Get up to date
Already up to date.

# Run main file
Done


06:00 22-10-2025

# Get in right directory

# Get up to date
Already up to date.

# Run main file
Done


06:30 22-10-2025

# Get in right directory

# Get up to date
Already up to date.

# Run main file
Done


07:00 22-10-2025

# Get in right directory

# Get up to date
Already up to date.

# Run main file
Done


07:30 22-10-2025

# Get in right directory

# Get up to date
Already up to date.

# Run main file
Done


08:00 22-10-2025

# Get in right directory

# Get up to date
Already up to date.

# Run main file
Done


08:30 22-10-2025

# Get in right directory

# Get up to date
Already up to date.

# Run main file
Done


09:00 22-10-2025

# Get in right directory

# Get up to date
Already up to date.

# Run main file
Done


09:30 22-10-2025

# Get in right directory

# Get up to date
Already up to date.

# Run main file
Done


10:00 22-10-2025

# Get in right directory

# Get up to date
Already up to date.

# Run main file
Done


10:30 22-10-2025

# Get in right directory

# Get up to date
Already up to date.

# Run main file
Done


11:00 22-10-2025

# Get in right directory

# Get up to date
Already up to date.

# Run main file
Done


11:30 22-10-2025

# Get in right directory

# Get up to date
Already up to date.

# Run main file
Done


12:00 22-10-2025

# Get in right directory

# Get up to date
Already up to date.

# Run main file
Done


12:30 22-10-2025

# Get in right directory

# Get up to date
Already up to date.

# Run main file
Done


13:00 22-10-2025

# Get in right directory

# Get up to date
Already up to date.

# Run main file
Done


13:30 22-10-2025

# Get in right directory

# Get up to date
Already up to date.

# Run main file
Done


14:00 22-10-2025

# Get in right directory

# Get up to date
Already up to date.

# Run main file
Done


14:30 22-10-2025

# Get in right directory

# Get up to date
Already up to date.

# Run main file
Done


15:00 22-10-2025

# Get in right directory

# Get up to date
Already up to date.

# Run main file
Done


15:30 22-10-2025

# Get in right directory

# Get up to date
Already up to date.

# Run main file
Done


16:00 22-10-2025

# Get in right directory

# Get up to date
Already up to date.

# Run main file
Done


16:30 22-10-2025

# Get in right directory

# Get up to date
Already up to date.

# Run main file
Done


17:00 22-10-2025

# Get in right directory

# Get up to date
Already up to date.

# Run main file
Done


17:30 22-10-2025

# Get in right directory

# Get up to date
Already up to date.

# Run main file
Done


18:00 22-10-2025

# Get in right directory

# Get up to date
Already up to date.

# Run main file
Done


18:30 22-10-2025

# Get in right directory

# Get up to date
Already up to date.

# Run main file
Done


19:00 22-10-2025

# Get in right directory

# Get up to date
Already up to date.

# Run main file
Done


19:30 22-10-2025

# Get in right directory

# Get up to date
Already up to date.

# Run main file
Done


20:00 22-10-2025

# Get in right directory

# Get up to date
Already up to date.

# Run main file
Done


20:30 22-10-2025

# Get in right directory

# Get up to date
Already up to date.

# Run main file
Done


21:00 22-10-2025

# Get in right directory

# Get up to date
Already up to date.

# Run main file
Done


21:30 22-10-2025

# Get in right directory

# Get up to date
Already up to date.

# Run main file
Done


22:00 22-10-2025

# Get in right directory

# Get up to date
Already up to date.

# Run main file
Done


22:30 22-10-2025

# Get in right directory

# Get up to date
Already up to date.

# Run main file
Done


23:00 22-10-2025

# Get in right directory

# Get up to date
Already up to date.

# Run main file
Done


23:30 22-10-2025

# Get in right directory

# Get up to date
Already up to date.

# Run main file
Done


00:00 23-10-2025

# Get in right directory

# Get up to date
Already up to date.

# Run main file
Done


00:30 23-10-2025

# Get in right directory

# Get up to date
Already up to date.

# Run main file
Done


01:00 23-10-2025

# Get in right directory

# Get up to date
Already up to date.

# Run main file
Done


01:30 23-10-2025

# Get in right directory

# Get up to date
Already up to date.

# Run main file
Done


02:00 23-10-2025

# Get in right directory

# Get up to date
Already up to date.

# Run main file
Done


02:30 23-10-2025

# Get in right directory

# Get up to date
Already up to date.

# Run main file
Done


03:00 23-10-2025

# Get in right directory

# Get up to date
Already up to date.

# Run main file
Done


03:30 23-10-2025

# Get in right directory

# Get up to date
Already up to date.

# Run main file
Done


04:00 23-10-2025

# Get in right directory

# Get up to date
Already up to date.

# Run main file
Done


04:30 23-10-2025

# Get in right directory

# Get up to date
Already up to date.

# Run main file
Done


05:00 23-10-2025

# Get in right directory

# Get up to date
Already up to date.

# Run main file
Done


05:30 23-10-2025

# Get in right directory

# Get up to date
Already up to date.

# Run main file
Done


06:00 23-10-2025

# Get in right directory

# Get up to date
Already up to date.

# Run main file
Done


06:30 23-10-2025

# Get in right directory

# Get up to date
Already up to date.

# Run main file
Done


07:00 23-10-2025

# Get in right directory

# Get up to date
Already up to date.

# Run main file
Done


07:30 23-10-2025

# Get in right directory

# Get up to date
Already up to date.

# Run main file
Done


08:00 23-10-2025

# Get in right directory

# Get up to date
Already up to date.

# Run main file
Done


08:30 23-10-2025

# Get in right directory

# Get up to date
Already up to date.

# Run main file
Done


09:00 23-10-2025

# Get in right directory

# Get up to date
Already up to date.

# Run main file
Done


09:30 23-10-2025

# Get in right directory

# Get up to date
Already up to date.

# Run main file
Done


10:00 23-10-2025

# Get in right directory

# Get up to date
Already up to date.

# Run main file
Done


10:30 23-10-2025

# Get in right directory

# Get up to date
Already up to date.

# Run main file
Done


11:00 23-10-2025

# Get in right directory

# Get up to date
Already up to date.

# Run main file
Done


11:30 23-10-2025

# Get in right directory

# Get up to date
Already up to date.

# Run main file
Done


12:00 23-10-2025

# Get in right directory

# Get up to date
Already up to date.

# Run main file
Done


12:30 23-10-2025

# Get in right directory

# Get up to date
Already up to date.

# Run main file
Done


13:00 23-10-2025

# Get in right directory

# Get up to date
Already up to date.

# Run main file
Done


13:30 23-10-2025

# Get in right directory

# Get up to date
Already up to date.

# Run main file
Done


14:00 23-10-2025

# Get in right directory

# Get up to date
Already up to date.

# Run main file
Done


14:30 23-10-2025

# Get in right directory

# Get up to date
Already up to date.

# Run main file
Done


15:00 23-10-2025

# Get in right directory

# Get up to date
Already up to date.

# Run main file
Done


15:30 23-10-2025

# Get in right directory

# Get up to date
Already up to date.

# Run main file
Done


16:00 23-10-2025

# Get in right directory

# Get up to date
Already up to date.

# Run main file
Done


16:30 23-10-2025

# Get in right directory

# Get up to date
Already up to date.

# Run main file
Done


17:00 23-10-2025

# Get in right directory

# Get up to date
Already up to date.

# Run main file
Done


17:30 23-10-2025

# Get in right directory

# Get up to date
Already up to date.

# Run main file
Done


18:00 23-10-2025

# Get in right directory

# Get up to date
Already up to date.

# Run main file
Done


18:30 23-10-2025

# Get in right directory

# Get up to date
Already up to date.

# Run main file
Done


19:00 23-10-2025

# Get in right directory

# Get up to date
Already up to date.

# Run main file
Done


19:30 23-10-2025

# Get in right directory

# Get up to date
Already up to date.

# Run main file
Done


20:00 23-10-2025

# Get in right directory

# Get up to date
Already up to date.

# Run main file
Done


20:30 23-10-2025

# Get in right directory

# Get up to date
Already up to date.

# Run main file
Done


21:00 23-10-2025

# Get in right directory

# Get up to date
Already up to date.

# Run main file
Done


21:30 23-10-2025

# Get in right directory

# Get up to date
Already up to date.

# Run main file
Done


22:00 23-10-2025

# Get in right directory

# Get up to date
Already up to date.

# Run main file
Done


22:30 23-10-2025

# Get in right directory

# Get up to date
Already up to date.

# Run main file
Done


23:00 23-10-2025

# Get in right directory

# Get up to date
Already up to date.

# Run main file
Done


23:30 23-10-2025

# Get in right directory

# Get up to date
Already up to date.

# Run main file
Done


00:00 24-10-2025

# Get in right directory

# Get up to date
Already up to date.

# Run main file
Done


00:30 24-10-2025

# Get in right directory

# Get up to date
Already up to date.

# Run main file
Done


01:00 24-10-2025

# Get in right directory

# Get up to date
Already up to date.

# Run main file
Done


01:30 24-10-2025

# Get in right directory

# Get up to date
Already up to date.

# Run main file
Done


02:00 24-10-2025

# Get in right directory

# Get up to date
Already up to date.

# Run main file
Done


02:30 24-10-2025

# Get in right directory

# Get up to date
Already up to date.

# Run main file
Done


03:00 24-10-2025

# Get in right directory

# Get up to date
Already up to date.

# Run main file
Done


03:30 24-10-2025

# Get in right directory

# Get up to date
Already up to date.

# Run main file
Done


04:00 24-10-2025

# Get in right directory

# Get up to date
Already up to date.

# Run main file
Done


04:30 24-10-2025

# Get in right directory

# Get up to date
Already up to date.

# Run main file
Done


05:00 24-10-2025

# Get in right directory

# Get up to date
Already up to date.

# Run main file
Done


05:30 24-10-2025

# Get in right directory

# Get up to date
Already up to date.

# Run main file
Done


06:00 24-10-2025

# Get in right directory

# Get up to date
Already up to date.

# Run main file
Done


06:30 24-10-2025

# Get in right directory

# Get up to date
Already up to date.

# Run main file
Done


07:00 24-10-2025

# Get in right directory

# Get up to date
Already up to date.

# Run main file
Done


07:30 24-10-2025

# Get in right directory

# Get up to date
Already up to date.

# Run main file
Done


08:00 24-10-2025

# Get in right directory

# Get up to date
Already up to date.

# Run main file
Done


08:30 24-10-2025

# Get in right directory

# Get up to date
Already up to date.

# Run main file
Done


09:00 24-10-2025

# Get in right directory

# Get up to date
Already up to date.

# Run main file
Done


09:30 24-10-2025

# Get in right directory

# Get up to date
Already up to date.

# Run main file
Done


10:00 24-10-2025

# Get in right directory

# Get up to date
Already up to date.

# Run main file
Done


10:30 24-10-2025

# Get in right directory

# Get up to date
Already up to date.

# Run main file
Done


11:00 24-10-2025

# Get in right directory

# Get up to date
Already up to date.

# Run main file
Done


11:30 24-10-2025

# Get in right directory

# Get up to date
Already up to date.

# Run main file
Done


12:00 24-10-2025

# Get in right directory

# Get up to date
Already up to date.

# Run main file
Done


12:30 24-10-2025

# Get in right directory

# Get up to date
Already up to date.

# Run main file
Done


13:00 24-10-2025

# Get in right directory

# Get up to date
Already up to date.

# Run main file
Done


13:30 24-10-2025

# Get in right directory

# Get up to date
Already up to date.

# Run main file
Done


14:00 24-10-2025

# Get in right directory

# Get up to date
Already up to date.

# Run main file
Done


14:30 24-10-2025

# Get in right directory

# Get up to date
Already up to date.

# Run main file
Done


15:00 24-10-2025

# Get in right directory

# Get up to date
Already up to date.

# Run main file
Done


15:30 24-10-2025

# Get in right directory

# Get up to date
Already up to date.

# Run main file
Done


16:00 24-10-2025

# Get in right directory

# Get up to date
Already up to date.

# Run main file
Done


16:30 24-10-2025

# Get in right directory

# Get up to date
Already up to date.

# Run main file
Done


17:00 24-10-2025

# Get in right directory

# Get up to date
Already up to date.

# Run main file
Done


17:30 24-10-2025

# Get in right directory

# Get up to date
Already up to date.

# Run main file
Done


18:00 24-10-2025

# Get in right directory

# Get up to date
Already up to date.

# Run main file
Done


18:30 24-10-2025

# Get in right directory

# Get up to date
Already up to date.

# Run main file
Done


19:00 24-10-2025

# Get in right directory

# Get up to date
Already up to date.

# Run main file
Done


19:30 24-10-2025

# Get in right directory

# Get up to date
Already up to date.

# Run main file
Done


20:00 24-10-2025

# Get in right directory

# Get up to date
Already up to date.

# Run main file
Done


20:30 24-10-2025

# Get in right directory

# Get up to date
Already up to date.

# Run main file
Done


21:00 24-10-2025

# Get in right directory

# Get up to date
Already up to date.

# Run main file
Done


21:30 24-10-2025

# Get in right directory

# Get up to date
Already up to date.

# Run main file
Done


22:00 24-10-2025

# Get in right directory

# Get up to date
Already up to date.

# Run main file
Done


22:30 24-10-2025

# Get in right directory

# Get up to date
Already up to date.

# Run main file
Done


23:00 24-10-2025

# Get in right directory

# Get up to date
Already up to date.

# Run main file
Done


23:30 24-10-2025

# Get in right directory

# Get up to date
Already up to date.

# Run main file
Done


00:00 25-10-2025

# Get in right directory

# Get up to date
Already up to date.

# Run main file
Done


00:30 25-10-2025

# Get in right directory

# Get up to date
Already up to date.

# Run main file
Done


01:00 25-10-2025

# Get in right directory

# Get up to date
Already up to date.

# Run main file
Done


01:30 25-10-2025

# Get in right directory

# Get up to date
Already up to date.

# Run main file
Done


02:00 25-10-2025

# Get in right directory

# Get up to date
Already up to date.

# Run main file
Done


02:30 25-10-2025

# Get in right directory

# Get up to date
Already up to date.

# Run main file
Done


03:00 25-10-2025

# Get in right directory

# Get up to date
Already up to date.

# Run main file
Done


03:30 25-10-2025

# Get in right directory

# Get up to date
Already up to date.

# Run main file
Done


04:00 25-10-2025

# Get in right directory

# Get up to date
Already up to date.

# Run main file
Done


04:30 25-10-2025

# Get in right directory

# Get up to date
Already up to date.

# Run main file
Done


05:00 25-10-2025

# Get in right directory

# Get up to date
Already up to date.

# Run main file
Done


05:30 25-10-2025

# Get in right directory

# Get up to date
Already up to date.

# Run main file
Done


06:00 25-10-2025

# Get in right directory

# Get up to date
Already up to date.

# Run main file
Done


06:30 25-10-2025

# Get in right directory

# Get up to date
Already up to date.

# Run main file
Done


07:00 25-10-2025

# Get in right directory

# Get up to date
Already up to date.

# Run main file
Done


07:30 25-10-2025

# Get in right directory

# Get up to date
Already up to date.

# Run main file
Done


08:00 25-10-2025

# Get in right directory

# Get up to date
Already up to date.

# Run main file
Done


08:30 25-10-2025

# Get in right directory

# Get up to date
Already up to date.

# Run main file
Done


09:00 25-10-2025

# Get in right directory

# Get up to date
Already up to date.

# Run main file
Done


09:30 25-10-2025

# Get in right directory

# Get up to date
Already up to date.

# Run main file
Done


10:00 25-10-2025

# Get in right directory

# Get up to date
Already up to date.

# Run main file
Done


10:30 25-10-2025

# Get in right directory

# Get up to date
Already up to date.

# Run main file
Done


11:00 25-10-2025

# Get in right directory

# Get up to date
Already up to date.

# Run main file
Done


11:30 25-10-2025

# Get in right directory

# Get up to date
Already up to date.

# Run main file
Done


12:00 25-10-2025

# Get in right directory

# Get up to date
Already up to date.

# Run main file
Done


12:30 25-10-2025

# Get in right directory

# Get up to date
Already up to date.

# Run main file
Done


13:00 25-10-2025

# Get in right directory

# Get up to date
Already up to date.

# Run main file
Done


13:30 25-10-2025

# Get in right directory

# Get up to date
Already up to date.

# Run main file
Done


14:00 25-10-2025

# Get in right directory

# Get up to date
Already up to date.

# Run main file
Done


14:30 25-10-2025

# Get in right directory

# Get up to date
Already up to date.

# Run main file
Done


15:00 25-10-2025

# Get in right directory

# Get up to date
Already up to date.

# Run main file
Done


15:30 25-10-2025

# Get in right directory

# Get up to date
Already up to date.

# Run main file
Done


16:00 25-10-2025

# Get in right directory

# Get up to date
Already up to date.

# Run main file
Done


16:30 25-10-2025

# Get in right directory

# Get up to date
Already up to date.

# Run main file
Done


17:00 25-10-2025

# Get in right directory

# Get up to date
Already up to date.

# Run main file
Done


17:30 25-10-2025

# Get in right directory

# Get up to date
Already up to date.

# Run main file
Done


18:00 25-10-2025

# Get in right directory

# Get up to date
Already up to date.

# Run main file
Done


18:30 25-10-2025

# Get in right directory

# Get up to date
Already up to date.

# Run main file
Done


19:00 25-10-2025

# Get in right directory

# Get up to date
Already up to date.

# Run main file
Done


19:30 25-10-2025

# Get in right directory

# Get up to date
Already up to date.

# Run main file
Done


20:00 25-10-2025

# Get in right directory

# Get up to date
Already up to date.

# Run main file
Done


20:30 25-10-2025

# Get in right directory

# Get up to date
Already up to date.

# Run main file
Done


21:00 25-10-2025

# Get in right directory

# Get up to date
Already up to date.

# Run main file
Done


21:30 25-10-2025

# Get in right directory

# Get up to date
Already up to date.

# Run main file
Done


22:00 25-10-2025

# Get in right directory

# Get up to date
Already up to date.

# Run main file
Done


22:30 25-10-2025

# Get in right directory

# Get up to date
Already up to date.

# Run main file
Done


23:00 25-10-2025

# Get in right directory

# Get up to date
Already up to date.

# Run main file
Done


23:30 25-10-2025

# Get in right directory

# Get up to date
Already up to date.

# Run main file
Done


00:00 26-10-2025

# Get in right directory

# Get up to date
Already up to date.

# Run main file
Done


00:30 26-10-2025

# Get in right directory

# Get up to date
Already up to date.

# Run main file
Done


01:00 26-10-2025

# Get in right directory

# Get up to date
Already up to date.

# Run main file
Done


01:30 26-10-2025

# Get in right directory

# Get up to date
Already up to date.

# Run main file
Done


02:00 26-10-2025

# Get in right directory

# Get up to date
Already up to date.

# Run main file
Done


02:30 26-10-2025

# Get in right directory

# Get up to date
Already up to date.

# Run main file
Done


02:00 26-10-2025

# Get in right directory

# Get up to date
Already up to date.

# Run main file
Done


02:30 26-10-2025

# Get in right directory

# Get up to date
Already up to date.

# Run main file
Done


03:00 26-10-2025

# Get in right directory

# Get up to date
Already up to date.

# Run main file
Done


03:30 26-10-2025

# Get in right directory

# Get up to date
Already up to date.

# Run main file
Done


04:00 26-10-2025

# Get in right directory

# Get up to date
Already up to date.

# Run main file
Done


04:30 26-10-2025

# Get in right directory

# Get up to date
Already up to date.

# Run main file
Done


05:00 26-10-2025

# Get in right directory

# Get up to date
Already up to date.

# Run main file
Done


05:30 26-10-2025

# Get in right directory

# Get up to date
Already up to date.

# Run main file
Done


06:00 26-10-2025

# Get in right directory

# Get up to date
Already up to date.

# Run main file
Done


06:30 26-10-2025

# Get in right directory

# Get up to date
fatal: unable to access 'https://github.com/LaurensGamet/Somtoday_Agendas.git/': Could not resolve host: github.com

# Run main file
Traceback (most recent call last):
  File "/usr/lib/python3/dist-packages/urllib3/connection.py", line 203, in _new_conn
    sock = connection.create_connection(
           ^^^^^^^^^^^^^^^^^^^^^^^^^^^^^
  File "/usr/lib/python3/dist-packages/urllib3/util/connection.py", line 60, in create_connection
    for res in socket.getaddrinfo(host, port, family, socket.SOCK_STREAM):
               ^^^^^^^^^^^^^^^^^^^^^^^^^^^^^^^^^^^^^^^^^^^^^^^^^^^^^^^^^^
  File "/usr/lib/python3.12/socket.py", line 963, in getaddrinfo
    for res in _socket.getaddrinfo(host, port, family, type, proto, flags):
               ^^^^^^^^^^^^^^^^^^^^^^^^^^^^^^^^^^^^^^^^^^^^^^^^^^^^^^^^^^^
socket.gaierror: [Errno -3] Temporary failure in name resolution

The above exception was the direct cause of the following exception:

Traceback (most recent call last):
  File "/usr/lib/python3/dist-packages/urllib3/connectionpool.py", line 791, in urlopen
    response = self._make_request(
               ^^^^^^^^^^^^^^^^^^^
  File "/usr/lib/python3/dist-packages/urllib3/connectionpool.py", line 492, in _make_request
    raise new_e
  File "/usr/lib/python3/dist-packages/urllib3/connectionpool.py", line 468, in _make_request
    self._validate_conn(conn)
  File "/usr/lib/python3/dist-packages/urllib3/connectionpool.py", line 1097, in _validate_conn
    conn.connect()
  File "/usr/lib/python3/dist-packages/urllib3/connection.py", line 611, in connect
    self.sock = sock = self._new_conn()
                       ^^^^^^^^^^^^^^^^
  File "/usr/lib/python3/dist-packages/urllib3/connection.py", line 210, in _new_conn
    raise NameResolutionError(self.host, self, e) from e
urllib3.exceptions.NameResolutionError: <urllib3.connection.HTTPSConnection object at 0x7ab95100ae40>: Failed to resolve 'elo.somtoday.nl' ([Errno -3] Temporary failure in name resolution)

The above exception was the direct cause of the following exception:

Traceback (most recent call last):
  File "/usr/lib/python3/dist-packages/requests/adapters.py", line 486, in send
    resp = conn.urlopen(
           ^^^^^^^^^^^^^
  File "/usr/lib/python3/dist-packages/urllib3/connectionpool.py", line 845, in urlopen
    retries = retries.increment(
              ^^^^^^^^^^^^^^^^^^
  File "/usr/lib/python3/dist-packages/urllib3/util/retry.py", line 517, in increment
    raise MaxRetryError(_pool, url, reason) from reason  # type: ignore[arg-type]
    ^^^^^^^^^^^^^^^^^^^^^^^^^^^^^^^^^^^^^^^^^^^^^^^^^^^
urllib3.exceptions.MaxRetryError: HTTPSConnectionPool(host='elo.somtoday.nl', port=443): Max retries exceeded with url: /services/webdav/calendarfeed/58405be0-5611-4aba-be66-9894a1009f12/4fc988ad-6d4d-4c2a-aaf0-8207665bf69b (Caused by NameResolutionError("<urllib3.connection.HTTPSConnection object at 0x7ab95100ae40>: Failed to resolve 'elo.somtoday.nl' ([Errno -3] Temporary failure in name resolution)"))

During handling of the above exception, another exception occurred:

Traceback (most recent call last):
  File "/home/laurens/Somtoday_Agendas/Laurens/main.py", line 22, in <module>
    r = requests.get(url, allow_redirects=True)
        ^^^^^^^^^^^^^^^^^^^^^^^^^^^^^^^^^^^^^^^
  File "/usr/lib/python3/dist-packages/requests/api.py", line 73, in get
    return request("get", url, params=params, **kwargs)
           ^^^^^^^^^^^^^^^^^^^^^^^^^^^^^^^^^^^^^^^^^^^^
  File "/usr/lib/python3/dist-packages/requests/api.py", line 59, in request
    return session.request(method=method, url=url, **kwargs)
           ^^^^^^^^^^^^^^^^^^^^^^^^^^^^^^^^^^^^^^^^^^^^^^^^^
  File "/usr/lib/python3/dist-packages/requests/sessions.py", line 589, in request
    resp = self.send(prep, **send_kwargs)
           ^^^^^^^^^^^^^^^^^^^^^^^^^^^^^^
  File "/usr/lib/python3/dist-packages/requests/sessions.py", line 703, in send
    r = adapter.send(request, **kwargs)
        ^^^^^^^^^^^^^^^^^^^^^^^^^^^^^^^
  File "/usr/lib/python3/dist-packages/requests/adapters.py", line 519, in send
    raise ConnectionError(e, request=request)
requests.exceptions.ConnectionError: HTTPSConnectionPool(host='elo.somtoday.nl', port=443): Max retries exceeded with url: /services/webdav/calendarfeed/58405be0-5611-4aba-be66-9894a1009f12/4fc988ad-6d4d-4c2a-aaf0-8207665bf69b (Caused by NameResolutionError("<urllib3.connection.HTTPSConnection object at 0x7ab95100ae40>: Failed to resolve 'elo.somtoday.nl' ([Errno -3] Temporary failure in name resolution)"))
Done


07:00 26-10-2025

# Get in right directory

# Get up to date
fatal: unable to access 'https://github.com/LaurensGamet/Somtoday_Agendas.git/': Could not resolve host: github.com

# Run main file
The file does not exist
Traceback (most recent call last):
  File "/usr/lib/python3/dist-packages/urllib3/connection.py", line 203, in _new_conn
    sock = connection.create_connection(
           ^^^^^^^^^^^^^^^^^^^^^^^^^^^^^
  File "/usr/lib/python3/dist-packages/urllib3/util/connection.py", line 60, in create_connection
    for res in socket.getaddrinfo(host, port, family, socket.SOCK_STREAM):
               ^^^^^^^^^^^^^^^^^^^^^^^^^^^^^^^^^^^^^^^^^^^^^^^^^^^^^^^^^^
  File "/usr/lib/python3.12/socket.py", line 963, in getaddrinfo
    for res in _socket.getaddrinfo(host, port, family, type, proto, flags):
               ^^^^^^^^^^^^^^^^^^^^^^^^^^^^^^^^^^^^^^^^^^^^^^^^^^^^^^^^^^^
socket.gaierror: [Errno -3] Temporary failure in name resolution

The above exception was the direct cause of the following exception:

Traceback (most recent call last):
  File "/usr/lib/python3/dist-packages/urllib3/connectionpool.py", line 791, in urlopen
    response = self._make_request(
               ^^^^^^^^^^^^^^^^^^^
  File "/usr/lib/python3/dist-packages/urllib3/connectionpool.py", line 492, in _make_request
    raise new_e
  File "/usr/lib/python3/dist-packages/urllib3/connectionpool.py", line 468, in _make_request
    self._validate_conn(conn)
  File "/usr/lib/python3/dist-packages/urllib3/connectionpool.py", line 1097, in _validate_conn
    conn.connect()
  File "/usr/lib/python3/dist-packages/urllib3/connection.py", line 611, in connect
    self.sock = sock = self._new_conn()
                       ^^^^^^^^^^^^^^^^
  File "/usr/lib/python3/dist-packages/urllib3/connection.py", line 210, in _new_conn
    raise NameResolutionError(self.host, self, e) from e
urllib3.exceptions.NameResolutionError: <urllib3.connection.HTTPSConnection object at 0x797131b25df0>: Failed to resolve 'elo.somtoday.nl' ([Errno -3] Temporary failure in name resolution)

The above exception was the direct cause of the following exception:

Traceback (most recent call last):
  File "/usr/lib/python3/dist-packages/requests/adapters.py", line 486, in send
    resp = conn.urlopen(
           ^^^^^^^^^^^^^
  File "/usr/lib/python3/dist-packages/urllib3/connectionpool.py", line 845, in urlopen
    retries = retries.increment(
              ^^^^^^^^^^^^^^^^^^
  File "/usr/lib/python3/dist-packages/urllib3/util/retry.py", line 517, in increment
    raise MaxRetryError(_pool, url, reason) from reason  # type: ignore[arg-type]
    ^^^^^^^^^^^^^^^^^^^^^^^^^^^^^^^^^^^^^^^^^^^^^^^^^^^
urllib3.exceptions.MaxRetryError: HTTPSConnectionPool(host='elo.somtoday.nl', port=443): Max retries exceeded with url: /services/webdav/calendarfeed/58405be0-5611-4aba-be66-9894a1009f12/4fc988ad-6d4d-4c2a-aaf0-8207665bf69b (Caused by NameResolutionError("<urllib3.connection.HTTPSConnection object at 0x797131b25df0>: Failed to resolve 'elo.somtoday.nl' ([Errno -3] Temporary failure in name resolution)"))

During handling of the above exception, another exception occurred:

Traceback (most recent call last):
  File "/home/laurens/Somtoday_Agendas/Laurens/main.py", line 22, in <module>
    r = requests.get(url, allow_redirects=True)
        ^^^^^^^^^^^^^^^^^^^^^^^^^^^^^^^^^^^^^^^
  File "/usr/lib/python3/dist-packages/requests/api.py", line 73, in get
    return request("get", url, params=params, **kwargs)
           ^^^^^^^^^^^^^^^^^^^^^^^^^^^^^^^^^^^^^^^^^^^^
  File "/usr/lib/python3/dist-packages/requests/api.py", line 59, in request
    return session.request(method=method, url=url, **kwargs)
           ^^^^^^^^^^^^^^^^^^^^^^^^^^^^^^^^^^^^^^^^^^^^^^^^^
  File "/usr/lib/python3/dist-packages/requests/sessions.py", line 589, in request
    resp = self.send(prep, **send_kwargs)
           ^^^^^^^^^^^^^^^^^^^^^^^^^^^^^^
  File "/usr/lib/python3/dist-packages/requests/sessions.py", line 703, in send
    r = adapter.send(request, **kwargs)
        ^^^^^^^^^^^^^^^^^^^^^^^^^^^^^^^
  File "/usr/lib/python3/dist-packages/requests/adapters.py", line 519, in send
    raise ConnectionError(e, request=request)
requests.exceptions.ConnectionError: HTTPSConnectionPool(host='elo.somtoday.nl', port=443): Max retries exceeded with url: /services/webdav/calendarfeed/58405be0-5611-4aba-be66-9894a1009f12/4fc988ad-6d4d-4c2a-aaf0-8207665bf69b (Caused by NameResolutionError("<urllib3.connection.HTTPSConnection object at 0x797131b25df0>: Failed to resolve 'elo.somtoday.nl' ([Errno -3] Temporary failure in name resolution)"))
Done


07:30 26-10-2025

# Get in right directory

# Get up to date
fatal: unable to access 'https://github.com/LaurensGamet/Somtoday_Agendas.git/': Could not resolve host: github.com

# Run main file
The file does not exist
Traceback (most recent call last):
  File "/usr/lib/python3/dist-packages/urllib3/connection.py", line 203, in _new_conn
    sock = connection.create_connection(
           ^^^^^^^^^^^^^^^^^^^^^^^^^^^^^
  File "/usr/lib/python3/dist-packages/urllib3/util/connection.py", line 60, in create_connection
    for res in socket.getaddrinfo(host, port, family, socket.SOCK_STREAM):
               ^^^^^^^^^^^^^^^^^^^^^^^^^^^^^^^^^^^^^^^^^^^^^^^^^^^^^^^^^^
  File "/usr/lib/python3.12/socket.py", line 963, in getaddrinfo
    for res in _socket.getaddrinfo(host, port, family, type, proto, flags):
               ^^^^^^^^^^^^^^^^^^^^^^^^^^^^^^^^^^^^^^^^^^^^^^^^^^^^^^^^^^^
socket.gaierror: [Errno -3] Temporary failure in name resolution

The above exception was the direct cause of the following exception:

Traceback (most recent call last):
  File "/usr/lib/python3/dist-packages/urllib3/connectionpool.py", line 791, in urlopen
    response = self._make_request(
               ^^^^^^^^^^^^^^^^^^^
  File "/usr/lib/python3/dist-packages/urllib3/connectionpool.py", line 492, in _make_request
    raise new_e
  File "/usr/lib/python3/dist-packages/urllib3/connectionpool.py", line 468, in _make_request
    self._validate_conn(conn)
  File "/usr/lib/python3/dist-packages/urllib3/connectionpool.py", line 1097, in _validate_conn
    conn.connect()
  File "/usr/lib/python3/dist-packages/urllib3/connection.py", line 611, in connect
    self.sock = sock = self._new_conn()
                       ^^^^^^^^^^^^^^^^
  File "/usr/lib/python3/dist-packages/urllib3/connection.py", line 210, in _new_conn
    raise NameResolutionError(self.host, self, e) from e
urllib3.exceptions.NameResolutionError: <urllib3.connection.HTTPSConnection object at 0x72a7bf4a1ee0>: Failed to resolve 'elo.somtoday.nl' ([Errno -3] Temporary failure in name resolution)

The above exception was the direct cause of the following exception:

Traceback (most recent call last):
  File "/usr/lib/python3/dist-packages/requests/adapters.py", line 486, in send
    resp = conn.urlopen(
           ^^^^^^^^^^^^^
  File "/usr/lib/python3/dist-packages/urllib3/connectionpool.py", line 845, in urlopen
    retries = retries.increment(
              ^^^^^^^^^^^^^^^^^^
  File "/usr/lib/python3/dist-packages/urllib3/util/retry.py", line 517, in increment
    raise MaxRetryError(_pool, url, reason) from reason  # type: ignore[arg-type]
    ^^^^^^^^^^^^^^^^^^^^^^^^^^^^^^^^^^^^^^^^^^^^^^^^^^^
urllib3.exceptions.MaxRetryError: HTTPSConnectionPool(host='elo.somtoday.nl', port=443): Max retries exceeded with url: /services/webdav/calendarfeed/58405be0-5611-4aba-be66-9894a1009f12/4fc988ad-6d4d-4c2a-aaf0-8207665bf69b (Caused by NameResolutionError("<urllib3.connection.HTTPSConnection object at 0x72a7bf4a1ee0>: Failed to resolve 'elo.somtoday.nl' ([Errno -3] Temporary failure in name resolution)"))

During handling of the above exception, another exception occurred:

Traceback (most recent call last):
  File "/home/laurens/Somtoday_Agendas/Laurens/main.py", line 22, in <module>
    r = requests.get(url, allow_redirects=True)
        ^^^^^^^^^^^^^^^^^^^^^^^^^^^^^^^^^^^^^^^
  File "/usr/lib/python3/dist-packages/requests/api.py", line 73, in get
    return request("get", url, params=params, **kwargs)
           ^^^^^^^^^^^^^^^^^^^^^^^^^^^^^^^^^^^^^^^^^^^^
  File "/usr/lib/python3/dist-packages/requests/api.py", line 59, in request
    return session.request(method=method, url=url, **kwargs)
           ^^^^^^^^^^^^^^^^^^^^^^^^^^^^^^^^^^^^^^^^^^^^^^^^^
  File "/usr/lib/python3/dist-packages/requests/sessions.py", line 589, in request
    resp = self.send(prep, **send_kwargs)
           ^^^^^^^^^^^^^^^^^^^^^^^^^^^^^^
  File "/usr/lib/python3/dist-packages/requests/sessions.py", line 703, in send
    r = adapter.send(request, **kwargs)
        ^^^^^^^^^^^^^^^^^^^^^^^^^^^^^^^
  File "/usr/lib/python3/dist-packages/requests/adapters.py", line 519, in send
    raise ConnectionError(e, request=request)
requests.exceptions.ConnectionError: HTTPSConnectionPool(host='elo.somtoday.nl', port=443): Max retries exceeded with url: /services/webdav/calendarfeed/58405be0-5611-4aba-be66-9894a1009f12/4fc988ad-6d4d-4c2a-aaf0-8207665bf69b (Caused by NameResolutionError("<urllib3.connection.HTTPSConnection object at 0x72a7bf4a1ee0>: Failed to resolve 'elo.somtoday.nl' ([Errno -3] Temporary failure in name resolution)"))
Done


08:00 26-10-2025

# Get in right directory

# Get up to date
fatal: unable to access 'https://github.com/LaurensGamet/Somtoday_Agendas.git/': Could not resolve host: github.com

# Run main file
The file does not exist
Traceback (most recent call last):
  File "/usr/lib/python3/dist-packages/urllib3/connection.py", line 203, in _new_conn
    sock = connection.create_connection(
           ^^^^^^^^^^^^^^^^^^^^^^^^^^^^^
  File "/usr/lib/python3/dist-packages/urllib3/util/connection.py", line 60, in create_connection
    for res in socket.getaddrinfo(host, port, family, socket.SOCK_STREAM):
               ^^^^^^^^^^^^^^^^^^^^^^^^^^^^^^^^^^^^^^^^^^^^^^^^^^^^^^^^^^
  File "/usr/lib/python3.12/socket.py", line 963, in getaddrinfo
    for res in _socket.getaddrinfo(host, port, family, type, proto, flags):
               ^^^^^^^^^^^^^^^^^^^^^^^^^^^^^^^^^^^^^^^^^^^^^^^^^^^^^^^^^^^
socket.gaierror: [Errno -3] Temporary failure in name resolution

The above exception was the direct cause of the following exception:

Traceback (most recent call last):
  File "/usr/lib/python3/dist-packages/urllib3/connectionpool.py", line 791, in urlopen
    response = self._make_request(
               ^^^^^^^^^^^^^^^^^^^
  File "/usr/lib/python3/dist-packages/urllib3/connectionpool.py", line 492, in _make_request
    raise new_e
  File "/usr/lib/python3/dist-packages/urllib3/connectionpool.py", line 468, in _make_request
    self._validate_conn(conn)
  File "/usr/lib/python3/dist-packages/urllib3/connectionpool.py", line 1097, in _validate_conn
    conn.connect()
  File "/usr/lib/python3/dist-packages/urllib3/connection.py", line 611, in connect
    self.sock = sock = self._new_conn()
                       ^^^^^^^^^^^^^^^^
  File "/usr/lib/python3/dist-packages/urllib3/connection.py", line 210, in _new_conn
    raise NameResolutionError(self.host, self, e) from e
urllib3.exceptions.NameResolutionError: <urllib3.connection.HTTPSConnection object at 0x78a0c3698f50>: Failed to resolve 'elo.somtoday.nl' ([Errno -3] Temporary failure in name resolution)

The above exception was the direct cause of the following exception:

Traceback (most recent call last):
  File "/usr/lib/python3/dist-packages/requests/adapters.py", line 486, in send
    resp = conn.urlopen(
           ^^^^^^^^^^^^^
  File "/usr/lib/python3/dist-packages/urllib3/connectionpool.py", line 845, in urlopen
    retries = retries.increment(
              ^^^^^^^^^^^^^^^^^^
  File "/usr/lib/python3/dist-packages/urllib3/util/retry.py", line 517, in increment
    raise MaxRetryError(_pool, url, reason) from reason  # type: ignore[arg-type]
    ^^^^^^^^^^^^^^^^^^^^^^^^^^^^^^^^^^^^^^^^^^^^^^^^^^^
urllib3.exceptions.MaxRetryError: HTTPSConnectionPool(host='elo.somtoday.nl', port=443): Max retries exceeded with url: /services/webdav/calendarfeed/58405be0-5611-4aba-be66-9894a1009f12/4fc988ad-6d4d-4c2a-aaf0-8207665bf69b (Caused by NameResolutionError("<urllib3.connection.HTTPSConnection object at 0x78a0c3698f50>: Failed to resolve 'elo.somtoday.nl' ([Errno -3] Temporary failure in name resolution)"))

During handling of the above exception, another exception occurred:

Traceback (most recent call last):
  File "/home/laurens/Somtoday_Agendas/Laurens/main.py", line 22, in <module>
    r = requests.get(url, allow_redirects=True)
        ^^^^^^^^^^^^^^^^^^^^^^^^^^^^^^^^^^^^^^^
  File "/usr/lib/python3/dist-packages/requests/api.py", line 73, in get
    return request("get", url, params=params, **kwargs)
           ^^^^^^^^^^^^^^^^^^^^^^^^^^^^^^^^^^^^^^^^^^^^
  File "/usr/lib/python3/dist-packages/requests/api.py", line 59, in request
    return session.request(method=method, url=url, **kwargs)
           ^^^^^^^^^^^^^^^^^^^^^^^^^^^^^^^^^^^^^^^^^^^^^^^^^
  File "/usr/lib/python3/dist-packages/requests/sessions.py", line 589, in request
    resp = self.send(prep, **send_kwargs)
           ^^^^^^^^^^^^^^^^^^^^^^^^^^^^^^
  File "/usr/lib/python3/dist-packages/requests/sessions.py", line 703, in send
    r = adapter.send(request, **kwargs)
        ^^^^^^^^^^^^^^^^^^^^^^^^^^^^^^^
  File "/usr/lib/python3/dist-packages/requests/adapters.py", line 519, in send
    raise ConnectionError(e, request=request)
requests.exceptions.ConnectionError: HTTPSConnectionPool(host='elo.somtoday.nl', port=443): Max retries exceeded with url: /services/webdav/calendarfeed/58405be0-5611-4aba-be66-9894a1009f12/4fc988ad-6d4d-4c2a-aaf0-8207665bf69b (Caused by NameResolutionError("<urllib3.connection.HTTPSConnection object at 0x78a0c3698f50>: Failed to resolve 'elo.somtoday.nl' ([Errno -3] Temporary failure in name resolution)"))
Done


08:30 26-10-2025

# Get in right directory

# Get up to date
fatal: unable to access 'https://github.com/LaurensGamet/Somtoday_Agendas.git/': Could not resolve host: github.com

# Run main file
The file does not exist
Traceback (most recent call last):
  File "/usr/lib/python3/dist-packages/urllib3/connection.py", line 203, in _new_conn
    sock = connection.create_connection(
           ^^^^^^^^^^^^^^^^^^^^^^^^^^^^^
  File "/usr/lib/python3/dist-packages/urllib3/util/connection.py", line 60, in create_connection
    for res in socket.getaddrinfo(host, port, family, socket.SOCK_STREAM):
               ^^^^^^^^^^^^^^^^^^^^^^^^^^^^^^^^^^^^^^^^^^^^^^^^^^^^^^^^^^
  File "/usr/lib/python3.12/socket.py", line 963, in getaddrinfo
    for res in _socket.getaddrinfo(host, port, family, type, proto, flags):
               ^^^^^^^^^^^^^^^^^^^^^^^^^^^^^^^^^^^^^^^^^^^^^^^^^^^^^^^^^^^
socket.gaierror: [Errno -3] Temporary failure in name resolution

The above exception was the direct cause of the following exception:

Traceback (most recent call last):
  File "/usr/lib/python3/dist-packages/urllib3/connectionpool.py", line 791, in urlopen
    response = self._make_request(
               ^^^^^^^^^^^^^^^^^^^
  File "/usr/lib/python3/dist-packages/urllib3/connectionpool.py", line 492, in _make_request
    raise new_e
  File "/usr/lib/python3/dist-packages/urllib3/connectionpool.py", line 468, in _make_request
    self._validate_conn(conn)
  File "/usr/lib/python3/dist-packages/urllib3/connectionpool.py", line 1097, in _validate_conn
    conn.connect()
  File "/usr/lib/python3/dist-packages/urllib3/connection.py", line 611, in connect
    self.sock = sock = self._new_conn()
                       ^^^^^^^^^^^^^^^^
  File "/usr/lib/python3/dist-packages/urllib3/connection.py", line 210, in _new_conn
    raise NameResolutionError(self.host, self, e) from e
urllib3.exceptions.NameResolutionError: <urllib3.connection.HTTPSConnection object at 0x7f1d8da26000>: Failed to resolve 'elo.somtoday.nl' ([Errno -3] Temporary failure in name resolution)

The above exception was the direct cause of the following exception:

Traceback (most recent call last):
  File "/usr/lib/python3/dist-packages/requests/adapters.py", line 486, in send
    resp = conn.urlopen(
           ^^^^^^^^^^^^^
  File "/usr/lib/python3/dist-packages/urllib3/connectionpool.py", line 845, in urlopen
    retries = retries.increment(
              ^^^^^^^^^^^^^^^^^^
  File "/usr/lib/python3/dist-packages/urllib3/util/retry.py", line 517, in increment
    raise MaxRetryError(_pool, url, reason) from reason  # type: ignore[arg-type]
    ^^^^^^^^^^^^^^^^^^^^^^^^^^^^^^^^^^^^^^^^^^^^^^^^^^^
urllib3.exceptions.MaxRetryError: HTTPSConnectionPool(host='elo.somtoday.nl', port=443): Max retries exceeded with url: /services/webdav/calendarfeed/58405be0-5611-4aba-be66-9894a1009f12/4fc988ad-6d4d-4c2a-aaf0-8207665bf69b (Caused by NameResolutionError("<urllib3.connection.HTTPSConnection object at 0x7f1d8da26000>: Failed to resolve 'elo.somtoday.nl' ([Errno -3] Temporary failure in name resolution)"))

During handling of the above exception, another exception occurred:

Traceback (most recent call last):
  File "/home/laurens/Somtoday_Agendas/Laurens/main.py", line 22, in <module>
    r = requests.get(url, allow_redirects=True)
        ^^^^^^^^^^^^^^^^^^^^^^^^^^^^^^^^^^^^^^^
  File "/usr/lib/python3/dist-packages/requests/api.py", line 73, in get
    return request("get", url, params=params, **kwargs)
           ^^^^^^^^^^^^^^^^^^^^^^^^^^^^^^^^^^^^^^^^^^^^
  File "/usr/lib/python3/dist-packages/requests/api.py", line 59, in request
    return session.request(method=method, url=url, **kwargs)
           ^^^^^^^^^^^^^^^^^^^^^^^^^^^^^^^^^^^^^^^^^^^^^^^^^
  File "/usr/lib/python3/dist-packages/requests/sessions.py", line 589, in request
    resp = self.send(prep, **send_kwargs)
           ^^^^^^^^^^^^^^^^^^^^^^^^^^^^^^
  File "/usr/lib/python3/dist-packages/requests/sessions.py", line 703, in send
    r = adapter.send(request, **kwargs)
        ^^^^^^^^^^^^^^^^^^^^^^^^^^^^^^^
  File "/usr/lib/python3/dist-packages/requests/adapters.py", line 519, in send
    raise ConnectionError(e, request=request)
requests.exceptions.ConnectionError: HTTPSConnectionPool(host='elo.somtoday.nl', port=443): Max retries exceeded with url: /services/webdav/calendarfeed/58405be0-5611-4aba-be66-9894a1009f12/4fc988ad-6d4d-4c2a-aaf0-8207665bf69b (Caused by NameResolutionError("<urllib3.connection.HTTPSConnection object at 0x7f1d8da26000>: Failed to resolve 'elo.somtoday.nl' ([Errno -3] Temporary failure in name resolution)"))
Done


09:00 26-10-2025

# Get in right directory

# Get up to date
fatal: unable to access 'https://github.com/LaurensGamet/Somtoday_Agendas.git/': Could not resolve host: github.com

# Run main file
The file does not exist
Traceback (most recent call last):
  File "/usr/lib/python3/dist-packages/urllib3/connection.py", line 203, in _new_conn
    sock = connection.create_connection(
           ^^^^^^^^^^^^^^^^^^^^^^^^^^^^^
  File "/usr/lib/python3/dist-packages/urllib3/util/connection.py", line 60, in create_connection
    for res in socket.getaddrinfo(host, port, family, socket.SOCK_STREAM):
               ^^^^^^^^^^^^^^^^^^^^^^^^^^^^^^^^^^^^^^^^^^^^^^^^^^^^^^^^^^
  File "/usr/lib/python3.12/socket.py", line 963, in getaddrinfo
    for res in _socket.getaddrinfo(host, port, family, type, proto, flags):
               ^^^^^^^^^^^^^^^^^^^^^^^^^^^^^^^^^^^^^^^^^^^^^^^^^^^^^^^^^^^
socket.gaierror: [Errno -3] Temporary failure in name resolution

The above exception was the direct cause of the following exception:

Traceback (most recent call last):
  File "/usr/lib/python3/dist-packages/urllib3/connectionpool.py", line 791, in urlopen
    response = self._make_request(
               ^^^^^^^^^^^^^^^^^^^
  File "/usr/lib/python3/dist-packages/urllib3/connectionpool.py", line 492, in _make_request
    raise new_e
  File "/usr/lib/python3/dist-packages/urllib3/connectionpool.py", line 468, in _make_request
    self._validate_conn(conn)
  File "/usr/lib/python3/dist-packages/urllib3/connectionpool.py", line 1097, in _validate_conn
    conn.connect()
  File "/usr/lib/python3/dist-packages/urllib3/connection.py", line 611, in connect
    self.sock = sock = self._new_conn()
                       ^^^^^^^^^^^^^^^^
  File "/usr/lib/python3/dist-packages/urllib3/connection.py", line 210, in _new_conn
    raise NameResolutionError(self.host, self, e) from e
urllib3.exceptions.NameResolutionError: <urllib3.connection.HTTPSConnection object at 0x71b102f00170>: Failed to resolve 'elo.somtoday.nl' ([Errno -3] Temporary failure in name resolution)

The above exception was the direct cause of the following exception:

Traceback (most recent call last):
  File "/usr/lib/python3/dist-packages/requests/adapters.py", line 486, in send
    resp = conn.urlopen(
           ^^^^^^^^^^^^^
  File "/usr/lib/python3/dist-packages/urllib3/connectionpool.py", line 845, in urlopen
    retries = retries.increment(
              ^^^^^^^^^^^^^^^^^^
  File "/usr/lib/python3/dist-packages/urllib3/util/retry.py", line 517, in increment
    raise MaxRetryError(_pool, url, reason) from reason  # type: ignore[arg-type]
    ^^^^^^^^^^^^^^^^^^^^^^^^^^^^^^^^^^^^^^^^^^^^^^^^^^^
urllib3.exceptions.MaxRetryError: HTTPSConnectionPool(host='elo.somtoday.nl', port=443): Max retries exceeded with url: /services/webdav/calendarfeed/58405be0-5611-4aba-be66-9894a1009f12/4fc988ad-6d4d-4c2a-aaf0-8207665bf69b (Caused by NameResolutionError("<urllib3.connection.HTTPSConnection object at 0x71b102f00170>: Failed to resolve 'elo.somtoday.nl' ([Errno -3] Temporary failure in name resolution)"))

During handling of the above exception, another exception occurred:

Traceback (most recent call last):
  File "/home/laurens/Somtoday_Agendas/Laurens/main.py", line 22, in <module>
    r = requests.get(url, allow_redirects=True)
        ^^^^^^^^^^^^^^^^^^^^^^^^^^^^^^^^^^^^^^^
  File "/usr/lib/python3/dist-packages/requests/api.py", line 73, in get
    return request("get", url, params=params, **kwargs)
           ^^^^^^^^^^^^^^^^^^^^^^^^^^^^^^^^^^^^^^^^^^^^
  File "/usr/lib/python3/dist-packages/requests/api.py", line 59, in request
    return session.request(method=method, url=url, **kwargs)
           ^^^^^^^^^^^^^^^^^^^^^^^^^^^^^^^^^^^^^^^^^^^^^^^^^
  File "/usr/lib/python3/dist-packages/requests/sessions.py", line 589, in request
    resp = self.send(prep, **send_kwargs)
           ^^^^^^^^^^^^^^^^^^^^^^^^^^^^^^
  File "/usr/lib/python3/dist-packages/requests/sessions.py", line 703, in send
    r = adapter.send(request, **kwargs)
        ^^^^^^^^^^^^^^^^^^^^^^^^^^^^^^^
  File "/usr/lib/python3/dist-packages/requests/adapters.py", line 519, in send
    raise ConnectionError(e, request=request)
requests.exceptions.ConnectionError: HTTPSConnectionPool(host='elo.somtoday.nl', port=443): Max retries exceeded with url: /services/webdav/calendarfeed/58405be0-5611-4aba-be66-9894a1009f12/4fc988ad-6d4d-4c2a-aaf0-8207665bf69b (Caused by NameResolutionError("<urllib3.connection.HTTPSConnection object at 0x71b102f00170>: Failed to resolve 'elo.somtoday.nl' ([Errno -3] Temporary failure in name resolution)"))
Done


09:30 26-10-2025

# Get in right directory

# Get up to date
fatal: unable to access 'https://github.com/LaurensGamet/Somtoday_Agendas.git/': Could not resolve host: github.com

# Run main file
The file does not exist
Traceback (most recent call last):
  File "/usr/lib/python3/dist-packages/urllib3/connection.py", line 203, in _new_conn
    sock = connection.create_connection(
           ^^^^^^^^^^^^^^^^^^^^^^^^^^^^^
  File "/usr/lib/python3/dist-packages/urllib3/util/connection.py", line 60, in create_connection
    for res in socket.getaddrinfo(host, port, family, socket.SOCK_STREAM):
               ^^^^^^^^^^^^^^^^^^^^^^^^^^^^^^^^^^^^^^^^^^^^^^^^^^^^^^^^^^
  File "/usr/lib/python3.12/socket.py", line 963, in getaddrinfo
    for res in _socket.getaddrinfo(host, port, family, type, proto, flags):
               ^^^^^^^^^^^^^^^^^^^^^^^^^^^^^^^^^^^^^^^^^^^^^^^^^^^^^^^^^^^
socket.gaierror: [Errno -3] Temporary failure in name resolution

The above exception was the direct cause of the following exception:

Traceback (most recent call last):
  File "/usr/lib/python3/dist-packages/urllib3/connectionpool.py", line 791, in urlopen
    response = self._make_request(
               ^^^^^^^^^^^^^^^^^^^
  File "/usr/lib/python3/dist-packages/urllib3/connectionpool.py", line 492, in _make_request
    raise new_e
  File "/usr/lib/python3/dist-packages/urllib3/connectionpool.py", line 468, in _make_request
    self._validate_conn(conn)
  File "/usr/lib/python3/dist-packages/urllib3/connectionpool.py", line 1097, in _validate_conn
    conn.connect()
  File "/usr/lib/python3/dist-packages/urllib3/connection.py", line 611, in connect
    self.sock = sock = self._new_conn()
                       ^^^^^^^^^^^^^^^^
  File "/usr/lib/python3/dist-packages/urllib3/connection.py", line 210, in _new_conn
    raise NameResolutionError(self.host, self, e) from e
urllib3.exceptions.NameResolutionError: <urllib3.connection.HTTPSConnection object at 0x73bd3f2a1ee0>: Failed to resolve 'elo.somtoday.nl' ([Errno -3] Temporary failure in name resolution)

The above exception was the direct cause of the following exception:

Traceback (most recent call last):
  File "/usr/lib/python3/dist-packages/requests/adapters.py", line 486, in send
    resp = conn.urlopen(
           ^^^^^^^^^^^^^
  File "/usr/lib/python3/dist-packages/urllib3/connectionpool.py", line 845, in urlopen
    retries = retries.increment(
              ^^^^^^^^^^^^^^^^^^
  File "/usr/lib/python3/dist-packages/urllib3/util/retry.py", line 517, in increment
    raise MaxRetryError(_pool, url, reason) from reason  # type: ignore[arg-type]
    ^^^^^^^^^^^^^^^^^^^^^^^^^^^^^^^^^^^^^^^^^^^^^^^^^^^
urllib3.exceptions.MaxRetryError: HTTPSConnectionPool(host='elo.somtoday.nl', port=443): Max retries exceeded with url: /services/webdav/calendarfeed/58405be0-5611-4aba-be66-9894a1009f12/4fc988ad-6d4d-4c2a-aaf0-8207665bf69b (Caused by NameResolutionError("<urllib3.connection.HTTPSConnection object at 0x73bd3f2a1ee0>: Failed to resolve 'elo.somtoday.nl' ([Errno -3] Temporary failure in name resolution)"))

During handling of the above exception, another exception occurred:

Traceback (most recent call last):
  File "/home/laurens/Somtoday_Agendas/Laurens/main.py", line 22, in <module>
    r = requests.get(url, allow_redirects=True)
        ^^^^^^^^^^^^^^^^^^^^^^^^^^^^^^^^^^^^^^^
  File "/usr/lib/python3/dist-packages/requests/api.py", line 73, in get
    return request("get", url, params=params, **kwargs)
           ^^^^^^^^^^^^^^^^^^^^^^^^^^^^^^^^^^^^^^^^^^^^
  File "/usr/lib/python3/dist-packages/requests/api.py", line 59, in request
    return session.request(method=method, url=url, **kwargs)
           ^^^^^^^^^^^^^^^^^^^^^^^^^^^^^^^^^^^^^^^^^^^^^^^^^
  File "/usr/lib/python3/dist-packages/requests/sessions.py", line 589, in request
    resp = self.send(prep, **send_kwargs)
           ^^^^^^^^^^^^^^^^^^^^^^^^^^^^^^
  File "/usr/lib/python3/dist-packages/requests/sessions.py", line 703, in send
    r = adapter.send(request, **kwargs)
        ^^^^^^^^^^^^^^^^^^^^^^^^^^^^^^^
  File "/usr/lib/python3/dist-packages/requests/adapters.py", line 519, in send
    raise ConnectionError(e, request=request)
requests.exceptions.ConnectionError: HTTPSConnectionPool(host='elo.somtoday.nl', port=443): Max retries exceeded with url: /services/webdav/calendarfeed/58405be0-5611-4aba-be66-9894a1009f12/4fc988ad-6d4d-4c2a-aaf0-8207665bf69b (Caused by NameResolutionError("<urllib3.connection.HTTPSConnection object at 0x73bd3f2a1ee0>: Failed to resolve 'elo.somtoday.nl' ([Errno -3] Temporary failure in name resolution)"))
Done


10:00 26-10-2025

# Get in right directory

# Get up to date
fatal: unable to access 'https://github.com/LaurensGamet/Somtoday_Agendas.git/': Could not resolve host: github.com

# Run main file
The file does not exist
Traceback (most recent call last):
  File "/usr/lib/python3/dist-packages/urllib3/connection.py", line 203, in _new_conn
    sock = connection.create_connection(
           ^^^^^^^^^^^^^^^^^^^^^^^^^^^^^
  File "/usr/lib/python3/dist-packages/urllib3/util/connection.py", line 60, in create_connection
    for res in socket.getaddrinfo(host, port, family, socket.SOCK_STREAM):
               ^^^^^^^^^^^^^^^^^^^^^^^^^^^^^^^^^^^^^^^^^^^^^^^^^^^^^^^^^^
  File "/usr/lib/python3.12/socket.py", line 963, in getaddrinfo
    for res in _socket.getaddrinfo(host, port, family, type, proto, flags):
               ^^^^^^^^^^^^^^^^^^^^^^^^^^^^^^^^^^^^^^^^^^^^^^^^^^^^^^^^^^^
socket.gaierror: [Errno -3] Temporary failure in name resolution

The above exception was the direct cause of the following exception:

Traceback (most recent call last):
  File "/usr/lib/python3/dist-packages/urllib3/connectionpool.py", line 791, in urlopen
    response = self._make_request(
               ^^^^^^^^^^^^^^^^^^^
  File "/usr/lib/python3/dist-packages/urllib3/connectionpool.py", line 492, in _make_request
    raise new_e
  File "/usr/lib/python3/dist-packages/urllib3/connectionpool.py", line 468, in _make_request
    self._validate_conn(conn)
  File "/usr/lib/python3/dist-packages/urllib3/connectionpool.py", line 1097, in _validate_conn
    conn.connect()
  File "/usr/lib/python3/dist-packages/urllib3/connection.py", line 611, in connect
    self.sock = sock = self._new_conn()
                       ^^^^^^^^^^^^^^^^
  File "/usr/lib/python3/dist-packages/urllib3/connection.py", line 210, in _new_conn
    raise NameResolutionError(self.host, self, e) from e
urllib3.exceptions.NameResolutionError: <urllib3.connection.HTTPSConnection object at 0x7b6b0282adb0>: Failed to resolve 'elo.somtoday.nl' ([Errno -3] Temporary failure in name resolution)

The above exception was the direct cause of the following exception:

Traceback (most recent call last):
  File "/usr/lib/python3/dist-packages/requests/adapters.py", line 486, in send
    resp = conn.urlopen(
           ^^^^^^^^^^^^^
  File "/usr/lib/python3/dist-packages/urllib3/connectionpool.py", line 845, in urlopen
    retries = retries.increment(
              ^^^^^^^^^^^^^^^^^^
  File "/usr/lib/python3/dist-packages/urllib3/util/retry.py", line 517, in increment
    raise MaxRetryError(_pool, url, reason) from reason  # type: ignore[arg-type]
    ^^^^^^^^^^^^^^^^^^^^^^^^^^^^^^^^^^^^^^^^^^^^^^^^^^^
urllib3.exceptions.MaxRetryError: HTTPSConnectionPool(host='elo.somtoday.nl', port=443): Max retries exceeded with url: /services/webdav/calendarfeed/58405be0-5611-4aba-be66-9894a1009f12/4fc988ad-6d4d-4c2a-aaf0-8207665bf69b (Caused by NameResolutionError("<urllib3.connection.HTTPSConnection object at 0x7b6b0282adb0>: Failed to resolve 'elo.somtoday.nl' ([Errno -3] Temporary failure in name resolution)"))

During handling of the above exception, another exception occurred:

Traceback (most recent call last):
  File "/home/laurens/Somtoday_Agendas/Laurens/main.py", line 22, in <module>
    r = requests.get(url, allow_redirects=True)
        ^^^^^^^^^^^^^^^^^^^^^^^^^^^^^^^^^^^^^^^
  File "/usr/lib/python3/dist-packages/requests/api.py", line 73, in get
    return request("get", url, params=params, **kwargs)
           ^^^^^^^^^^^^^^^^^^^^^^^^^^^^^^^^^^^^^^^^^^^^
  File "/usr/lib/python3/dist-packages/requests/api.py", line 59, in request
    return session.request(method=method, url=url, **kwargs)
           ^^^^^^^^^^^^^^^^^^^^^^^^^^^^^^^^^^^^^^^^^^^^^^^^^
  File "/usr/lib/python3/dist-packages/requests/sessions.py", line 589, in request
    resp = self.send(prep, **send_kwargs)
           ^^^^^^^^^^^^^^^^^^^^^^^^^^^^^^
  File "/usr/lib/python3/dist-packages/requests/sessions.py", line 703, in send
    r = adapter.send(request, **kwargs)
        ^^^^^^^^^^^^^^^^^^^^^^^^^^^^^^^
  File "/usr/lib/python3/dist-packages/requests/adapters.py", line 519, in send
    raise ConnectionError(e, request=request)
requests.exceptions.ConnectionError: HTTPSConnectionPool(host='elo.somtoday.nl', port=443): Max retries exceeded with url: /services/webdav/calendarfeed/58405be0-5611-4aba-be66-9894a1009f12/4fc988ad-6d4d-4c2a-aaf0-8207665bf69b (Caused by NameResolutionError("<urllib3.connection.HTTPSConnection object at 0x7b6b0282adb0>: Failed to resolve 'elo.somtoday.nl' ([Errno -3] Temporary failure in name resolution)"))
Done


10:30 26-10-2025

# Get in right directory

# Get up to date
fatal: unable to access 'https://github.com/LaurensGamet/Somtoday_Agendas.git/': Could not resolve host: github.com

# Run main file
The file does not exist
Traceback (most recent call last):
  File "/usr/lib/python3/dist-packages/urllib3/connection.py", line 203, in _new_conn
    sock = connection.create_connection(
           ^^^^^^^^^^^^^^^^^^^^^^^^^^^^^
  File "/usr/lib/python3/dist-packages/urllib3/util/connection.py", line 60, in create_connection
    for res in socket.getaddrinfo(host, port, family, socket.SOCK_STREAM):
               ^^^^^^^^^^^^^^^^^^^^^^^^^^^^^^^^^^^^^^^^^^^^^^^^^^^^^^^^^^
  File "/usr/lib/python3.12/socket.py", line 963, in getaddrinfo
    for res in _socket.getaddrinfo(host, port, family, type, proto, flags):
               ^^^^^^^^^^^^^^^^^^^^^^^^^^^^^^^^^^^^^^^^^^^^^^^^^^^^^^^^^^^
socket.gaierror: [Errno -3] Temporary failure in name resolution

The above exception was the direct cause of the following exception:

Traceback (most recent call last):
  File "/usr/lib/python3/dist-packages/urllib3/connectionpool.py", line 791, in urlopen
    response = self._make_request(
               ^^^^^^^^^^^^^^^^^^^
  File "/usr/lib/python3/dist-packages/urllib3/connectionpool.py", line 492, in _make_request
    raise new_e
  File "/usr/lib/python3/dist-packages/urllib3/connectionpool.py", line 468, in _make_request
    self._validate_conn(conn)
  File "/usr/lib/python3/dist-packages/urllib3/connectionpool.py", line 1097, in _validate_conn
    conn.connect()
  File "/usr/lib/python3/dist-packages/urllib3/connection.py", line 611, in connect
    self.sock = sock = self._new_conn()
                       ^^^^^^^^^^^^^^^^
  File "/usr/lib/python3/dist-packages/urllib3/connection.py", line 210, in _new_conn
    raise NameResolutionError(self.host, self, e) from e
urllib3.exceptions.NameResolutionError: <urllib3.connection.HTTPSConnection object at 0x7dc106500170>: Failed to resolve 'elo.somtoday.nl' ([Errno -3] Temporary failure in name resolution)

The above exception was the direct cause of the following exception:

Traceback (most recent call last):
  File "/usr/lib/python3/dist-packages/requests/adapters.py", line 486, in send
    resp = conn.urlopen(
           ^^^^^^^^^^^^^
  File "/usr/lib/python3/dist-packages/urllib3/connectionpool.py", line 845, in urlopen
    retries = retries.increment(
              ^^^^^^^^^^^^^^^^^^
  File "/usr/lib/python3/dist-packages/urllib3/util/retry.py", line 517, in increment
    raise MaxRetryError(_pool, url, reason) from reason  # type: ignore[arg-type]
    ^^^^^^^^^^^^^^^^^^^^^^^^^^^^^^^^^^^^^^^^^^^^^^^^^^^
urllib3.exceptions.MaxRetryError: HTTPSConnectionPool(host='elo.somtoday.nl', port=443): Max retries exceeded with url: /services/webdav/calendarfeed/58405be0-5611-4aba-be66-9894a1009f12/4fc988ad-6d4d-4c2a-aaf0-8207665bf69b (Caused by NameResolutionError("<urllib3.connection.HTTPSConnection object at 0x7dc106500170>: Failed to resolve 'elo.somtoday.nl' ([Errno -3] Temporary failure in name resolution)"))

During handling of the above exception, another exception occurred:

Traceback (most recent call last):
  File "/home/laurens/Somtoday_Agendas/Laurens/main.py", line 22, in <module>
    r = requests.get(url, allow_redirects=True)
        ^^^^^^^^^^^^^^^^^^^^^^^^^^^^^^^^^^^^^^^
  File "/usr/lib/python3/dist-packages/requests/api.py", line 73, in get
    return request("get", url, params=params, **kwargs)
           ^^^^^^^^^^^^^^^^^^^^^^^^^^^^^^^^^^^^^^^^^^^^
  File "/usr/lib/python3/dist-packages/requests/api.py", line 59, in request
    return session.request(method=method, url=url, **kwargs)
           ^^^^^^^^^^^^^^^^^^^^^^^^^^^^^^^^^^^^^^^^^^^^^^^^^
  File "/usr/lib/python3/dist-packages/requests/sessions.py", line 589, in request
    resp = self.send(prep, **send_kwargs)
           ^^^^^^^^^^^^^^^^^^^^^^^^^^^^^^
  File "/usr/lib/python3/dist-packages/requests/sessions.py", line 703, in send
    r = adapter.send(request, **kwargs)
        ^^^^^^^^^^^^^^^^^^^^^^^^^^^^^^^
  File "/usr/lib/python3/dist-packages/requests/adapters.py", line 519, in send
    raise ConnectionError(e, request=request)
requests.exceptions.ConnectionError: HTTPSConnectionPool(host='elo.somtoday.nl', port=443): Max retries exceeded with url: /services/webdav/calendarfeed/58405be0-5611-4aba-be66-9894a1009f12/4fc988ad-6d4d-4c2a-aaf0-8207665bf69b (Caused by NameResolutionError("<urllib3.connection.HTTPSConnection object at 0x7dc106500170>: Failed to resolve 'elo.somtoday.nl' ([Errno -3] Temporary failure in name resolution)"))
Done


11:00 26-10-2025

# Get in right directory

# Get up to date
fatal: unable to access 'https://github.com/LaurensGamet/Somtoday_Agendas.git/': Could not resolve host: github.com

# Run main file
The file does not exist
Traceback (most recent call last):
  File "/usr/lib/python3/dist-packages/urllib3/connection.py", line 203, in _new_conn
    sock = connection.create_connection(
           ^^^^^^^^^^^^^^^^^^^^^^^^^^^^^
  File "/usr/lib/python3/dist-packages/urllib3/util/connection.py", line 60, in create_connection
    for res in socket.getaddrinfo(host, port, family, socket.SOCK_STREAM):
               ^^^^^^^^^^^^^^^^^^^^^^^^^^^^^^^^^^^^^^^^^^^^^^^^^^^^^^^^^^
  File "/usr/lib/python3.12/socket.py", line 963, in getaddrinfo
    for res in _socket.getaddrinfo(host, port, family, type, proto, flags):
               ^^^^^^^^^^^^^^^^^^^^^^^^^^^^^^^^^^^^^^^^^^^^^^^^^^^^^^^^^^^
socket.gaierror: [Errno -3] Temporary failure in name resolution

The above exception was the direct cause of the following exception:

Traceback (most recent call last):
  File "/usr/lib/python3/dist-packages/urllib3/connectionpool.py", line 791, in urlopen
    response = self._make_request(
               ^^^^^^^^^^^^^^^^^^^
  File "/usr/lib/python3/dist-packages/urllib3/connectionpool.py", line 492, in _make_request
    raise new_e
  File "/usr/lib/python3/dist-packages/urllib3/connectionpool.py", line 468, in _make_request
    self._validate_conn(conn)
  File "/usr/lib/python3/dist-packages/urllib3/connectionpool.py", line 1097, in _validate_conn
    conn.connect()
  File "/usr/lib/python3/dist-packages/urllib3/connection.py", line 611, in connect
    self.sock = sock = self._new_conn()
                       ^^^^^^^^^^^^^^^^
  File "/usr/lib/python3/dist-packages/urllib3/connection.py", line 210, in _new_conn
    raise NameResolutionError(self.host, self, e) from e
urllib3.exceptions.NameResolutionError: <urllib3.connection.HTTPSConnection object at 0x747cba300170>: Failed to resolve 'elo.somtoday.nl' ([Errno -3] Temporary failure in name resolution)

The above exception was the direct cause of the following exception:

Traceback (most recent call last):
  File "/usr/lib/python3/dist-packages/requests/adapters.py", line 486, in send
    resp = conn.urlopen(
           ^^^^^^^^^^^^^
  File "/usr/lib/python3/dist-packages/urllib3/connectionpool.py", line 845, in urlopen
    retries = retries.increment(
              ^^^^^^^^^^^^^^^^^^
  File "/usr/lib/python3/dist-packages/urllib3/util/retry.py", line 517, in increment
    raise MaxRetryError(_pool, url, reason) from reason  # type: ignore[arg-type]
    ^^^^^^^^^^^^^^^^^^^^^^^^^^^^^^^^^^^^^^^^^^^^^^^^^^^
urllib3.exceptions.MaxRetryError: HTTPSConnectionPool(host='elo.somtoday.nl', port=443): Max retries exceeded with url: /services/webdav/calendarfeed/58405be0-5611-4aba-be66-9894a1009f12/4fc988ad-6d4d-4c2a-aaf0-8207665bf69b (Caused by NameResolutionError("<urllib3.connection.HTTPSConnection object at 0x747cba300170>: Failed to resolve 'elo.somtoday.nl' ([Errno -3] Temporary failure in name resolution)"))

During handling of the above exception, another exception occurred:

Traceback (most recent call last):
  File "/home/laurens/Somtoday_Agendas/Laurens/main.py", line 22, in <module>
    r = requests.get(url, allow_redirects=True)
        ^^^^^^^^^^^^^^^^^^^^^^^^^^^^^^^^^^^^^^^
  File "/usr/lib/python3/dist-packages/requests/api.py", line 73, in get
    return request("get", url, params=params, **kwargs)
           ^^^^^^^^^^^^^^^^^^^^^^^^^^^^^^^^^^^^^^^^^^^^
  File "/usr/lib/python3/dist-packages/requests/api.py", line 59, in request
    return session.request(method=method, url=url, **kwargs)
           ^^^^^^^^^^^^^^^^^^^^^^^^^^^^^^^^^^^^^^^^^^^^^^^^^
  File "/usr/lib/python3/dist-packages/requests/sessions.py", line 589, in request
    resp = self.send(prep, **send_kwargs)
           ^^^^^^^^^^^^^^^^^^^^^^^^^^^^^^
  File "/usr/lib/python3/dist-packages/requests/sessions.py", line 703, in send
    r = adapter.send(request, **kwargs)
        ^^^^^^^^^^^^^^^^^^^^^^^^^^^^^^^
  File "/usr/lib/python3/dist-packages/requests/adapters.py", line 519, in send
    raise ConnectionError(e, request=request)
requests.exceptions.ConnectionError: HTTPSConnectionPool(host='elo.somtoday.nl', port=443): Max retries exceeded with url: /services/webdav/calendarfeed/58405be0-5611-4aba-be66-9894a1009f12/4fc988ad-6d4d-4c2a-aaf0-8207665bf69b (Caused by NameResolutionError("<urllib3.connection.HTTPSConnection object at 0x747cba300170>: Failed to resolve 'elo.somtoday.nl' ([Errno -3] Temporary failure in name resolution)"))
Done


11:30 26-10-2025

# Get in right directory

# Get up to date
fatal: unable to access 'https://github.com/LaurensGamet/Somtoday_Agendas.git/': Could not resolve host: github.com

# Run main file
The file does not exist
Traceback (most recent call last):
  File "/usr/lib/python3/dist-packages/urllib3/connection.py", line 203, in _new_conn
    sock = connection.create_connection(
           ^^^^^^^^^^^^^^^^^^^^^^^^^^^^^
  File "/usr/lib/python3/dist-packages/urllib3/util/connection.py", line 60, in create_connection
    for res in socket.getaddrinfo(host, port, family, socket.SOCK_STREAM):
               ^^^^^^^^^^^^^^^^^^^^^^^^^^^^^^^^^^^^^^^^^^^^^^^^^^^^^^^^^^
  File "/usr/lib/python3.12/socket.py", line 963, in getaddrinfo
    for res in _socket.getaddrinfo(host, port, family, type, proto, flags):
               ^^^^^^^^^^^^^^^^^^^^^^^^^^^^^^^^^^^^^^^^^^^^^^^^^^^^^^^^^^^
socket.gaierror: [Errno -3] Temporary failure in name resolution

The above exception was the direct cause of the following exception:

Traceback (most recent call last):
  File "/usr/lib/python3/dist-packages/urllib3/connectionpool.py", line 791, in urlopen
    response = self._make_request(
               ^^^^^^^^^^^^^^^^^^^
  File "/usr/lib/python3/dist-packages/urllib3/connectionpool.py", line 492, in _make_request
    raise new_e
  File "/usr/lib/python3/dist-packages/urllib3/connectionpool.py", line 468, in _make_request
    self._validate_conn(conn)
  File "/usr/lib/python3/dist-packages/urllib3/connectionpool.py", line 1097, in _validate_conn
    conn.connect()
  File "/usr/lib/python3/dist-packages/urllib3/connection.py", line 611, in connect
    self.sock = sock = self._new_conn()
                       ^^^^^^^^^^^^^^^^
  File "/usr/lib/python3/dist-packages/urllib3/connection.py", line 210, in _new_conn
    raise NameResolutionError(self.host, self, e) from e
urllib3.exceptions.NameResolutionError: <urllib3.connection.HTTPSConnection object at 0x7edddb925df0>: Failed to resolve 'elo.somtoday.nl' ([Errno -3] Temporary failure in name resolution)

The above exception was the direct cause of the following exception:

Traceback (most recent call last):
  File "/usr/lib/python3/dist-packages/requests/adapters.py", line 486, in send
    resp = conn.urlopen(
           ^^^^^^^^^^^^^
  File "/usr/lib/python3/dist-packages/urllib3/connectionpool.py", line 845, in urlopen
    retries = retries.increment(
              ^^^^^^^^^^^^^^^^^^
  File "/usr/lib/python3/dist-packages/urllib3/util/retry.py", line 517, in increment
    raise MaxRetryError(_pool, url, reason) from reason  # type: ignore[arg-type]
    ^^^^^^^^^^^^^^^^^^^^^^^^^^^^^^^^^^^^^^^^^^^^^^^^^^^
urllib3.exceptions.MaxRetryError: HTTPSConnectionPool(host='elo.somtoday.nl', port=443): Max retries exceeded with url: /services/webdav/calendarfeed/58405be0-5611-4aba-be66-9894a1009f12/4fc988ad-6d4d-4c2a-aaf0-8207665bf69b (Caused by NameResolutionError("<urllib3.connection.HTTPSConnection object at 0x7edddb925df0>: Failed to resolve 'elo.somtoday.nl' ([Errno -3] Temporary failure in name resolution)"))

During handling of the above exception, another exception occurred:

Traceback (most recent call last):
  File "/home/laurens/Somtoday_Agendas/Laurens/main.py", line 22, in <module>
    r = requests.get(url, allow_redirects=True)
        ^^^^^^^^^^^^^^^^^^^^^^^^^^^^^^^^^^^^^^^
  File "/usr/lib/python3/dist-packages/requests/api.py", line 73, in get
    return request("get", url, params=params, **kwargs)
           ^^^^^^^^^^^^^^^^^^^^^^^^^^^^^^^^^^^^^^^^^^^^
  File "/usr/lib/python3/dist-packages/requests/api.py", line 59, in request
    return session.request(method=method, url=url, **kwargs)
           ^^^^^^^^^^^^^^^^^^^^^^^^^^^^^^^^^^^^^^^^^^^^^^^^^
  File "/usr/lib/python3/dist-packages/requests/sessions.py", line 589, in request
    resp = self.send(prep, **send_kwargs)
           ^^^^^^^^^^^^^^^^^^^^^^^^^^^^^^
  File "/usr/lib/python3/dist-packages/requests/sessions.py", line 703, in send
    r = adapter.send(request, **kwargs)
        ^^^^^^^^^^^^^^^^^^^^^^^^^^^^^^^
  File "/usr/lib/python3/dist-packages/requests/adapters.py", line 519, in send
    raise ConnectionError(e, request=request)
requests.exceptions.ConnectionError: HTTPSConnectionPool(host='elo.somtoday.nl', port=443): Max retries exceeded with url: /services/webdav/calendarfeed/58405be0-5611-4aba-be66-9894a1009f12/4fc988ad-6d4d-4c2a-aaf0-8207665bf69b (Caused by NameResolutionError("<urllib3.connection.HTTPSConnection object at 0x7edddb925df0>: Failed to resolve 'elo.somtoday.nl' ([Errno -3] Temporary failure in name resolution)"))
Done


12:00 26-10-2025

# Get in right directory

# Get up to date
fatal: unable to access 'https://github.com/LaurensGamet/Somtoday_Agendas.git/': Could not resolve host: github.com

# Run main file
The file does not exist
Traceback (most recent call last):
  File "/usr/lib/python3/dist-packages/urllib3/connection.py", line 203, in _new_conn
    sock = connection.create_connection(
           ^^^^^^^^^^^^^^^^^^^^^^^^^^^^^
  File "/usr/lib/python3/dist-packages/urllib3/util/connection.py", line 60, in create_connection
    for res in socket.getaddrinfo(host, port, family, socket.SOCK_STREAM):
               ^^^^^^^^^^^^^^^^^^^^^^^^^^^^^^^^^^^^^^^^^^^^^^^^^^^^^^^^^^
  File "/usr/lib/python3.12/socket.py", line 963, in getaddrinfo
    for res in _socket.getaddrinfo(host, port, family, type, proto, flags):
               ^^^^^^^^^^^^^^^^^^^^^^^^^^^^^^^^^^^^^^^^^^^^^^^^^^^^^^^^^^^
socket.gaierror: [Errno -3] Temporary failure in name resolution

The above exception was the direct cause of the following exception:

Traceback (most recent call last):
  File "/usr/lib/python3/dist-packages/urllib3/connectionpool.py", line 791, in urlopen
    response = self._make_request(
               ^^^^^^^^^^^^^^^^^^^
  File "/usr/lib/python3/dist-packages/urllib3/connectionpool.py", line 492, in _make_request
    raise new_e
  File "/usr/lib/python3/dist-packages/urllib3/connectionpool.py", line 468, in _make_request
    self._validate_conn(conn)
  File "/usr/lib/python3/dist-packages/urllib3/connectionpool.py", line 1097, in _validate_conn
    conn.connect()
  File "/usr/lib/python3/dist-packages/urllib3/connection.py", line 611, in connect
    self.sock = sock = self._new_conn()
                       ^^^^^^^^^^^^^^^^
  File "/usr/lib/python3/dist-packages/urllib3/connection.py", line 210, in _new_conn
    raise NameResolutionError(self.host, self, e) from e
urllib3.exceptions.NameResolutionError: <urllib3.connection.HTTPSConnection object at 0x71c85aea1ee0>: Failed to resolve 'elo.somtoday.nl' ([Errno -3] Temporary failure in name resolution)

The above exception was the direct cause of the following exception:

Traceback (most recent call last):
  File "/usr/lib/python3/dist-packages/requests/adapters.py", line 486, in send
    resp = conn.urlopen(
           ^^^^^^^^^^^^^
  File "/usr/lib/python3/dist-packages/urllib3/connectionpool.py", line 845, in urlopen
    retries = retries.increment(
              ^^^^^^^^^^^^^^^^^^
  File "/usr/lib/python3/dist-packages/urllib3/util/retry.py", line 517, in increment
    raise MaxRetryError(_pool, url, reason) from reason  # type: ignore[arg-type]
    ^^^^^^^^^^^^^^^^^^^^^^^^^^^^^^^^^^^^^^^^^^^^^^^^^^^
urllib3.exceptions.MaxRetryError: HTTPSConnectionPool(host='elo.somtoday.nl', port=443): Max retries exceeded with url: /services/webdav/calendarfeed/58405be0-5611-4aba-be66-9894a1009f12/4fc988ad-6d4d-4c2a-aaf0-8207665bf69b (Caused by NameResolutionError("<urllib3.connection.HTTPSConnection object at 0x71c85aea1ee0>: Failed to resolve 'elo.somtoday.nl' ([Errno -3] Temporary failure in name resolution)"))

During handling of the above exception, another exception occurred:

Traceback (most recent call last):
  File "/home/laurens/Somtoday_Agendas/Laurens/main.py", line 22, in <module>
    r = requests.get(url, allow_redirects=True)
        ^^^^^^^^^^^^^^^^^^^^^^^^^^^^^^^^^^^^^^^
  File "/usr/lib/python3/dist-packages/requests/api.py", line 73, in get
    return request("get", url, params=params, **kwargs)
           ^^^^^^^^^^^^^^^^^^^^^^^^^^^^^^^^^^^^^^^^^^^^
  File "/usr/lib/python3/dist-packages/requests/api.py", line 59, in request
    return session.request(method=method, url=url, **kwargs)
           ^^^^^^^^^^^^^^^^^^^^^^^^^^^^^^^^^^^^^^^^^^^^^^^^^
  File "/usr/lib/python3/dist-packages/requests/sessions.py", line 589, in request
    resp = self.send(prep, **send_kwargs)
           ^^^^^^^^^^^^^^^^^^^^^^^^^^^^^^
  File "/usr/lib/python3/dist-packages/requests/sessions.py", line 703, in send
    r = adapter.send(request, **kwargs)
        ^^^^^^^^^^^^^^^^^^^^^^^^^^^^^^^
  File "/usr/lib/python3/dist-packages/requests/adapters.py", line 519, in send
    raise ConnectionError(e, request=request)
requests.exceptions.ConnectionError: HTTPSConnectionPool(host='elo.somtoday.nl', port=443): Max retries exceeded with url: /services/webdav/calendarfeed/58405be0-5611-4aba-be66-9894a1009f12/4fc988ad-6d4d-4c2a-aaf0-8207665bf69b (Caused by NameResolutionError("<urllib3.connection.HTTPSConnection object at 0x71c85aea1ee0>: Failed to resolve 'elo.somtoday.nl' ([Errno -3] Temporary failure in name resolution)"))
Done


12:30 26-10-2025

# Get in right directory

# Get up to date
fatal: unable to access 'https://github.com/LaurensGamet/Somtoday_Agendas.git/': Could not resolve host: github.com

# Run main file
The file does not exist
Traceback (most recent call last):
  File "/usr/lib/python3/dist-packages/urllib3/connection.py", line 203, in _new_conn
    sock = connection.create_connection(
           ^^^^^^^^^^^^^^^^^^^^^^^^^^^^^
  File "/usr/lib/python3/dist-packages/urllib3/util/connection.py", line 60, in create_connection
    for res in socket.getaddrinfo(host, port, family, socket.SOCK_STREAM):
               ^^^^^^^^^^^^^^^^^^^^^^^^^^^^^^^^^^^^^^^^^^^^^^^^^^^^^^^^^^
  File "/usr/lib/python3.12/socket.py", line 963, in getaddrinfo
    for res in _socket.getaddrinfo(host, port, family, type, proto, flags):
               ^^^^^^^^^^^^^^^^^^^^^^^^^^^^^^^^^^^^^^^^^^^^^^^^^^^^^^^^^^^
socket.gaierror: [Errno -3] Temporary failure in name resolution

The above exception was the direct cause of the following exception:

Traceback (most recent call last):
  File "/usr/lib/python3/dist-packages/urllib3/connectionpool.py", line 791, in urlopen
    response = self._make_request(
               ^^^^^^^^^^^^^^^^^^^
  File "/usr/lib/python3/dist-packages/urllib3/connectionpool.py", line 492, in _make_request
    raise new_e
  File "/usr/lib/python3/dist-packages/urllib3/connectionpool.py", line 468, in _make_request
    self._validate_conn(conn)
  File "/usr/lib/python3/dist-packages/urllib3/connectionpool.py", line 1097, in _validate_conn
    conn.connect()
  File "/usr/lib/python3/dist-packages/urllib3/connection.py", line 611, in connect
    self.sock = sock = self._new_conn()
                       ^^^^^^^^^^^^^^^^
  File "/usr/lib/python3/dist-packages/urllib3/connection.py", line 210, in _new_conn
    raise NameResolutionError(self.host, self, e) from e
urllib3.exceptions.NameResolutionError: <urllib3.connection.HTTPSConnection object at 0x764753f2e000>: Failed to resolve 'elo.somtoday.nl' ([Errno -3] Temporary failure in name resolution)

The above exception was the direct cause of the following exception:

Traceback (most recent call last):
  File "/usr/lib/python3/dist-packages/requests/adapters.py", line 486, in send
    resp = conn.urlopen(
           ^^^^^^^^^^^^^
  File "/usr/lib/python3/dist-packages/urllib3/connectionpool.py", line 845, in urlopen
    retries = retries.increment(
              ^^^^^^^^^^^^^^^^^^
  File "/usr/lib/python3/dist-packages/urllib3/util/retry.py", line 517, in increment
    raise MaxRetryError(_pool, url, reason) from reason  # type: ignore[arg-type]
    ^^^^^^^^^^^^^^^^^^^^^^^^^^^^^^^^^^^^^^^^^^^^^^^^^^^
urllib3.exceptions.MaxRetryError: HTTPSConnectionPool(host='elo.somtoday.nl', port=443): Max retries exceeded with url: /services/webdav/calendarfeed/58405be0-5611-4aba-be66-9894a1009f12/4fc988ad-6d4d-4c2a-aaf0-8207665bf69b (Caused by NameResolutionError("<urllib3.connection.HTTPSConnection object at 0x764753f2e000>: Failed to resolve 'elo.somtoday.nl' ([Errno -3] Temporary failure in name resolution)"))

During handling of the above exception, another exception occurred:

Traceback (most recent call last):
  File "/home/laurens/Somtoday_Agendas/Laurens/main.py", line 22, in <module>
    r = requests.get(url, allow_redirects=True)
        ^^^^^^^^^^^^^^^^^^^^^^^^^^^^^^^^^^^^^^^
  File "/usr/lib/python3/dist-packages/requests/api.py", line 73, in get
    return request("get", url, params=params, **kwargs)
           ^^^^^^^^^^^^^^^^^^^^^^^^^^^^^^^^^^^^^^^^^^^^
  File "/usr/lib/python3/dist-packages/requests/api.py", line 59, in request
    return session.request(method=method, url=url, **kwargs)
           ^^^^^^^^^^^^^^^^^^^^^^^^^^^^^^^^^^^^^^^^^^^^^^^^^
  File "/usr/lib/python3/dist-packages/requests/sessions.py", line 589, in request
    resp = self.send(prep, **send_kwargs)
           ^^^^^^^^^^^^^^^^^^^^^^^^^^^^^^
  File "/usr/lib/python3/dist-packages/requests/sessions.py", line 703, in send
    r = adapter.send(request, **kwargs)
        ^^^^^^^^^^^^^^^^^^^^^^^^^^^^^^^
  File "/usr/lib/python3/dist-packages/requests/adapters.py", line 519, in send
    raise ConnectionError(e, request=request)
requests.exceptions.ConnectionError: HTTPSConnectionPool(host='elo.somtoday.nl', port=443): Max retries exceeded with url: /services/webdav/calendarfeed/58405be0-5611-4aba-be66-9894a1009f12/4fc988ad-6d4d-4c2a-aaf0-8207665bf69b (Caused by NameResolutionError("<urllib3.connection.HTTPSConnection object at 0x764753f2e000>: Failed to resolve 'elo.somtoday.nl' ([Errno -3] Temporary failure in name resolution)"))
Done


13:00 26-10-2025

# Get in right directory

# Get up to date
fatal: unable to access 'https://github.com/LaurensGamet/Somtoday_Agendas.git/': Could not resolve host: github.com

# Run main file
The file does not exist
Traceback (most recent call last):
  File "/usr/lib/python3/dist-packages/urllib3/connection.py", line 203, in _new_conn
    sock = connection.create_connection(
           ^^^^^^^^^^^^^^^^^^^^^^^^^^^^^
  File "/usr/lib/python3/dist-packages/urllib3/util/connection.py", line 60, in create_connection
    for res in socket.getaddrinfo(host, port, family, socket.SOCK_STREAM):
               ^^^^^^^^^^^^^^^^^^^^^^^^^^^^^^^^^^^^^^^^^^^^^^^^^^^^^^^^^^
  File "/usr/lib/python3.12/socket.py", line 963, in getaddrinfo
    for res in _socket.getaddrinfo(host, port, family, type, proto, flags):
               ^^^^^^^^^^^^^^^^^^^^^^^^^^^^^^^^^^^^^^^^^^^^^^^^^^^^^^^^^^^
socket.gaierror: [Errno -3] Temporary failure in name resolution

The above exception was the direct cause of the following exception:

Traceback (most recent call last):
  File "/usr/lib/python3/dist-packages/urllib3/connectionpool.py", line 791, in urlopen
    response = self._make_request(
               ^^^^^^^^^^^^^^^^^^^
  File "/usr/lib/python3/dist-packages/urllib3/connectionpool.py", line 492, in _make_request
    raise new_e
  File "/usr/lib/python3/dist-packages/urllib3/connectionpool.py", line 468, in _make_request
    self._validate_conn(conn)
  File "/usr/lib/python3/dist-packages/urllib3/connectionpool.py", line 1097, in _validate_conn
    conn.connect()
  File "/usr/lib/python3/dist-packages/urllib3/connection.py", line 611, in connect
    self.sock = sock = self._new_conn()
                       ^^^^^^^^^^^^^^^^
  File "/usr/lib/python3/dist-packages/urllib3/connection.py", line 210, in _new_conn
    raise NameResolutionError(self.host, self, e) from e
urllib3.exceptions.NameResolutionError: <urllib3.connection.HTTPSConnection object at 0x742111100170>: Failed to resolve 'elo.somtoday.nl' ([Errno -3] Temporary failure in name resolution)

The above exception was the direct cause of the following exception:

Traceback (most recent call last):
  File "/usr/lib/python3/dist-packages/requests/adapters.py", line 486, in send
    resp = conn.urlopen(
           ^^^^^^^^^^^^^
  File "/usr/lib/python3/dist-packages/urllib3/connectionpool.py", line 845, in urlopen
    retries = retries.increment(
              ^^^^^^^^^^^^^^^^^^
  File "/usr/lib/python3/dist-packages/urllib3/util/retry.py", line 517, in increment
    raise MaxRetryError(_pool, url, reason) from reason  # type: ignore[arg-type]
    ^^^^^^^^^^^^^^^^^^^^^^^^^^^^^^^^^^^^^^^^^^^^^^^^^^^
urllib3.exceptions.MaxRetryError: HTTPSConnectionPool(host='elo.somtoday.nl', port=443): Max retries exceeded with url: /services/webdav/calendarfeed/58405be0-5611-4aba-be66-9894a1009f12/4fc988ad-6d4d-4c2a-aaf0-8207665bf69b (Caused by NameResolutionError("<urllib3.connection.HTTPSConnection object at 0x742111100170>: Failed to resolve 'elo.somtoday.nl' ([Errno -3] Temporary failure in name resolution)"))

During handling of the above exception, another exception occurred:

Traceback (most recent call last):
  File "/home/laurens/Somtoday_Agendas/Laurens/main.py", line 22, in <module>
    r = requests.get(url, allow_redirects=True)
        ^^^^^^^^^^^^^^^^^^^^^^^^^^^^^^^^^^^^^^^
  File "/usr/lib/python3/dist-packages/requests/api.py", line 73, in get
    return request("get", url, params=params, **kwargs)
           ^^^^^^^^^^^^^^^^^^^^^^^^^^^^^^^^^^^^^^^^^^^^
  File "/usr/lib/python3/dist-packages/requests/api.py", line 59, in request
    return session.request(method=method, url=url, **kwargs)
           ^^^^^^^^^^^^^^^^^^^^^^^^^^^^^^^^^^^^^^^^^^^^^^^^^
  File "/usr/lib/python3/dist-packages/requests/sessions.py", line 589, in request
    resp = self.send(prep, **send_kwargs)
           ^^^^^^^^^^^^^^^^^^^^^^^^^^^^^^
  File "/usr/lib/python3/dist-packages/requests/sessions.py", line 703, in send
    r = adapter.send(request, **kwargs)
        ^^^^^^^^^^^^^^^^^^^^^^^^^^^^^^^
  File "/usr/lib/python3/dist-packages/requests/adapters.py", line 519, in send
    raise ConnectionError(e, request=request)
requests.exceptions.ConnectionError: HTTPSConnectionPool(host='elo.somtoday.nl', port=443): Max retries exceeded with url: /services/webdav/calendarfeed/58405be0-5611-4aba-be66-9894a1009f12/4fc988ad-6d4d-4c2a-aaf0-8207665bf69b (Caused by NameResolutionError("<urllib3.connection.HTTPSConnection object at 0x742111100170>: Failed to resolve 'elo.somtoday.nl' ([Errno -3] Temporary failure in name resolution)"))
Done


13:30 26-10-2025

# Get in right directory

# Get up to date
fatal: unable to access 'https://github.com/LaurensGamet/Somtoday_Agendas.git/': Could not resolve host: github.com

# Run main file
The file does not exist
Traceback (most recent call last):
  File "/usr/lib/python3/dist-packages/urllib3/connection.py", line 203, in _new_conn
    sock = connection.create_connection(
           ^^^^^^^^^^^^^^^^^^^^^^^^^^^^^
  File "/usr/lib/python3/dist-packages/urllib3/util/connection.py", line 60, in create_connection
    for res in socket.getaddrinfo(host, port, family, socket.SOCK_STREAM):
               ^^^^^^^^^^^^^^^^^^^^^^^^^^^^^^^^^^^^^^^^^^^^^^^^^^^^^^^^^^
  File "/usr/lib/python3.12/socket.py", line 963, in getaddrinfo
    for res in _socket.getaddrinfo(host, port, family, type, proto, flags):
               ^^^^^^^^^^^^^^^^^^^^^^^^^^^^^^^^^^^^^^^^^^^^^^^^^^^^^^^^^^^
socket.gaierror: [Errno -3] Temporary failure in name resolution

The above exception was the direct cause of the following exception:

Traceback (most recent call last):
  File "/usr/lib/python3/dist-packages/urllib3/connectionpool.py", line 791, in urlopen
    response = self._make_request(
               ^^^^^^^^^^^^^^^^^^^
  File "/usr/lib/python3/dist-packages/urllib3/connectionpool.py", line 492, in _make_request
    raise new_e
  File "/usr/lib/python3/dist-packages/urllib3/connectionpool.py", line 468, in _make_request
    self._validate_conn(conn)
  File "/usr/lib/python3/dist-packages/urllib3/connectionpool.py", line 1097, in _validate_conn
    conn.connect()
  File "/usr/lib/python3/dist-packages/urllib3/connection.py", line 611, in connect
    self.sock = sock = self._new_conn()
                       ^^^^^^^^^^^^^^^^
  File "/usr/lib/python3/dist-packages/urllib3/connection.py", line 210, in _new_conn
    raise NameResolutionError(self.host, self, e) from e
urllib3.exceptions.NameResolutionError: <urllib3.connection.HTTPSConnection object at 0x74f082b00170>: Failed to resolve 'elo.somtoday.nl' ([Errno -3] Temporary failure in name resolution)

The above exception was the direct cause of the following exception:

Traceback (most recent call last):
  File "/usr/lib/python3/dist-packages/requests/adapters.py", line 486, in send
    resp = conn.urlopen(
           ^^^^^^^^^^^^^
  File "/usr/lib/python3/dist-packages/urllib3/connectionpool.py", line 845, in urlopen
    retries = retries.increment(
              ^^^^^^^^^^^^^^^^^^
  File "/usr/lib/python3/dist-packages/urllib3/util/retry.py", line 517, in increment
    raise MaxRetryError(_pool, url, reason) from reason  # type: ignore[arg-type]
    ^^^^^^^^^^^^^^^^^^^^^^^^^^^^^^^^^^^^^^^^^^^^^^^^^^^
urllib3.exceptions.MaxRetryError: HTTPSConnectionPool(host='elo.somtoday.nl', port=443): Max retries exceeded with url: /services/webdav/calendarfeed/58405be0-5611-4aba-be66-9894a1009f12/4fc988ad-6d4d-4c2a-aaf0-8207665bf69b (Caused by NameResolutionError("<urllib3.connection.HTTPSConnection object at 0x74f082b00170>: Failed to resolve 'elo.somtoday.nl' ([Errno -3] Temporary failure in name resolution)"))

During handling of the above exception, another exception occurred:

Traceback (most recent call last):
  File "/home/laurens/Somtoday_Agendas/Laurens/main.py", line 22, in <module>
    r = requests.get(url, allow_redirects=True)
        ^^^^^^^^^^^^^^^^^^^^^^^^^^^^^^^^^^^^^^^
  File "/usr/lib/python3/dist-packages/requests/api.py", line 73, in get
    return request("get", url, params=params, **kwargs)
           ^^^^^^^^^^^^^^^^^^^^^^^^^^^^^^^^^^^^^^^^^^^^
  File "/usr/lib/python3/dist-packages/requests/api.py", line 59, in request
    return session.request(method=method, url=url, **kwargs)
           ^^^^^^^^^^^^^^^^^^^^^^^^^^^^^^^^^^^^^^^^^^^^^^^^^
  File "/usr/lib/python3/dist-packages/requests/sessions.py", line 589, in request
    resp = self.send(prep, **send_kwargs)
           ^^^^^^^^^^^^^^^^^^^^^^^^^^^^^^
  File "/usr/lib/python3/dist-packages/requests/sessions.py", line 703, in send
    r = adapter.send(request, **kwargs)
        ^^^^^^^^^^^^^^^^^^^^^^^^^^^^^^^
  File "/usr/lib/python3/dist-packages/requests/adapters.py", line 519, in send
    raise ConnectionError(e, request=request)
requests.exceptions.ConnectionError: HTTPSConnectionPool(host='elo.somtoday.nl', port=443): Max retries exceeded with url: /services/webdav/calendarfeed/58405be0-5611-4aba-be66-9894a1009f12/4fc988ad-6d4d-4c2a-aaf0-8207665bf69b (Caused by NameResolutionError("<urllib3.connection.HTTPSConnection object at 0x74f082b00170>: Failed to resolve 'elo.somtoday.nl' ([Errno -3] Temporary failure in name resolution)"))
Done


14:00 26-10-2025

# Get in right directory

# Get up to date
fatal: unable to access 'https://github.com/LaurensGamet/Somtoday_Agendas.git/': Could not resolve host: github.com

# Run main file
The file does not exist
Traceback (most recent call last):
  File "/usr/lib/python3/dist-packages/urllib3/connection.py", line 203, in _new_conn
    sock = connection.create_connection(
           ^^^^^^^^^^^^^^^^^^^^^^^^^^^^^
  File "/usr/lib/python3/dist-packages/urllib3/util/connection.py", line 60, in create_connection
    for res in socket.getaddrinfo(host, port, family, socket.SOCK_STREAM):
               ^^^^^^^^^^^^^^^^^^^^^^^^^^^^^^^^^^^^^^^^^^^^^^^^^^^^^^^^^^
  File "/usr/lib/python3.12/socket.py", line 963, in getaddrinfo
    for res in _socket.getaddrinfo(host, port, family, type, proto, flags):
               ^^^^^^^^^^^^^^^^^^^^^^^^^^^^^^^^^^^^^^^^^^^^^^^^^^^^^^^^^^^
socket.gaierror: [Errno -3] Temporary failure in name resolution

The above exception was the direct cause of the following exception:

Traceback (most recent call last):
  File "/usr/lib/python3/dist-packages/urllib3/connectionpool.py", line 791, in urlopen
    response = self._make_request(
               ^^^^^^^^^^^^^^^^^^^
  File "/usr/lib/python3/dist-packages/urllib3/connectionpool.py", line 492, in _make_request
    raise new_e
  File "/usr/lib/python3/dist-packages/urllib3/connectionpool.py", line 468, in _make_request
    self._validate_conn(conn)
  File "/usr/lib/python3/dist-packages/urllib3/connectionpool.py", line 1097, in _validate_conn
    conn.connect()
  File "/usr/lib/python3/dist-packages/urllib3/connection.py", line 611, in connect
    self.sock = sock = self._new_conn()
                       ^^^^^^^^^^^^^^^^
  File "/usr/lib/python3/dist-packages/urllib3/connection.py", line 210, in _new_conn
    raise NameResolutionError(self.host, self, e) from e
urllib3.exceptions.NameResolutionError: <urllib3.connection.HTTPSConnection object at 0x716d89300170>: Failed to resolve 'elo.somtoday.nl' ([Errno -3] Temporary failure in name resolution)

The above exception was the direct cause of the following exception:

Traceback (most recent call last):
  File "/usr/lib/python3/dist-packages/requests/adapters.py", line 486, in send
    resp = conn.urlopen(
           ^^^^^^^^^^^^^
  File "/usr/lib/python3/dist-packages/urllib3/connectionpool.py", line 845, in urlopen
    retries = retries.increment(
              ^^^^^^^^^^^^^^^^^^
  File "/usr/lib/python3/dist-packages/urllib3/util/retry.py", line 517, in increment
    raise MaxRetryError(_pool, url, reason) from reason  # type: ignore[arg-type]
    ^^^^^^^^^^^^^^^^^^^^^^^^^^^^^^^^^^^^^^^^^^^^^^^^^^^
urllib3.exceptions.MaxRetryError: HTTPSConnectionPool(host='elo.somtoday.nl', port=443): Max retries exceeded with url: /services/webdav/calendarfeed/58405be0-5611-4aba-be66-9894a1009f12/4fc988ad-6d4d-4c2a-aaf0-8207665bf69b (Caused by NameResolutionError("<urllib3.connection.HTTPSConnection object at 0x716d89300170>: Failed to resolve 'elo.somtoday.nl' ([Errno -3] Temporary failure in name resolution)"))

During handling of the above exception, another exception occurred:

Traceback (most recent call last):
  File "/home/laurens/Somtoday_Agendas/Laurens/main.py", line 22, in <module>
    r = requests.get(url, allow_redirects=True)
        ^^^^^^^^^^^^^^^^^^^^^^^^^^^^^^^^^^^^^^^
  File "/usr/lib/python3/dist-packages/requests/api.py", line 73, in get
    return request("get", url, params=params, **kwargs)
           ^^^^^^^^^^^^^^^^^^^^^^^^^^^^^^^^^^^^^^^^^^^^
  File "/usr/lib/python3/dist-packages/requests/api.py", line 59, in request
    return session.request(method=method, url=url, **kwargs)
           ^^^^^^^^^^^^^^^^^^^^^^^^^^^^^^^^^^^^^^^^^^^^^^^^^
  File "/usr/lib/python3/dist-packages/requests/sessions.py", line 589, in request
    resp = self.send(prep, **send_kwargs)
           ^^^^^^^^^^^^^^^^^^^^^^^^^^^^^^
  File "/usr/lib/python3/dist-packages/requests/sessions.py", line 703, in send
    r = adapter.send(request, **kwargs)
        ^^^^^^^^^^^^^^^^^^^^^^^^^^^^^^^
  File "/usr/lib/python3/dist-packages/requests/adapters.py", line 519, in send
    raise ConnectionError(e, request=request)
requests.exceptions.ConnectionError: HTTPSConnectionPool(host='elo.somtoday.nl', port=443): Max retries exceeded with url: /services/webdav/calendarfeed/58405be0-5611-4aba-be66-9894a1009f12/4fc988ad-6d4d-4c2a-aaf0-8207665bf69b (Caused by NameResolutionError("<urllib3.connection.HTTPSConnection object at 0x716d89300170>: Failed to resolve 'elo.somtoday.nl' ([Errno -3] Temporary failure in name resolution)"))
Done


14:30 26-10-2025

# Get in right directory

# Get up to date
Already up to date.

# Run main file
The file does not exist
Done


15:00 26-10-2025

# Get in right directory

# Get up to date
Already up to date.

# Run main file
Done


15:30 26-10-2025

# Get in right directory

# Get up to date
Already up to date.

# Run main file
Done


16:00 26-10-2025

# Get in right directory

# Get up to date
Already up to date.

# Run main file
Done


16:30 26-10-2025

# Get in right directory

# Get up to date
Already up to date.

# Run main file
Done


17:00 26-10-2025

# Get in right directory

# Get up to date
Already up to date.

# Run main file
Done


17:30 26-10-2025

# Get in right directory

# Get up to date
Already up to date.

# Run main file
Done


18:00 26-10-2025

# Get in right directory

# Get up to date
Already up to date.

# Run main file
Done


18:30 26-10-2025

# Get in right directory

# Get up to date
Already up to date.

# Run main file
Done


19:00 26-10-2025

# Get in right directory

# Get up to date
Already up to date.

# Run main file
Done


19:30 26-10-2025

# Get in right directory

# Get up to date
Already up to date.

# Run main file
Done


20:00 26-10-2025

# Get in right directory

# Get up to date
Already up to date.

# Run main file
Done


20:30 26-10-2025

# Get in right directory

# Get up to date
Already up to date.

# Run main file
Done


21:00 26-10-2025

# Get in right directory

# Get up to date
Already up to date.

# Run main file
Done


21:30 26-10-2025

# Get in right directory

# Get up to date
Already up to date.

# Run main file
Done


22:00 26-10-2025

# Get in right directory

# Get up to date
Already up to date.

# Run main file
Done


22:30 26-10-2025

# Get in right directory

# Get up to date
Already up to date.

# Run main file
Done


23:00 26-10-2025

# Get in right directory

# Get up to date
Already up to date.

# Run main file
Done


23:30 26-10-2025

# Get in right directory

# Get up to date
Already up to date.

# Run main file
Done


00:00 27-10-2025

# Get in right directory

# Get up to date
Already up to date.

# Run main file
Done


00:30 27-10-2025

# Get in right directory

# Get up to date
Already up to date.

# Run main file
Done


01:00 27-10-2025

# Get in right directory

# Get up to date
Already up to date.

# Run main file
Done


01:30 27-10-2025

# Get in right directory

# Get up to date
Already up to date.

# Run main file
Done


02:00 27-10-2025

# Get in right directory

# Get up to date
Already up to date.

# Run main file
Done


02:30 27-10-2025

# Get in right directory

# Get up to date
Already up to date.

# Run main file
Done


03:00 27-10-2025

# Get in right directory

# Get up to date
Already up to date.

# Run main file
Done


03:30 27-10-2025

# Get in right directory

# Get up to date
Already up to date.

# Run main file
Done


04:00 27-10-2025

# Get in right directory

# Get up to date
Already up to date.

# Run main file
Done


04:30 27-10-2025

# Get in right directory

# Get up to date
Already up to date.

# Run main file
Done


05:00 27-10-2025

# Get in right directory

# Get up to date
Already up to date.

# Run main file
Done


05:30 27-10-2025

# Get in right directory

# Get up to date
Already up to date.

# Run main file
Done


06:00 27-10-2025

# Get in right directory

# Get up to date
Already up to date.

# Run main file
Done


06:30 27-10-2025

# Get in right directory

# Get up to date
Already up to date.

# Run main file
Done


07:00 27-10-2025

# Get in right directory

# Get up to date
Already up to date.

# Run main file
Done


07:30 27-10-2025

# Get in right directory

# Get up to date
Already up to date.

# Run main file
Done


08:00 27-10-2025

# Get in right directory

# Get up to date
Already up to date.

# Run main file
Done


08:30 27-10-2025

# Get in right directory

# Get up to date
Already up to date.

# Run main file
Done


09:00 27-10-2025

# Get in right directory

# Get up to date
Already up to date.

# Run main file
Done


09:30 27-10-2025

# Get in right directory

# Get up to date
Already up to date.

# Run main file
Done


10:00 27-10-2025

# Get in right directory

# Get up to date
Already up to date.

# Run main file
Done


10:30 27-10-2025

# Get in right directory

# Get up to date
Already up to date.

# Run main file
Done


11:00 27-10-2025

# Get in right directory

# Get up to date
Already up to date.

# Run main file
Done


11:30 27-10-2025

# Get in right directory

# Get up to date
Already up to date.

# Run main file
Done


12:00 27-10-2025

# Get in right directory

# Get up to date
Already up to date.

# Run main file
Done


12:30 27-10-2025

# Get in right directory

# Get up to date
Already up to date.

# Run main file
Done


13:00 27-10-2025

# Get in right directory

# Get up to date
Already up to date.

# Run main file
Done


13:30 27-10-2025

# Get in right directory

# Get up to date
Already up to date.

# Run main file
Done


14:00 27-10-2025

# Get in right directory

# Get up to date
Already up to date.

# Run main file
Done


14:30 27-10-2025

# Get in right directory

# Get up to date
Already up to date.

# Run main file
Done


15:00 27-10-2025

# Get in right directory

# Get up to date
Already up to date.

# Run main file
Done


15:30 27-10-2025

# Get in right directory

# Get up to date
Already up to date.

# Run main file
Done


16:00 27-10-2025

# Get in right directory

# Get up to date
Already up to date.

# Run main file
Done


16:30 27-10-2025

# Get in right directory

# Get up to date
Already up to date.

# Run main file
Done


17:00 27-10-2025

# Get in right directory

# Get up to date
Already up to date.

# Run main file
Done


17:30 27-10-2025

# Get in right directory

# Get up to date
Already up to date.

# Run main file
Done


18:00 27-10-2025

# Get in right directory

# Get up to date
Already up to date.

# Run main file
Done


18:30 27-10-2025

# Get in right directory

# Get up to date
Already up to date.

# Run main file
Done


