00:15 21-10-2025

# Get in right directory

# Get up to date
Already up to date.

# Run main file
Done


00:30 21-10-2025

# Get in right directory

# Get up to date
Already up to date.

# Run main file
Done


01:00 21-10-2025

# Get in right directory

# Get up to date
Already up to date.

# Run main file
Done


01:30 21-10-2025

# Get in right directory

# Get up to date
Already up to date.

# Run main file
Done


02:00 21-10-2025

# Get in right directory

# Get up to date
Already up to date.

# Run main file
Done


02:30 21-10-2025

# Get in right directory

# Get up to date
Already up to date.

# Run main file
Done


03:00 21-10-2025

# Get in right directory

# Get up to date
Already up to date.

# Run main file
Done


03:30 21-10-2025

# Get in right directory

# Get up to date
Already up to date.

# Run main file
Done


04:00 21-10-2025

# Get in right directory

# Get up to date
Already up to date.

# Run main file
Done


04:30 21-10-2025

# Get in right directory

# Get up to date
Already up to date.

# Run main file
Done


05:00 21-10-2025

# Get in right directory

# Get up to date
Already up to date.

# Run main file
Done


05:30 21-10-2025

# Get in right directory

# Get up to date
Already up to date.

# Run main file
Done


06:00 21-10-2025

# Get in right directory

# Get up to date
Already up to date.

# Run main file
Done


06:30 21-10-2025

# Get in right directory

# Get up to date
Already up to date.

# Run main file
Done


07:00 21-10-2025

# Get in right directory

# Get up to date
Already up to date.

# Run main file
Done


07:30 21-10-2025

# Get in right directory

# Get up to date
Already up to date.

# Run main file
Done


08:00 21-10-2025

# Get in right directory

# Get up to date
Already up to date.

# Run main file
Done


08:30 21-10-2025

# Get in right directory

# Get up to date
Already up to date.

# Run main file
Done


09:00 21-10-2025

# Get in right directory

# Get up to date
Already up to date.

# Run main file
Done


09:30 21-10-2025

# Get in right directory

# Get up to date
Already up to date.

# Run main file
Done


10:00 21-10-2025

# Get in right directory

# Get up to date
warning: fetch updated the current branch head.
fast-forwarding your working tree from
commit 4f04ea7befec937cc2d089302c812ade5135e8f6.
error: Your local changes to the following files would be overwritten by merge:
	Laurens/Final-File.ics
	Logs/Laurens.log
	Logs/Loukas.log
	Logs/Madelief.log
	Madelief/Final-File.ics
Please commit your changes or stash them before you merge.
Aborting
fatal: Cannot fast-forward your working tree.
After making sure that you saved anything precious from
$ git diff 4f04ea7befec937cc2d089302c812ade5135e8f6
output, run
$ git reset --hard
to recover.

# Run main file
Done


10:30 21-10-2025

# Get in right directory

# Get up to date
Already up to date.

# Run main file
Done


11:00 21-10-2025

# Get in right directory

# Get up to date
Already up to date.

# Run main file
Done


11:30 21-10-2025

# Get in right directory

# Get up to date
Already up to date.

# Run main file
Done


12:00 21-10-2025

# Get in right directory

# Get up to date
Already up to date.

# Run main file
Done


12:30 21-10-2025

# Get in right directory

# Get up to date
Already up to date.

# Run main file
Done


13:00 21-10-2025

# Get in right directory

# Get up to date
Already up to date.

# Run main file
Done


13:30 21-10-2025

# Get in right directory

# Get up to date
Already up to date.

# Run main file
Done


14:00 21-10-2025

# Get in right directory

# Get up to date
Already up to date.

# Run main file
Done


14:30 21-10-2025

# Get in right directory

# Get up to date
Already up to date.

# Run main file
Done


15:00 21-10-2025

# Get in right directory

# Get up to date
Already up to date.

# Run main file
Done


15:30 21-10-2025

# Get in right directory

# Get up to date
Already up to date.

# Run main file
Done


16:00 21-10-2025

# Get in right directory

# Get up to date
Already up to date.

# Run main file
Done


16:30 21-10-2025

# Get in right directory

# Get up to date
Already up to date.

# Run main file
Done


17:00 21-10-2025

# Get in right directory

# Get up to date
Already up to date.

# Run main file
Done


17:30 21-10-2025

# Get in right directory

# Get up to date
Already up to date.

# Run main file
Done


18:00 21-10-2025

# Get in right directory

# Get up to date
Already up to date.

# Run main file
Done


18:30 21-10-2025

# Get in right directory

# Get up to date
Already up to date.

# Run main file
Done


19:00 21-10-2025

# Get in right directory

# Get up to date
Already up to date.

# Run main file
Done


19:30 21-10-2025

# Get in right directory

# Get up to date
Already up to date.

# Run main file
Done


20:00 21-10-2025

# Get in right directory

# Get up to date
Already up to date.

# Run main file
Done


20:30 21-10-2025

# Get in right directory

# Get up to date
Already up to date.

# Run main file
Done


21:00 21-10-2025

# Get in right directory

# Get up to date
Already up to date.

# Run main file
Done


21:30 21-10-2025

# Get in right directory

# Get up to date
Already up to date.

# Run main file
Done


22:00 21-10-2025

# Get in right directory

# Get up to date
Already up to date.

# Run main file
Done


22:30 21-10-2025

# Get in right directory

# Get up to date
Already up to date.

# Run main file
Done


23:00 21-10-2025

# Get in right directory

# Get up to date
Already up to date.

# Run main file
Done


23:30 21-10-2025

# Get in right directory

# Get up to date
Already up to date.

# Run main file
Done


00:00 22-10-2025

# Get in right directory

# Get up to date
Already up to date.

# Run main file
Done


00:30 22-10-2025

# Get in right directory

# Get up to date
Already up to date.

# Run main file
Done


01:00 22-10-2025

# Get in right directory

# Get up to date
Already up to date.

# Run main file
Done


01:30 22-10-2025

# Get in right directory

# Get up to date
Already up to date.

# Run main file
Done


02:00 22-10-2025

# Get in right directory

# Get up to date
Already up to date.

# Run main file
Done


02:30 22-10-2025

# Get in right directory

# Get up to date
Already up to date.

# Run main file
Done


03:00 22-10-2025

# Get in right directory

# Get up to date
Already up to date.

# Run main file
Done


03:30 22-10-2025

# Get in right directory

# Get up to date
Already up to date.

# Run main file
Done


04:00 22-10-2025

# Get in right directory

# Get up to date
Already up to date.

# Run main file
Done


04:30 22-10-2025

# Get in right directory

# Get up to date
Already up to date.

# Run main file
Done


05:00 22-10-2025

# Get in right directory

# Get up to date
Already up to date.

# Run main file
Done


05:30 22-10-2025

# Get in right directory

# Get up to date
Already up to date.

# Run main file
Done


06:00 22-10-2025

# Get in right directory

# Get up to date
Already up to date.

# Run main file
Done


06:30 22-10-2025

# Get in right directory

# Get up to date
Already up to date.

# Run main file
Done


07:00 22-10-2025

# Get in right directory

# Get up to date
Already up to date.

# Run main file
Done


07:30 22-10-2025

# Get in right directory

# Get up to date
Already up to date.

# Run main file
Done


08:00 22-10-2025

# Get in right directory

# Get up to date
Already up to date.

# Run main file
Done


08:30 22-10-2025

# Get in right directory

# Get up to date
Already up to date.

# Run main file
Done


09:00 22-10-2025

# Get in right directory

# Get up to date
Already up to date.

# Run main file
Done


09:30 22-10-2025

# Get in right directory

# Get up to date
Already up to date.

# Run main file
Done


10:00 22-10-2025

# Get in right directory

# Get up to date
Already up to date.

# Run main file
Done


10:30 22-10-2025

# Get in right directory

# Get up to date
Already up to date.

# Run main file
Done


11:00 22-10-2025

# Get in right directory

# Get up to date
Already up to date.

# Run main file
Done


11:30 22-10-2025

# Get in right directory

# Get up to date
Already up to date.

# Run main file
Done


12:00 22-10-2025

# Get in right directory

# Get up to date
Already up to date.

# Run main file
Done


12:30 22-10-2025

# Get in right directory

# Get up to date
Already up to date.

# Run main file
Done


13:00 22-10-2025

# Get in right directory

# Get up to date
Already up to date.

# Run main file
Done


13:30 22-10-2025

# Get in right directory

# Get up to date
Already up to date.

# Run main file
Done


14:00 22-10-2025

# Get in right directory

# Get up to date
Already up to date.

# Run main file
Done


14:30 22-10-2025

# Get in right directory

# Get up to date
Already up to date.

# Run main file
Done


15:00 22-10-2025

# Get in right directory

# Get up to date
Already up to date.

# Run main file
Done


15:30 22-10-2025

# Get in right directory

# Get up to date
Already up to date.

# Run main file
Done


16:00 22-10-2025

# Get in right directory

# Get up to date
Already up to date.

# Run main file
Done


16:30 22-10-2025

# Get in right directory

# Get up to date
Already up to date.

# Run main file
Done


17:00 22-10-2025

# Get in right directory

# Get up to date
Already up to date.

# Run main file
Done


17:30 22-10-2025

# Get in right directory

# Get up to date
Already up to date.

# Run main file
Done


18:00 22-10-2025

# Get in right directory

# Get up to date
Already up to date.

# Run main file
Done


18:30 22-10-2025

# Get in right directory

# Get up to date
Already up to date.

# Run main file
Done


19:00 22-10-2025

# Get in right directory

# Get up to date
Already up to date.

# Run main file
Done


19:30 22-10-2025

# Get in right directory

# Get up to date
Already up to date.

# Run main file
Done


20:00 22-10-2025

# Get in right directory

# Get up to date
Already up to date.

# Run main file
Done


20:30 22-10-2025

# Get in right directory

# Get up to date
Already up to date.

# Run main file
Done


21:00 22-10-2025

# Get in right directory

# Get up to date
Already up to date.

# Run main file
Done


21:30 22-10-2025

# Get in right directory

# Get up to date
Already up to date.

# Run main file
Done


22:00 22-10-2025

# Get in right directory

# Get up to date
Already up to date.

# Run main file
Done


22:30 22-10-2025

# Get in right directory

# Get up to date
Already up to date.

# Run main file
Done


23:00 22-10-2025

# Get in right directory

# Get up to date
Already up to date.

# Run main file
Done


23:30 22-10-2025

# Get in right directory

# Get up to date
Already up to date.

# Run main file
Done


00:00 23-10-2025

# Get in right directory

# Get up to date
Already up to date.

# Run main file
Done


00:30 23-10-2025

# Get in right directory

# Get up to date
Already up to date.

# Run main file
Done


01:00 23-10-2025

# Get in right directory

# Get up to date
Already up to date.

# Run main file
Done


01:30 23-10-2025

# Get in right directory

# Get up to date
Already up to date.

# Run main file
Done


02:00 23-10-2025

# Get in right directory

# Get up to date
Already up to date.

# Run main file
Done


02:30 23-10-2025

# Get in right directory

# Get up to date
Already up to date.

# Run main file
Done


03:00 23-10-2025

# Get in right directory

# Get up to date
Already up to date.

# Run main file
Done


03:30 23-10-2025

# Get in right directory

# Get up to date
Already up to date.

# Run main file
Done


04:00 23-10-2025

# Get in right directory

# Get up to date
Already up to date.

# Run main file
Done


04:30 23-10-2025

# Get in right directory

# Get up to date
Already up to date.

# Run main file
Done


05:00 23-10-2025

# Get in right directory

# Get up to date
Already up to date.

# Run main file
Done


05:30 23-10-2025

# Get in right directory

# Get up to date
Already up to date.

# Run main file
Done


06:00 23-10-2025

# Get in right directory

# Get up to date
Already up to date.

# Run main file
Done


06:30 23-10-2025

# Get in right directory

# Get up to date
Already up to date.

# Run main file
Done


07:00 23-10-2025

# Get in right directory

# Get up to date
Already up to date.

# Run main file
Done


07:30 23-10-2025

# Get in right directory

# Get up to date
Already up to date.

# Run main file
Done


08:00 23-10-2025

# Get in right directory

# Get up to date
Already up to date.

# Run main file
Done


08:30 23-10-2025

# Get in right directory

# Get up to date
Already up to date.

# Run main file
Done


09:00 23-10-2025

# Get in right directory

# Get up to date
Already up to date.

# Run main file
Done


09:30 23-10-2025

# Get in right directory

# Get up to date
Already up to date.

# Run main file
Done


10:00 23-10-2025

# Get in right directory

# Get up to date
Already up to date.

# Run main file
Done


10:30 23-10-2025

# Get in right directory

# Get up to date
Already up to date.

# Run main file
Done


11:00 23-10-2025

# Get in right directory

# Get up to date
Already up to date.

# Run main file
Done


11:30 23-10-2025

# Get in right directory

# Get up to date
Already up to date.

# Run main file
Done


12:00 23-10-2025

# Get in right directory

# Get up to date
Already up to date.

# Run main file
Done


12:30 23-10-2025

# Get in right directory

# Get up to date
Already up to date.

# Run main file
Done


13:00 23-10-2025

# Get in right directory

# Get up to date
Already up to date.

# Run main file
Done


13:30 23-10-2025

# Get in right directory

# Get up to date
Already up to date.

# Run main file
Done


14:00 23-10-2025

# Get in right directory

# Get up to date
Already up to date.

# Run main file
Done


14:30 23-10-2025

# Get in right directory

# Get up to date
Already up to date.

# Run main file
Done


15:00 23-10-2025

# Get in right directory

# Get up to date
Already up to date.

# Run main file
Done


15:30 23-10-2025

# Get in right directory

# Get up to date
Already up to date.

# Run main file
Done


16:00 23-10-2025

# Get in right directory

# Get up to date
Already up to date.

# Run main file
Done


16:30 23-10-2025

# Get in right directory

# Get up to date
Already up to date.

# Run main file
Done


17:00 23-10-2025

# Get in right directory

# Get up to date
Already up to date.

# Run main file
Done


17:30 23-10-2025

# Get in right directory

# Get up to date
Already up to date.

# Run main file
Done


18:00 23-10-2025

# Get in right directory

# Get up to date
Already up to date.

# Run main file
Done


18:30 23-10-2025

# Get in right directory

# Get up to date
Already up to date.

# Run main file
Done


19:00 23-10-2025

# Get in right directory

# Get up to date
Already up to date.

# Run main file
Done


19:30 23-10-2025

# Get in right directory

# Get up to date
Already up to date.

# Run main file
Done


20:00 23-10-2025

# Get in right directory

# Get up to date
Already up to date.

# Run main file
Done


20:30 23-10-2025

# Get in right directory

# Get up to date
Already up to date.

# Run main file
Done


21:00 23-10-2025

# Get in right directory

# Get up to date
Already up to date.

# Run main file
Done


21:30 23-10-2025

# Get in right directory

# Get up to date
Already up to date.

# Run main file
Done


22:00 23-10-2025

# Get in right directory

# Get up to date
Already up to date.

# Run main file
Done


22:30 23-10-2025

# Get in right directory

# Get up to date
Already up to date.

# Run main file
Done


23:00 23-10-2025

# Get in right directory

# Get up to date
Already up to date.

# Run main file
Done


23:30 23-10-2025

# Get in right directory

# Get up to date
Already up to date.

# Run main file
Done


00:00 24-10-2025

# Get in right directory

# Get up to date
Already up to date.

# Run main file
Done


00:30 24-10-2025

# Get in right directory

# Get up to date
Already up to date.

# Run main file
Done


01:00 24-10-2025

# Get in right directory

# Get up to date
Already up to date.

# Run main file
Done


01:30 24-10-2025

# Get in right directory

# Get up to date
Already up to date.

# Run main file
Done


02:00 24-10-2025

# Get in right directory

# Get up to date
Already up to date.

# Run main file
Done


02:30 24-10-2025

# Get in right directory

# Get up to date
Already up to date.

# Run main file
Done


03:00 24-10-2025

# Get in right directory

# Get up to date
Already up to date.

# Run main file
Done


03:30 24-10-2025

# Get in right directory

# Get up to date
Already up to date.

# Run main file
Done


04:00 24-10-2025

# Get in right directory

# Get up to date
Already up to date.

# Run main file
Done


04:30 24-10-2025

# Get in right directory

# Get up to date
Already up to date.

# Run main file
Done


05:00 24-10-2025

# Get in right directory

# Get up to date
Already up to date.

# Run main file
Done


05:30 24-10-2025

# Get in right directory

# Get up to date
Already up to date.

# Run main file
Done


06:00 24-10-2025

# Get in right directory

# Get up to date
Already up to date.

# Run main file
Done


06:30 24-10-2025

# Get in right directory

# Get up to date
Already up to date.

# Run main file
Done


07:00 24-10-2025

# Get in right directory

# Get up to date
Already up to date.

# Run main file
Done


07:30 24-10-2025

# Get in right directory

# Get up to date
Already up to date.

# Run main file
Done


08:00 24-10-2025

# Get in right directory

# Get up to date
Already up to date.

# Run main file
Done


08:30 24-10-2025

# Get in right directory

# Get up to date
Already up to date.

# Run main file
Done


09:00 24-10-2025

# Get in right directory

# Get up to date
Already up to date.

# Run main file
Done


09:30 24-10-2025

# Get in right directory

# Get up to date
Already up to date.

# Run main file
Done


10:00 24-10-2025

# Get in right directory

# Get up to date
Already up to date.

# Run main file
Done


10:30 24-10-2025

# Get in right directory

# Get up to date
Already up to date.

# Run main file
Done


11:00 24-10-2025

# Get in right directory

# Get up to date
Already up to date.

# Run main file
Done


11:30 24-10-2025

# Get in right directory

# Get up to date
Already up to date.

# Run main file
Done


12:00 24-10-2025

# Get in right directory

# Get up to date
Already up to date.

# Run main file
Done


12:30 24-10-2025

# Get in right directory

# Get up to date
Already up to date.

# Run main file
Done


13:00 24-10-2025

# Get in right directory

# Get up to date
Already up to date.

# Run main file
Done


13:30 24-10-2025

# Get in right directory

# Get up to date
Already up to date.

# Run main file
Done


14:00 24-10-2025

# Get in right directory

# Get up to date
Already up to date.

# Run main file
Done


14:30 24-10-2025

# Get in right directory

# Get up to date
Already up to date.

# Run main file
Done


15:00 24-10-2025

# Get in right directory

# Get up to date
Already up to date.

# Run main file
Done


15:30 24-10-2025

# Get in right directory

# Get up to date
Already up to date.

# Run main file
Done


16:00 24-10-2025

# Get in right directory

# Get up to date
Already up to date.

# Run main file
Done


16:30 24-10-2025

# Get in right directory

# Get up to date
Already up to date.

# Run main file
Done


17:00 24-10-2025

# Get in right directory

# Get up to date
Already up to date.

# Run main file
Done


17:30 24-10-2025

# Get in right directory

# Get up to date
Already up to date.

# Run main file
Done


18:00 24-10-2025

# Get in right directory

# Get up to date
Already up to date.

# Run main file
Done


18:30 24-10-2025

# Get in right directory

# Get up to date
Already up to date.

# Run main file
Done


19:00 24-10-2025

# Get in right directory

# Get up to date
Already up to date.

# Run main file
Done


19:30 24-10-2025

# Get in right directory

# Get up to date
Already up to date.

# Run main file
Done


20:00 24-10-2025

# Get in right directory

# Get up to date
Already up to date.

# Run main file
Done


20:30 24-10-2025

# Get in right directory

# Get up to date
Already up to date.

# Run main file
Done


21:00 24-10-2025

# Get in right directory

# Get up to date
Already up to date.

# Run main file
Done


21:30 24-10-2025

# Get in right directory

# Get up to date
Already up to date.

# Run main file
Done


22:00 24-10-2025

# Get in right directory

# Get up to date
Already up to date.

# Run main file
Done


22:30 24-10-2025

# Get in right directory

# Get up to date
Already up to date.

# Run main file
Done


23:00 24-10-2025

# Get in right directory

# Get up to date
Already up to date.

# Run main file
Done


23:30 24-10-2025

# Get in right directory

# Get up to date
Already up to date.

# Run main file
Done


00:00 25-10-2025

# Get in right directory

# Get up to date
Already up to date.

# Run main file
Done


00:30 25-10-2025

# Get in right directory

# Get up to date
Already up to date.

# Run main file
Done


01:00 25-10-2025

# Get in right directory

# Get up to date
Already up to date.

# Run main file
Done


01:30 25-10-2025

# Get in right directory

# Get up to date
Already up to date.

# Run main file
Done


02:00 25-10-2025

# Get in right directory

# Get up to date
Already up to date.

# Run main file
Done


02:30 25-10-2025

# Get in right directory

# Get up to date
Already up to date.

# Run main file
Done


03:00 25-10-2025

# Get in right directory

# Get up to date
Already up to date.

# Run main file
Done


03:30 25-10-2025

# Get in right directory

# Get up to date
Already up to date.

# Run main file
Done


04:00 25-10-2025

# Get in right directory

# Get up to date
Already up to date.

# Run main file
Done


04:30 25-10-2025

# Get in right directory

# Get up to date
Already up to date.

# Run main file
Done


05:00 25-10-2025

# Get in right directory

# Get up to date
Already up to date.

# Run main file
Done


05:30 25-10-2025

# Get in right directory

# Get up to date
Already up to date.

# Run main file
Done


06:00 25-10-2025

# Get in right directory

# Get up to date
Already up to date.

# Run main file
Done


06:30 25-10-2025

# Get in right directory

# Get up to date
Already up to date.

# Run main file
Done


07:00 25-10-2025

# Get in right directory

# Get up to date
Already up to date.

# Run main file
Done


07:30 25-10-2025

# Get in right directory

# Get up to date
Already up to date.

# Run main file
Done


08:00 25-10-2025

# Get in right directory

# Get up to date
Already up to date.

# Run main file
Done


08:30 25-10-2025

# Get in right directory

# Get up to date
Already up to date.

# Run main file
Done


09:00 25-10-2025

# Get in right directory

# Get up to date
Already up to date.

# Run main file
Done


09:30 25-10-2025

# Get in right directory

# Get up to date
Already up to date.

# Run main file
Done


10:00 25-10-2025

# Get in right directory

# Get up to date
Already up to date.

# Run main file
Done


10:30 25-10-2025

# Get in right directory

# Get up to date
Already up to date.

# Run main file
Done


11:00 25-10-2025

# Get in right directory

# Get up to date
Already up to date.

# Run main file
Done


11:30 25-10-2025

# Get in right directory

# Get up to date
Already up to date.

# Run main file
Done


12:00 25-10-2025

# Get in right directory

# Get up to date
Already up to date.

# Run main file
Done


12:30 25-10-2025

# Get in right directory

# Get up to date
Already up to date.

# Run main file
Done


13:00 25-10-2025

# Get in right directory

# Get up to date
Already up to date.

# Run main file
Done


13:30 25-10-2025

# Get in right directory

# Get up to date
Already up to date.

# Run main file
Done


14:00 25-10-2025

# Get in right directory

# Get up to date
Already up to date.

# Run main file
Done


14:30 25-10-2025

# Get in right directory

# Get up to date
Already up to date.

# Run main file
Done


15:00 25-10-2025

# Get in right directory

# Get up to date
Already up to date.

# Run main file
Done


15:30 25-10-2025

# Get in right directory

# Get up to date
Already up to date.

# Run main file
Done


16:00 25-10-2025

# Get in right directory

# Get up to date
Already up to date.

# Run main file
Done


16:30 25-10-2025

# Get in right directory

# Get up to date
Already up to date.

# Run main file
Done


17:00 25-10-2025

# Get in right directory

# Get up to date
Already up to date.

# Run main file
Done


17:30 25-10-2025

# Get in right directory

# Get up to date
Already up to date.

# Run main file
Done


18:00 25-10-2025

# Get in right directory

# Get up to date
Already up to date.

# Run main file
Done


18:30 25-10-2025

# Get in right directory

# Get up to date
Already up to date.

# Run main file
Done


19:00 25-10-2025

# Get in right directory

# Get up to date
Already up to date.

# Run main file
Done


19:30 25-10-2025

# Get in right directory

# Get up to date
Already up to date.

# Run main file
Done


20:00 25-10-2025

# Get in right directory

# Get up to date
Already up to date.

# Run main file
Done


20:30 25-10-2025

# Get in right directory

# Get up to date
Already up to date.

# Run main file
Done


21:00 25-10-2025

# Get in right directory

# Get up to date
Already up to date.

# Run main file
Done


21:30 25-10-2025

# Get in right directory

# Get up to date
Already up to date.

# Run main file
Done


22:00 25-10-2025

# Get in right directory

# Get up to date
Already up to date.

# Run main file
Done


22:30 25-10-2025

# Get in right directory

# Get up to date
Already up to date.

# Run main file
Done


23:00 25-10-2025

# Get in right directory

# Get up to date
Already up to date.

# Run main file
Done


23:30 25-10-2025

# Get in right directory

# Get up to date
Already up to date.

# Run main file
Done


00:00 26-10-2025

# Get in right directory

# Get up to date
Already up to date.

# Run main file
Done


00:30 26-10-2025

# Get in right directory

# Get up to date
Already up to date.

# Run main file
Done


01:00 26-10-2025

# Get in right directory

# Get up to date
Already up to date.

# Run main file
Done


01:30 26-10-2025

# Get in right directory

# Get up to date
Already up to date.

# Run main file
Done


02:00 26-10-2025

# Get in right directory

# Get up to date
Already up to date.

# Run main file
Done


02:30 26-10-2025

# Get in right directory

# Get up to date
Already up to date.

# Run main file
Done


02:00 26-10-2025

# Get in right directory

# Get up to date
Already up to date.

# Run main file
Done


02:30 26-10-2025

# Get in right directory

# Get up to date
Already up to date.

# Run main file
Done


03:00 26-10-2025

# Get in right directory

# Get up to date
Already up to date.

# Run main file
Done


03:30 26-10-2025

# Get in right directory

# Get up to date
Already up to date.

# Run main file
Done


04:00 26-10-2025

# Get in right directory

# Get up to date
Already up to date.

# Run main file
Done


04:30 26-10-2025

# Get in right directory

# Get up to date
Already up to date.

# Run main file
Done


05:00 26-10-2025

# Get in right directory

# Get up to date
Already up to date.

# Run main file
Done


05:30 26-10-2025

# Get in right directory

# Get up to date
Already up to date.

# Run main file
Done


06:00 26-10-2025

# Get in right directory

# Get up to date
Already up to date.

# Run main file
Done


06:31 26-10-2025

# Get in right directory

# Get up to date
fatal: unable to access 'https://github.com/LaurensGamet/Somtoday_Agendas.git/': Could not resolve host: github.com

# Run main file
Traceback (most recent call last):
  File "/usr/lib/python3/dist-packages/urllib3/connection.py", line 203, in _new_conn
    sock = connection.create_connection(
           ^^^^^^^^^^^^^^^^^^^^^^^^^^^^^
  File "/usr/lib/python3/dist-packages/urllib3/util/connection.py", line 60, in create_connection
    for res in socket.getaddrinfo(host, port, family, socket.SOCK_STREAM):
               ^^^^^^^^^^^^^^^^^^^^^^^^^^^^^^^^^^^^^^^^^^^^^^^^^^^^^^^^^^
  File "/usr/lib/python3.12/socket.py", line 963, in getaddrinfo
    for res in _socket.getaddrinfo(host, port, family, type, proto, flags):
               ^^^^^^^^^^^^^^^^^^^^^^^^^^^^^^^^^^^^^^^^^^^^^^^^^^^^^^^^^^^
socket.gaierror: [Errno -3] Temporary failure in name resolution

The above exception was the direct cause of the following exception:

Traceback (most recent call last):
  File "/usr/lib/python3/dist-packages/urllib3/connectionpool.py", line 791, in urlopen
    response = self._make_request(
               ^^^^^^^^^^^^^^^^^^^
  File "/usr/lib/python3/dist-packages/urllib3/connectionpool.py", line 492, in _make_request
    raise new_e
  File "/usr/lib/python3/dist-packages/urllib3/connectionpool.py", line 468, in _make_request
    self._validate_conn(conn)
  File "/usr/lib/python3/dist-packages/urllib3/connectionpool.py", line 1097, in _validate_conn
    conn.connect()
  File "/usr/lib/python3/dist-packages/urllib3/connection.py", line 611, in connect
    self.sock = sock = self._new_conn()
                       ^^^^^^^^^^^^^^^^
  File "/usr/lib/python3/dist-packages/urllib3/connection.py", line 210, in _new_conn
    raise NameResolutionError(self.host, self, e) from e
urllib3.exceptions.NameResolutionError: <urllib3.connection.HTTPSConnection object at 0x73643988e7e0>: Failed to resolve 'rsgrijks.zportal.nl' ([Errno -3] Temporary failure in name resolution)

The above exception was the direct cause of the following exception:

Traceback (most recent call last):
  File "/usr/lib/python3/dist-packages/requests/adapters.py", line 486, in send
    resp = conn.urlopen(
           ^^^^^^^^^^^^^
  File "/usr/lib/python3/dist-packages/urllib3/connectionpool.py", line 845, in urlopen
    retries = retries.increment(
              ^^^^^^^^^^^^^^^^^^
  File "/usr/lib/python3/dist-packages/urllib3/util/retry.py", line 517, in increment
    raise MaxRetryError(_pool, url, reason) from reason  # type: ignore[arg-type]
    ^^^^^^^^^^^^^^^^^^^^^^^^^^^^^^^^^^^^^^^^^^^^^^^^^^^
urllib3.exceptions.MaxRetryError: HTTPSConnectionPool(host='rsgrijks.zportal.nl', port=443): Max retries exceeded with url: /api/v3/ical?access_token=mc24jkscuoqntcvkuqom8nt8uh&startWeekOffset=0&endWeekOffset=1&valid=true&user=~me (Caused by NameResolutionError("<urllib3.connection.HTTPSConnection object at 0x73643988e7e0>: Failed to resolve 'rsgrijks.zportal.nl' ([Errno -3] Temporary failure in name resolution)"))

During handling of the above exception, another exception occurred:

Traceback (most recent call last):
  File "/home/laurens/Somtoday_Agendas/Loukas/main.py", line 36, in <module>
    r = requests.get(url, allow_redirects=True)
        ^^^^^^^^^^^^^^^^^^^^^^^^^^^^^^^^^^^^^^^
  File "/usr/lib/python3/dist-packages/requests/api.py", line 73, in get
    return request("get", url, params=params, **kwargs)
           ^^^^^^^^^^^^^^^^^^^^^^^^^^^^^^^^^^^^^^^^^^^^
  File "/usr/lib/python3/dist-packages/requests/api.py", line 59, in request
    return session.request(method=method, url=url, **kwargs)
           ^^^^^^^^^^^^^^^^^^^^^^^^^^^^^^^^^^^^^^^^^^^^^^^^^
  File "/usr/lib/python3/dist-packages/requests/sessions.py", line 589, in request
    resp = self.send(prep, **send_kwargs)
           ^^^^^^^^^^^^^^^^^^^^^^^^^^^^^^
  File "/usr/lib/python3/dist-packages/requests/sessions.py", line 703, in send
    r = adapter.send(request, **kwargs)
        ^^^^^^^^^^^^^^^^^^^^^^^^^^^^^^^
  File "/usr/lib/python3/dist-packages/requests/adapters.py", line 519, in send
    raise ConnectionError(e, request=request)
requests.exceptions.ConnectionError: HTTPSConnectionPool(host='rsgrijks.zportal.nl', port=443): Max retries exceeded with url: /api/v3/ical?access_token=mc24jkscuoqntcvkuqom8nt8uh&startWeekOffset=0&endWeekOffset=1&valid=true&user=~me (Caused by NameResolutionError("<urllib3.connection.HTTPSConnection object at 0x73643988e7e0>: Failed to resolve 'rsgrijks.zportal.nl' ([Errno -3] Temporary failure in name resolution)"))
Done


07:01 26-10-2025

# Get in right directory

# Get up to date
fatal: unable to access 'https://github.com/LaurensGamet/Somtoday_Agendas.git/': Could not resolve host: github.com

# Run main file
The file does not exist
Traceback (most recent call last):
  File "/usr/lib/python3/dist-packages/urllib3/connection.py", line 203, in _new_conn
    sock = connection.create_connection(
           ^^^^^^^^^^^^^^^^^^^^^^^^^^^^^
  File "/usr/lib/python3/dist-packages/urllib3/util/connection.py", line 60, in create_connection
    for res in socket.getaddrinfo(host, port, family, socket.SOCK_STREAM):
               ^^^^^^^^^^^^^^^^^^^^^^^^^^^^^^^^^^^^^^^^^^^^^^^^^^^^^^^^^^
  File "/usr/lib/python3.12/socket.py", line 963, in getaddrinfo
    for res in _socket.getaddrinfo(host, port, family, type, proto, flags):
               ^^^^^^^^^^^^^^^^^^^^^^^^^^^^^^^^^^^^^^^^^^^^^^^^^^^^^^^^^^^
socket.gaierror: [Errno -3] Temporary failure in name resolution

The above exception was the direct cause of the following exception:

Traceback (most recent call last):
  File "/usr/lib/python3/dist-packages/urllib3/connectionpool.py", line 791, in urlopen
    response = self._make_request(
               ^^^^^^^^^^^^^^^^^^^
  File "/usr/lib/python3/dist-packages/urllib3/connectionpool.py", line 492, in _make_request
    raise new_e
  File "/usr/lib/python3/dist-packages/urllib3/connectionpool.py", line 468, in _make_request
    self._validate_conn(conn)
  File "/usr/lib/python3/dist-packages/urllib3/connectionpool.py", line 1097, in _validate_conn
    conn.connect()
  File "/usr/lib/python3/dist-packages/urllib3/connection.py", line 611, in connect
    self.sock = sock = self._new_conn()
                       ^^^^^^^^^^^^^^^^
  File "/usr/lib/python3/dist-packages/urllib3/connection.py", line 210, in _new_conn
    raise NameResolutionError(self.host, self, e) from e
urllib3.exceptions.NameResolutionError: <urllib3.connection.HTTPSConnection object at 0x725d3ccfde80>: Failed to resolve 'rsgrijks.zportal.nl' ([Errno -3] Temporary failure in name resolution)

The above exception was the direct cause of the following exception:

Traceback (most recent call last):
  File "/usr/lib/python3/dist-packages/requests/adapters.py", line 486, in send
    resp = conn.urlopen(
           ^^^^^^^^^^^^^
  File "/usr/lib/python3/dist-packages/urllib3/connectionpool.py", line 845, in urlopen
    retries = retries.increment(
              ^^^^^^^^^^^^^^^^^^
  File "/usr/lib/python3/dist-packages/urllib3/util/retry.py", line 517, in increment
    raise MaxRetryError(_pool, url, reason) from reason  # type: ignore[arg-type]
    ^^^^^^^^^^^^^^^^^^^^^^^^^^^^^^^^^^^^^^^^^^^^^^^^^^^
urllib3.exceptions.MaxRetryError: HTTPSConnectionPool(host='rsgrijks.zportal.nl', port=443): Max retries exceeded with url: /api/v3/ical?access_token=mc24jkscuoqntcvkuqom8nt8uh&startWeekOffset=0&endWeekOffset=1&valid=true&user=~me (Caused by NameResolutionError("<urllib3.connection.HTTPSConnection object at 0x725d3ccfde80>: Failed to resolve 'rsgrijks.zportal.nl' ([Errno -3] Temporary failure in name resolution)"))

During handling of the above exception, another exception occurred:

Traceback (most recent call last):
  File "/home/laurens/Somtoday_Agendas/Loukas/main.py", line 36, in <module>
    r = requests.get(url, allow_redirects=True)
        ^^^^^^^^^^^^^^^^^^^^^^^^^^^^^^^^^^^^^^^
  File "/usr/lib/python3/dist-packages/requests/api.py", line 73, in get
    return request("get", url, params=params, **kwargs)
           ^^^^^^^^^^^^^^^^^^^^^^^^^^^^^^^^^^^^^^^^^^^^
  File "/usr/lib/python3/dist-packages/requests/api.py", line 59, in request
    return session.request(method=method, url=url, **kwargs)
           ^^^^^^^^^^^^^^^^^^^^^^^^^^^^^^^^^^^^^^^^^^^^^^^^^
  File "/usr/lib/python3/dist-packages/requests/sessions.py", line 589, in request
    resp = self.send(prep, **send_kwargs)
           ^^^^^^^^^^^^^^^^^^^^^^^^^^^^^^
  File "/usr/lib/python3/dist-packages/requests/sessions.py", line 703, in send
    r = adapter.send(request, **kwargs)
        ^^^^^^^^^^^^^^^^^^^^^^^^^^^^^^^
  File "/usr/lib/python3/dist-packages/requests/adapters.py", line 519, in send
    raise ConnectionError(e, request=request)
requests.exceptions.ConnectionError: HTTPSConnectionPool(host='rsgrijks.zportal.nl', port=443): Max retries exceeded with url: /api/v3/ical?access_token=mc24jkscuoqntcvkuqom8nt8uh&startWeekOffset=0&endWeekOffset=1&valid=true&user=~me (Caused by NameResolutionError("<urllib3.connection.HTTPSConnection object at 0x725d3ccfde80>: Failed to resolve 'rsgrijks.zportal.nl' ([Errno -3] Temporary failure in name resolution)"))
Done


07:31 26-10-2025

# Get in right directory

# Get up to date
fatal: unable to access 'https://github.com/LaurensGamet/Somtoday_Agendas.git/': Could not resolve host: github.com

# Run main file
The file does not exist
Traceback (most recent call last):
  File "/usr/lib/python3/dist-packages/urllib3/connection.py", line 203, in _new_conn
    sock = connection.create_connection(
           ^^^^^^^^^^^^^^^^^^^^^^^^^^^^^
  File "/usr/lib/python3/dist-packages/urllib3/util/connection.py", line 60, in create_connection
    for res in socket.getaddrinfo(host, port, family, socket.SOCK_STREAM):
               ^^^^^^^^^^^^^^^^^^^^^^^^^^^^^^^^^^^^^^^^^^^^^^^^^^^^^^^^^^
  File "/usr/lib/python3.12/socket.py", line 963, in getaddrinfo
    for res in _socket.getaddrinfo(host, port, family, type, proto, flags):
               ^^^^^^^^^^^^^^^^^^^^^^^^^^^^^^^^^^^^^^^^^^^^^^^^^^^^^^^^^^^
socket.gaierror: [Errno -3] Temporary failure in name resolution

The above exception was the direct cause of the following exception:

Traceback (most recent call last):
  File "/usr/lib/python3/dist-packages/urllib3/connectionpool.py", line 791, in urlopen
    response = self._make_request(
               ^^^^^^^^^^^^^^^^^^^
  File "/usr/lib/python3/dist-packages/urllib3/connectionpool.py", line 492, in _make_request
    raise new_e
  File "/usr/lib/python3/dist-packages/urllib3/connectionpool.py", line 468, in _make_request
    self._validate_conn(conn)
  File "/usr/lib/python3/dist-packages/urllib3/connectionpool.py", line 1097, in _validate_conn
    conn.connect()
  File "/usr/lib/python3/dist-packages/urllib3/connection.py", line 611, in connect
    self.sock = sock = self._new_conn()
                       ^^^^^^^^^^^^^^^^
  File "/usr/lib/python3/dist-packages/urllib3/connection.py", line 210, in _new_conn
    raise NameResolutionError(self.host, self, e) from e
urllib3.exceptions.NameResolutionError: <urllib3.connection.HTTPSConnection object at 0x779f215b0a10>: Failed to resolve 'rsgrijks.zportal.nl' ([Errno -3] Temporary failure in name resolution)

The above exception was the direct cause of the following exception:

Traceback (most recent call last):
  File "/usr/lib/python3/dist-packages/requests/adapters.py", line 486, in send
    resp = conn.urlopen(
           ^^^^^^^^^^^^^
  File "/usr/lib/python3/dist-packages/urllib3/connectionpool.py", line 845, in urlopen
    retries = retries.increment(
              ^^^^^^^^^^^^^^^^^^
  File "/usr/lib/python3/dist-packages/urllib3/util/retry.py", line 517, in increment
    raise MaxRetryError(_pool, url, reason) from reason  # type: ignore[arg-type]
    ^^^^^^^^^^^^^^^^^^^^^^^^^^^^^^^^^^^^^^^^^^^^^^^^^^^
urllib3.exceptions.MaxRetryError: HTTPSConnectionPool(host='rsgrijks.zportal.nl', port=443): Max retries exceeded with url: /api/v3/ical?access_token=mc24jkscuoqntcvkuqom8nt8uh&startWeekOffset=0&endWeekOffset=1&valid=true&user=~me (Caused by NameResolutionError("<urllib3.connection.HTTPSConnection object at 0x779f215b0a10>: Failed to resolve 'rsgrijks.zportal.nl' ([Errno -3] Temporary failure in name resolution)"))

During handling of the above exception, another exception occurred:

Traceback (most recent call last):
  File "/home/laurens/Somtoday_Agendas/Loukas/main.py", line 36, in <module>
    r = requests.get(url, allow_redirects=True)
        ^^^^^^^^^^^^^^^^^^^^^^^^^^^^^^^^^^^^^^^
  File "/usr/lib/python3/dist-packages/requests/api.py", line 73, in get
    return request("get", url, params=params, **kwargs)
           ^^^^^^^^^^^^^^^^^^^^^^^^^^^^^^^^^^^^^^^^^^^^
  File "/usr/lib/python3/dist-packages/requests/api.py", line 59, in request
    return session.request(method=method, url=url, **kwargs)
           ^^^^^^^^^^^^^^^^^^^^^^^^^^^^^^^^^^^^^^^^^^^^^^^^^
  File "/usr/lib/python3/dist-packages/requests/sessions.py", line 589, in request
    resp = self.send(prep, **send_kwargs)
           ^^^^^^^^^^^^^^^^^^^^^^^^^^^^^^
  File "/usr/lib/python3/dist-packages/requests/sessions.py", line 703, in send
    r = adapter.send(request, **kwargs)
        ^^^^^^^^^^^^^^^^^^^^^^^^^^^^^^^
  File "/usr/lib/python3/dist-packages/requests/adapters.py", line 519, in send
    raise ConnectionError(e, request=request)
requests.exceptions.ConnectionError: HTTPSConnectionPool(host='rsgrijks.zportal.nl', port=443): Max retries exceeded with url: /api/v3/ical?access_token=mc24jkscuoqntcvkuqom8nt8uh&startWeekOffset=0&endWeekOffset=1&valid=true&user=~me (Caused by NameResolutionError("<urllib3.connection.HTTPSConnection object at 0x779f215b0a10>: Failed to resolve 'rsgrijks.zportal.nl' ([Errno -3] Temporary failure in name resolution)"))
Done


08:01 26-10-2025

# Get in right directory

# Get up to date
fatal: unable to access 'https://github.com/LaurensGamet/Somtoday_Agendas.git/': Could not resolve host: github.com

# Run main file
The file does not exist
Traceback (most recent call last):
  File "/usr/lib/python3/dist-packages/urllib3/connection.py", line 203, in _new_conn
    sock = connection.create_connection(
           ^^^^^^^^^^^^^^^^^^^^^^^^^^^^^
  File "/usr/lib/python3/dist-packages/urllib3/util/connection.py", line 60, in create_connection
    for res in socket.getaddrinfo(host, port, family, socket.SOCK_STREAM):
               ^^^^^^^^^^^^^^^^^^^^^^^^^^^^^^^^^^^^^^^^^^^^^^^^^^^^^^^^^^
  File "/usr/lib/python3.12/socket.py", line 963, in getaddrinfo
    for res in _socket.getaddrinfo(host, port, family, type, proto, flags):
               ^^^^^^^^^^^^^^^^^^^^^^^^^^^^^^^^^^^^^^^^^^^^^^^^^^^^^^^^^^^
socket.gaierror: [Errno -3] Temporary failure in name resolution

The above exception was the direct cause of the following exception:

Traceback (most recent call last):
  File "/usr/lib/python3/dist-packages/urllib3/connectionpool.py", line 791, in urlopen
    response = self._make_request(
               ^^^^^^^^^^^^^^^^^^^
  File "/usr/lib/python3/dist-packages/urllib3/connectionpool.py", line 492, in _make_request
    raise new_e
  File "/usr/lib/python3/dist-packages/urllib3/connectionpool.py", line 468, in _make_request
    self._validate_conn(conn)
  File "/usr/lib/python3/dist-packages/urllib3/connectionpool.py", line 1097, in _validate_conn
    conn.connect()
  File "/usr/lib/python3/dist-packages/urllib3/connection.py", line 611, in connect
    self.sock = sock = self._new_conn()
                       ^^^^^^^^^^^^^^^^
  File "/usr/lib/python3/dist-packages/urllib3/connection.py", line 210, in _new_conn
    raise NameResolutionError(self.host, self, e) from e
urllib3.exceptions.NameResolutionError: <urllib3.connection.HTTPSConnection object at 0x7a41b8afde80>: Failed to resolve 'rsgrijks.zportal.nl' ([Errno -3] Temporary failure in name resolution)

The above exception was the direct cause of the following exception:

Traceback (most recent call last):
  File "/usr/lib/python3/dist-packages/requests/adapters.py", line 486, in send
    resp = conn.urlopen(
           ^^^^^^^^^^^^^
  File "/usr/lib/python3/dist-packages/urllib3/connectionpool.py", line 845, in urlopen
    retries = retries.increment(
              ^^^^^^^^^^^^^^^^^^
  File "/usr/lib/python3/dist-packages/urllib3/util/retry.py", line 517, in increment
    raise MaxRetryError(_pool, url, reason) from reason  # type: ignore[arg-type]
    ^^^^^^^^^^^^^^^^^^^^^^^^^^^^^^^^^^^^^^^^^^^^^^^^^^^
urllib3.exceptions.MaxRetryError: HTTPSConnectionPool(host='rsgrijks.zportal.nl', port=443): Max retries exceeded with url: /api/v3/ical?access_token=mc24jkscuoqntcvkuqom8nt8uh&startWeekOffset=0&endWeekOffset=1&valid=true&user=~me (Caused by NameResolutionError("<urllib3.connection.HTTPSConnection object at 0x7a41b8afde80>: Failed to resolve 'rsgrijks.zportal.nl' ([Errno -3] Temporary failure in name resolution)"))

During handling of the above exception, another exception occurred:

Traceback (most recent call last):
  File "/home/laurens/Somtoday_Agendas/Loukas/main.py", line 36, in <module>
    r = requests.get(url, allow_redirects=True)
        ^^^^^^^^^^^^^^^^^^^^^^^^^^^^^^^^^^^^^^^
  File "/usr/lib/python3/dist-packages/requests/api.py", line 73, in get
    return request("get", url, params=params, **kwargs)
           ^^^^^^^^^^^^^^^^^^^^^^^^^^^^^^^^^^^^^^^^^^^^
  File "/usr/lib/python3/dist-packages/requests/api.py", line 59, in request
    return session.request(method=method, url=url, **kwargs)
           ^^^^^^^^^^^^^^^^^^^^^^^^^^^^^^^^^^^^^^^^^^^^^^^^^
  File "/usr/lib/python3/dist-packages/requests/sessions.py", line 589, in request
    resp = self.send(prep, **send_kwargs)
           ^^^^^^^^^^^^^^^^^^^^^^^^^^^^^^
  File "/usr/lib/python3/dist-packages/requests/sessions.py", line 703, in send
    r = adapter.send(request, **kwargs)
        ^^^^^^^^^^^^^^^^^^^^^^^^^^^^^^^
  File "/usr/lib/python3/dist-packages/requests/adapters.py", line 519, in send
    raise ConnectionError(e, request=request)
requests.exceptions.ConnectionError: HTTPSConnectionPool(host='rsgrijks.zportal.nl', port=443): Max retries exceeded with url: /api/v3/ical?access_token=mc24jkscuoqntcvkuqom8nt8uh&startWeekOffset=0&endWeekOffset=1&valid=true&user=~me (Caused by NameResolutionError("<urllib3.connection.HTTPSConnection object at 0x7a41b8afde80>: Failed to resolve 'rsgrijks.zportal.nl' ([Errno -3] Temporary failure in name resolution)"))
Done


08:31 26-10-2025

# Get in right directory

# Get up to date
fatal: unable to access 'https://github.com/LaurensGamet/Somtoday_Agendas.git/': Could not resolve host: github.com

# Run main file
The file does not exist
Traceback (most recent call last):
  File "/usr/lib/python3/dist-packages/urllib3/connection.py", line 203, in _new_conn
    sock = connection.create_connection(
           ^^^^^^^^^^^^^^^^^^^^^^^^^^^^^
  File "/usr/lib/python3/dist-packages/urllib3/util/connection.py", line 60, in create_connection
    for res in socket.getaddrinfo(host, port, family, socket.SOCK_STREAM):
               ^^^^^^^^^^^^^^^^^^^^^^^^^^^^^^^^^^^^^^^^^^^^^^^^^^^^^^^^^^
  File "/usr/lib/python3.12/socket.py", line 963, in getaddrinfo
    for res in _socket.getaddrinfo(host, port, family, type, proto, flags):
               ^^^^^^^^^^^^^^^^^^^^^^^^^^^^^^^^^^^^^^^^^^^^^^^^^^^^^^^^^^^
socket.gaierror: [Errno -3] Temporary failure in name resolution

The above exception was the direct cause of the following exception:

Traceback (most recent call last):
  File "/usr/lib/python3/dist-packages/urllib3/connectionpool.py", line 791, in urlopen
    response = self._make_request(
               ^^^^^^^^^^^^^^^^^^^
  File "/usr/lib/python3/dist-packages/urllib3/connectionpool.py", line 492, in _make_request
    raise new_e
  File "/usr/lib/python3/dist-packages/urllib3/connectionpool.py", line 468, in _make_request
    self._validate_conn(conn)
  File "/usr/lib/python3/dist-packages/urllib3/connectionpool.py", line 1097, in _validate_conn
    conn.connect()
  File "/usr/lib/python3/dist-packages/urllib3/connection.py", line 611, in connect
    self.sock = sock = self._new_conn()
                       ^^^^^^^^^^^^^^^^
  File "/usr/lib/python3/dist-packages/urllib3/connection.py", line 210, in _new_conn
    raise NameResolutionError(self.host, self, e) from e
urllib3.exceptions.NameResolutionError: <urllib3.connection.HTTPSConnection object at 0x7bea00c58650>: Failed to resolve 'rsgrijks.zportal.nl' ([Errno -3] Temporary failure in name resolution)

The above exception was the direct cause of the following exception:

Traceback (most recent call last):
  File "/usr/lib/python3/dist-packages/requests/adapters.py", line 486, in send
    resp = conn.urlopen(
           ^^^^^^^^^^^^^
  File "/usr/lib/python3/dist-packages/urllib3/connectionpool.py", line 845, in urlopen
    retries = retries.increment(
              ^^^^^^^^^^^^^^^^^^
  File "/usr/lib/python3/dist-packages/urllib3/util/retry.py", line 517, in increment
    raise MaxRetryError(_pool, url, reason) from reason  # type: ignore[arg-type]
    ^^^^^^^^^^^^^^^^^^^^^^^^^^^^^^^^^^^^^^^^^^^^^^^^^^^
urllib3.exceptions.MaxRetryError: HTTPSConnectionPool(host='rsgrijks.zportal.nl', port=443): Max retries exceeded with url: /api/v3/ical?access_token=mc24jkscuoqntcvkuqom8nt8uh&startWeekOffset=0&endWeekOffset=1&valid=true&user=~me (Caused by NameResolutionError("<urllib3.connection.HTTPSConnection object at 0x7bea00c58650>: Failed to resolve 'rsgrijks.zportal.nl' ([Errno -3] Temporary failure in name resolution)"))

During handling of the above exception, another exception occurred:

Traceback (most recent call last):
  File "/home/laurens/Somtoday_Agendas/Loukas/main.py", line 36, in <module>
    r = requests.get(url, allow_redirects=True)
        ^^^^^^^^^^^^^^^^^^^^^^^^^^^^^^^^^^^^^^^
  File "/usr/lib/python3/dist-packages/requests/api.py", line 73, in get
    return request("get", url, params=params, **kwargs)
           ^^^^^^^^^^^^^^^^^^^^^^^^^^^^^^^^^^^^^^^^^^^^
  File "/usr/lib/python3/dist-packages/requests/api.py", line 59, in request
    return session.request(method=method, url=url, **kwargs)
           ^^^^^^^^^^^^^^^^^^^^^^^^^^^^^^^^^^^^^^^^^^^^^^^^^
  File "/usr/lib/python3/dist-packages/requests/sessions.py", line 589, in request
    resp = self.send(prep, **send_kwargs)
           ^^^^^^^^^^^^^^^^^^^^^^^^^^^^^^
  File "/usr/lib/python3/dist-packages/requests/sessions.py", line 703, in send
    r = adapter.send(request, **kwargs)
        ^^^^^^^^^^^^^^^^^^^^^^^^^^^^^^^
  File "/usr/lib/python3/dist-packages/requests/adapters.py", line 519, in send
    raise ConnectionError(e, request=request)
requests.exceptions.ConnectionError: HTTPSConnectionPool(host='rsgrijks.zportal.nl', port=443): Max retries exceeded with url: /api/v3/ical?access_token=mc24jkscuoqntcvkuqom8nt8uh&startWeekOffset=0&endWeekOffset=1&valid=true&user=~me (Caused by NameResolutionError("<urllib3.connection.HTTPSConnection object at 0x7bea00c58650>: Failed to resolve 'rsgrijks.zportal.nl' ([Errno -3] Temporary failure in name resolution)"))
Done


09:01 26-10-2025

# Get in right directory

# Get up to date
fatal: unable to access 'https://github.com/LaurensGamet/Somtoday_Agendas.git/': Could not resolve host: github.com

# Run main file
The file does not exist
Traceback (most recent call last):
  File "/usr/lib/python3/dist-packages/urllib3/connection.py", line 203, in _new_conn
    sock = connection.create_connection(
           ^^^^^^^^^^^^^^^^^^^^^^^^^^^^^
  File "/usr/lib/python3/dist-packages/urllib3/util/connection.py", line 60, in create_connection
    for res in socket.getaddrinfo(host, port, family, socket.SOCK_STREAM):
               ^^^^^^^^^^^^^^^^^^^^^^^^^^^^^^^^^^^^^^^^^^^^^^^^^^^^^^^^^^
  File "/usr/lib/python3.12/socket.py", line 963, in getaddrinfo
    for res in _socket.getaddrinfo(host, port, family, type, proto, flags):
               ^^^^^^^^^^^^^^^^^^^^^^^^^^^^^^^^^^^^^^^^^^^^^^^^^^^^^^^^^^^
socket.gaierror: [Errno -3] Temporary failure in name resolution

The above exception was the direct cause of the following exception:

Traceback (most recent call last):
  File "/usr/lib/python3/dist-packages/urllib3/connectionpool.py", line 791, in urlopen
    response = self._make_request(
               ^^^^^^^^^^^^^^^^^^^
  File "/usr/lib/python3/dist-packages/urllib3/connectionpool.py", line 492, in _make_request
    raise new_e
  File "/usr/lib/python3/dist-packages/urllib3/connectionpool.py", line 468, in _make_request
    self._validate_conn(conn)
  File "/usr/lib/python3/dist-packages/urllib3/connectionpool.py", line 1097, in _validate_conn
    conn.connect()
  File "/usr/lib/python3/dist-packages/urllib3/connection.py", line 611, in connect
    self.sock = sock = self._new_conn()
                       ^^^^^^^^^^^^^^^^
  File "/usr/lib/python3/dist-packages/urllib3/connection.py", line 210, in _new_conn
    raise NameResolutionError(self.host, self, e) from e
urllib3.exceptions.NameResolutionError: <urllib3.connection.HTTPSConnection object at 0x71ef47e5ab40>: Failed to resolve 'rsgrijks.zportal.nl' ([Errno -3] Temporary failure in name resolution)

The above exception was the direct cause of the following exception:

Traceback (most recent call last):
  File "/usr/lib/python3/dist-packages/requests/adapters.py", line 486, in send
    resp = conn.urlopen(
           ^^^^^^^^^^^^^
  File "/usr/lib/python3/dist-packages/urllib3/connectionpool.py", line 845, in urlopen
    retries = retries.increment(
              ^^^^^^^^^^^^^^^^^^
  File "/usr/lib/python3/dist-packages/urllib3/util/retry.py", line 517, in increment
    raise MaxRetryError(_pool, url, reason) from reason  # type: ignore[arg-type]
    ^^^^^^^^^^^^^^^^^^^^^^^^^^^^^^^^^^^^^^^^^^^^^^^^^^^
urllib3.exceptions.MaxRetryError: HTTPSConnectionPool(host='rsgrijks.zportal.nl', port=443): Max retries exceeded with url: /api/v3/ical?access_token=mc24jkscuoqntcvkuqom8nt8uh&startWeekOffset=0&endWeekOffset=1&valid=true&user=~me (Caused by NameResolutionError("<urllib3.connection.HTTPSConnection object at 0x71ef47e5ab40>: Failed to resolve 'rsgrijks.zportal.nl' ([Errno -3] Temporary failure in name resolution)"))

During handling of the above exception, another exception occurred:

Traceback (most recent call last):
  File "/home/laurens/Somtoday_Agendas/Loukas/main.py", line 36, in <module>
    r = requests.get(url, allow_redirects=True)
        ^^^^^^^^^^^^^^^^^^^^^^^^^^^^^^^^^^^^^^^
  File "/usr/lib/python3/dist-packages/requests/api.py", line 73, in get
    return request("get", url, params=params, **kwargs)
           ^^^^^^^^^^^^^^^^^^^^^^^^^^^^^^^^^^^^^^^^^^^^
  File "/usr/lib/python3/dist-packages/requests/api.py", line 59, in request
    return session.request(method=method, url=url, **kwargs)
           ^^^^^^^^^^^^^^^^^^^^^^^^^^^^^^^^^^^^^^^^^^^^^^^^^
  File "/usr/lib/python3/dist-packages/requests/sessions.py", line 589, in request
    resp = self.send(prep, **send_kwargs)
           ^^^^^^^^^^^^^^^^^^^^^^^^^^^^^^
  File "/usr/lib/python3/dist-packages/requests/sessions.py", line 703, in send
    r = adapter.send(request, **kwargs)
        ^^^^^^^^^^^^^^^^^^^^^^^^^^^^^^^
  File "/usr/lib/python3/dist-packages/requests/adapters.py", line 519, in send
    raise ConnectionError(e, request=request)
requests.exceptions.ConnectionError: HTTPSConnectionPool(host='rsgrijks.zportal.nl', port=443): Max retries exceeded with url: /api/v3/ical?access_token=mc24jkscuoqntcvkuqom8nt8uh&startWeekOffset=0&endWeekOffset=1&valid=true&user=~me (Caused by NameResolutionError("<urllib3.connection.HTTPSConnection object at 0x71ef47e5ab40>: Failed to resolve 'rsgrijks.zportal.nl' ([Errno -3] Temporary failure in name resolution)"))
Done


09:31 26-10-2025

# Get in right directory

# Get up to date
fatal: unable to access 'https://github.com/LaurensGamet/Somtoday_Agendas.git/': Could not resolve host: github.com

# Run main file
The file does not exist
Traceback (most recent call last):
  File "/usr/lib/python3/dist-packages/urllib3/connection.py", line 203, in _new_conn
    sock = connection.create_connection(
           ^^^^^^^^^^^^^^^^^^^^^^^^^^^^^
  File "/usr/lib/python3/dist-packages/urllib3/util/connection.py", line 60, in create_connection
    for res in socket.getaddrinfo(host, port, family, socket.SOCK_STREAM):
               ^^^^^^^^^^^^^^^^^^^^^^^^^^^^^^^^^^^^^^^^^^^^^^^^^^^^^^^^^^
  File "/usr/lib/python3.12/socket.py", line 963, in getaddrinfo
    for res in _socket.getaddrinfo(host, port, family, type, proto, flags):
               ^^^^^^^^^^^^^^^^^^^^^^^^^^^^^^^^^^^^^^^^^^^^^^^^^^^^^^^^^^^
socket.gaierror: [Errno -3] Temporary failure in name resolution

The above exception was the direct cause of the following exception:

Traceback (most recent call last):
  File "/usr/lib/python3/dist-packages/urllib3/connectionpool.py", line 791, in urlopen
    response = self._make_request(
               ^^^^^^^^^^^^^^^^^^^
  File "/usr/lib/python3/dist-packages/urllib3/connectionpool.py", line 492, in _make_request
    raise new_e
  File "/usr/lib/python3/dist-packages/urllib3/connectionpool.py", line 468, in _make_request
    self._validate_conn(conn)
  File "/usr/lib/python3/dist-packages/urllib3/connectionpool.py", line 1097, in _validate_conn
    conn.connect()
  File "/usr/lib/python3/dist-packages/urllib3/connection.py", line 611, in connect
    self.sock = sock = self._new_conn()
                       ^^^^^^^^^^^^^^^^
  File "/usr/lib/python3/dist-packages/urllib3/connection.py", line 210, in _new_conn
    raise NameResolutionError(self.host, self, e) from e
urllib3.exceptions.NameResolutionError: <urllib3.connection.HTTPSConnection object at 0x7af651d248c0>: Failed to resolve 'rsgrijks.zportal.nl' ([Errno -3] Temporary failure in name resolution)

The above exception was the direct cause of the following exception:

Traceback (most recent call last):
  File "/usr/lib/python3/dist-packages/requests/adapters.py", line 486, in send
    resp = conn.urlopen(
           ^^^^^^^^^^^^^
  File "/usr/lib/python3/dist-packages/urllib3/connectionpool.py", line 845, in urlopen
    retries = retries.increment(
              ^^^^^^^^^^^^^^^^^^
  File "/usr/lib/python3/dist-packages/urllib3/util/retry.py", line 517, in increment
    raise MaxRetryError(_pool, url, reason) from reason  # type: ignore[arg-type]
    ^^^^^^^^^^^^^^^^^^^^^^^^^^^^^^^^^^^^^^^^^^^^^^^^^^^
urllib3.exceptions.MaxRetryError: HTTPSConnectionPool(host='rsgrijks.zportal.nl', port=443): Max retries exceeded with url: /api/v3/ical?access_token=mc24jkscuoqntcvkuqom8nt8uh&startWeekOffset=0&endWeekOffset=1&valid=true&user=~me (Caused by NameResolutionError("<urllib3.connection.HTTPSConnection object at 0x7af651d248c0>: Failed to resolve 'rsgrijks.zportal.nl' ([Errno -3] Temporary failure in name resolution)"))

During handling of the above exception, another exception occurred:

Traceback (most recent call last):
  File "/home/laurens/Somtoday_Agendas/Loukas/main.py", line 36, in <module>
    r = requests.get(url, allow_redirects=True)
        ^^^^^^^^^^^^^^^^^^^^^^^^^^^^^^^^^^^^^^^
  File "/usr/lib/python3/dist-packages/requests/api.py", line 73, in get
    return request("get", url, params=params, **kwargs)
           ^^^^^^^^^^^^^^^^^^^^^^^^^^^^^^^^^^^^^^^^^^^^
  File "/usr/lib/python3/dist-packages/requests/api.py", line 59, in request
    return session.request(method=method, url=url, **kwargs)
           ^^^^^^^^^^^^^^^^^^^^^^^^^^^^^^^^^^^^^^^^^^^^^^^^^
  File "/usr/lib/python3/dist-packages/requests/sessions.py", line 589, in request
    resp = self.send(prep, **send_kwargs)
           ^^^^^^^^^^^^^^^^^^^^^^^^^^^^^^
  File "/usr/lib/python3/dist-packages/requests/sessions.py", line 703, in send
    r = adapter.send(request, **kwargs)
        ^^^^^^^^^^^^^^^^^^^^^^^^^^^^^^^
  File "/usr/lib/python3/dist-packages/requests/adapters.py", line 519, in send
    raise ConnectionError(e, request=request)
requests.exceptions.ConnectionError: HTTPSConnectionPool(host='rsgrijks.zportal.nl', port=443): Max retries exceeded with url: /api/v3/ical?access_token=mc24jkscuoqntcvkuqom8nt8uh&startWeekOffset=0&endWeekOffset=1&valid=true&user=~me (Caused by NameResolutionError("<urllib3.connection.HTTPSConnection object at 0x7af651d248c0>: Failed to resolve 'rsgrijks.zportal.nl' ([Errno -3] Temporary failure in name resolution)"))
Done


10:01 26-10-2025

# Get in right directory

# Get up to date
fatal: unable to access 'https://github.com/LaurensGamet/Somtoday_Agendas.git/': Could not resolve host: github.com

# Run main file
The file does not exist
Traceback (most recent call last):
  File "/usr/lib/python3/dist-packages/urllib3/connection.py", line 203, in _new_conn
    sock = connection.create_connection(
           ^^^^^^^^^^^^^^^^^^^^^^^^^^^^^
  File "/usr/lib/python3/dist-packages/urllib3/util/connection.py", line 60, in create_connection
    for res in socket.getaddrinfo(host, port, family, socket.SOCK_STREAM):
               ^^^^^^^^^^^^^^^^^^^^^^^^^^^^^^^^^^^^^^^^^^^^^^^^^^^^^^^^^^
  File "/usr/lib/python3.12/socket.py", line 963, in getaddrinfo
    for res in _socket.getaddrinfo(host, port, family, type, proto, flags):
               ^^^^^^^^^^^^^^^^^^^^^^^^^^^^^^^^^^^^^^^^^^^^^^^^^^^^^^^^^^^
socket.gaierror: [Errno -3] Temporary failure in name resolution

The above exception was the direct cause of the following exception:

Traceback (most recent call last):
  File "/usr/lib/python3/dist-packages/urllib3/connectionpool.py", line 791, in urlopen
    response = self._make_request(
               ^^^^^^^^^^^^^^^^^^^
  File "/usr/lib/python3/dist-packages/urllib3/connectionpool.py", line 492, in _make_request
    raise new_e
  File "/usr/lib/python3/dist-packages/urllib3/connectionpool.py", line 468, in _make_request
    self._validate_conn(conn)
  File "/usr/lib/python3/dist-packages/urllib3/connectionpool.py", line 1097, in _validate_conn
    conn.connect()
  File "/usr/lib/python3/dist-packages/urllib3/connection.py", line 611, in connect
    self.sock = sock = self._new_conn()
                       ^^^^^^^^^^^^^^^^
  File "/usr/lib/python3/dist-packages/urllib3/connection.py", line 210, in _new_conn
    raise NameResolutionError(self.host, self, e) from e
urllib3.exceptions.NameResolutionError: <urllib3.connection.HTTPSConnection object at 0x79d16dd8da00>: Failed to resolve 'rsgrijks.zportal.nl' ([Errno -3] Temporary failure in name resolution)

The above exception was the direct cause of the following exception:

Traceback (most recent call last):
  File "/usr/lib/python3/dist-packages/requests/adapters.py", line 486, in send
    resp = conn.urlopen(
           ^^^^^^^^^^^^^
  File "/usr/lib/python3/dist-packages/urllib3/connectionpool.py", line 845, in urlopen
    retries = retries.increment(
              ^^^^^^^^^^^^^^^^^^
  File "/usr/lib/python3/dist-packages/urllib3/util/retry.py", line 517, in increment
    raise MaxRetryError(_pool, url, reason) from reason  # type: ignore[arg-type]
    ^^^^^^^^^^^^^^^^^^^^^^^^^^^^^^^^^^^^^^^^^^^^^^^^^^^
urllib3.exceptions.MaxRetryError: HTTPSConnectionPool(host='rsgrijks.zportal.nl', port=443): Max retries exceeded with url: /api/v3/ical?access_token=mc24jkscuoqntcvkuqom8nt8uh&startWeekOffset=0&endWeekOffset=1&valid=true&user=~me (Caused by NameResolutionError("<urllib3.connection.HTTPSConnection object at 0x79d16dd8da00>: Failed to resolve 'rsgrijks.zportal.nl' ([Errno -3] Temporary failure in name resolution)"))

During handling of the above exception, another exception occurred:

Traceback (most recent call last):
  File "/home/laurens/Somtoday_Agendas/Loukas/main.py", line 36, in <module>
    r = requests.get(url, allow_redirects=True)
        ^^^^^^^^^^^^^^^^^^^^^^^^^^^^^^^^^^^^^^^
  File "/usr/lib/python3/dist-packages/requests/api.py", line 73, in get
    return request("get", url, params=params, **kwargs)
           ^^^^^^^^^^^^^^^^^^^^^^^^^^^^^^^^^^^^^^^^^^^^
  File "/usr/lib/python3/dist-packages/requests/api.py", line 59, in request
    return session.request(method=method, url=url, **kwargs)
           ^^^^^^^^^^^^^^^^^^^^^^^^^^^^^^^^^^^^^^^^^^^^^^^^^
  File "/usr/lib/python3/dist-packages/requests/sessions.py", line 589, in request
    resp = self.send(prep, **send_kwargs)
           ^^^^^^^^^^^^^^^^^^^^^^^^^^^^^^
  File "/usr/lib/python3/dist-packages/requests/sessions.py", line 703, in send
    r = adapter.send(request, **kwargs)
        ^^^^^^^^^^^^^^^^^^^^^^^^^^^^^^^
  File "/usr/lib/python3/dist-packages/requests/adapters.py", line 519, in send
    raise ConnectionError(e, request=request)
requests.exceptions.ConnectionError: HTTPSConnectionPool(host='rsgrijks.zportal.nl', port=443): Max retries exceeded with url: /api/v3/ical?access_token=mc24jkscuoqntcvkuqom8nt8uh&startWeekOffset=0&endWeekOffset=1&valid=true&user=~me (Caused by NameResolutionError("<urllib3.connection.HTTPSConnection object at 0x79d16dd8da00>: Failed to resolve 'rsgrijks.zportal.nl' ([Errno -3] Temporary failure in name resolution)"))
Done


10:31 26-10-2025

# Get in right directory

# Get up to date
fatal: unable to access 'https://github.com/LaurensGamet/Somtoday_Agendas.git/': Could not resolve host: github.com

# Run main file
The file does not exist
Traceback (most recent call last):
  File "/usr/lib/python3/dist-packages/urllib3/connection.py", line 203, in _new_conn
    sock = connection.create_connection(
           ^^^^^^^^^^^^^^^^^^^^^^^^^^^^^
  File "/usr/lib/python3/dist-packages/urllib3/util/connection.py", line 60, in create_connection
    for res in socket.getaddrinfo(host, port, family, socket.SOCK_STREAM):
               ^^^^^^^^^^^^^^^^^^^^^^^^^^^^^^^^^^^^^^^^^^^^^^^^^^^^^^^^^^
  File "/usr/lib/python3.12/socket.py", line 963, in getaddrinfo
    for res in _socket.getaddrinfo(host, port, family, type, proto, flags):
               ^^^^^^^^^^^^^^^^^^^^^^^^^^^^^^^^^^^^^^^^^^^^^^^^^^^^^^^^^^^
socket.gaierror: [Errno -3] Temporary failure in name resolution

The above exception was the direct cause of the following exception:

Traceback (most recent call last):
  File "/usr/lib/python3/dist-packages/urllib3/connectionpool.py", line 791, in urlopen
    response = self._make_request(
               ^^^^^^^^^^^^^^^^^^^
  File "/usr/lib/python3/dist-packages/urllib3/connectionpool.py", line 492, in _make_request
    raise new_e
  File "/usr/lib/python3/dist-packages/urllib3/connectionpool.py", line 468, in _make_request
    self._validate_conn(conn)
  File "/usr/lib/python3/dist-packages/urllib3/connectionpool.py", line 1097, in _validate_conn
    conn.connect()
  File "/usr/lib/python3/dist-packages/urllib3/connection.py", line 611, in connect
    self.sock = sock = self._new_conn()
                       ^^^^^^^^^^^^^^^^
  File "/usr/lib/python3/dist-packages/urllib3/connection.py", line 210, in _new_conn
    raise NameResolutionError(self.host, self, e) from e
urllib3.exceptions.NameResolutionError: <urllib3.connection.HTTPSConnection object at 0x7a80e34fde80>: Failed to resolve 'rsgrijks.zportal.nl' ([Errno -3] Temporary failure in name resolution)

The above exception was the direct cause of the following exception:

Traceback (most recent call last):
  File "/usr/lib/python3/dist-packages/requests/adapters.py", line 486, in send
    resp = conn.urlopen(
           ^^^^^^^^^^^^^
  File "/usr/lib/python3/dist-packages/urllib3/connectionpool.py", line 845, in urlopen
    retries = retries.increment(
              ^^^^^^^^^^^^^^^^^^
  File "/usr/lib/python3/dist-packages/urllib3/util/retry.py", line 517, in increment
    raise MaxRetryError(_pool, url, reason) from reason  # type: ignore[arg-type]
    ^^^^^^^^^^^^^^^^^^^^^^^^^^^^^^^^^^^^^^^^^^^^^^^^^^^
urllib3.exceptions.MaxRetryError: HTTPSConnectionPool(host='rsgrijks.zportal.nl', port=443): Max retries exceeded with url: /api/v3/ical?access_token=mc24jkscuoqntcvkuqom8nt8uh&startWeekOffset=0&endWeekOffset=1&valid=true&user=~me (Caused by NameResolutionError("<urllib3.connection.HTTPSConnection object at 0x7a80e34fde80>: Failed to resolve 'rsgrijks.zportal.nl' ([Errno -3] Temporary failure in name resolution)"))

During handling of the above exception, another exception occurred:

Traceback (most recent call last):
  File "/home/laurens/Somtoday_Agendas/Loukas/main.py", line 36, in <module>
    r = requests.get(url, allow_redirects=True)
        ^^^^^^^^^^^^^^^^^^^^^^^^^^^^^^^^^^^^^^^
  File "/usr/lib/python3/dist-packages/requests/api.py", line 73, in get
    return request("get", url, params=params, **kwargs)
           ^^^^^^^^^^^^^^^^^^^^^^^^^^^^^^^^^^^^^^^^^^^^
  File "/usr/lib/python3/dist-packages/requests/api.py", line 59, in request
    return session.request(method=method, url=url, **kwargs)
           ^^^^^^^^^^^^^^^^^^^^^^^^^^^^^^^^^^^^^^^^^^^^^^^^^
  File "/usr/lib/python3/dist-packages/requests/sessions.py", line 589, in request
    resp = self.send(prep, **send_kwargs)
           ^^^^^^^^^^^^^^^^^^^^^^^^^^^^^^
  File "/usr/lib/python3/dist-packages/requests/sessions.py", line 703, in send
    r = adapter.send(request, **kwargs)
        ^^^^^^^^^^^^^^^^^^^^^^^^^^^^^^^
  File "/usr/lib/python3/dist-packages/requests/adapters.py", line 519, in send
    raise ConnectionError(e, request=request)
requests.exceptions.ConnectionError: HTTPSConnectionPool(host='rsgrijks.zportal.nl', port=443): Max retries exceeded with url: /api/v3/ical?access_token=mc24jkscuoqntcvkuqom8nt8uh&startWeekOffset=0&endWeekOffset=1&valid=true&user=~me (Caused by NameResolutionError("<urllib3.connection.HTTPSConnection object at 0x7a80e34fde80>: Failed to resolve 'rsgrijks.zportal.nl' ([Errno -3] Temporary failure in name resolution)"))
Done


11:01 26-10-2025

# Get in right directory

# Get up to date
fatal: unable to access 'https://github.com/LaurensGamet/Somtoday_Agendas.git/': Could not resolve host: github.com

# Run main file
The file does not exist
Traceback (most recent call last):
  File "/usr/lib/python3/dist-packages/urllib3/connection.py", line 203, in _new_conn
    sock = connection.create_connection(
           ^^^^^^^^^^^^^^^^^^^^^^^^^^^^^
  File "/usr/lib/python3/dist-packages/urllib3/util/connection.py", line 60, in create_connection
    for res in socket.getaddrinfo(host, port, family, socket.SOCK_STREAM):
               ^^^^^^^^^^^^^^^^^^^^^^^^^^^^^^^^^^^^^^^^^^^^^^^^^^^^^^^^^^
  File "/usr/lib/python3.12/socket.py", line 963, in getaddrinfo
    for res in _socket.getaddrinfo(host, port, family, type, proto, flags):
               ^^^^^^^^^^^^^^^^^^^^^^^^^^^^^^^^^^^^^^^^^^^^^^^^^^^^^^^^^^^
socket.gaierror: [Errno -3] Temporary failure in name resolution

The above exception was the direct cause of the following exception:

Traceback (most recent call last):
  File "/usr/lib/python3/dist-packages/urllib3/connectionpool.py", line 791, in urlopen
    response = self._make_request(
               ^^^^^^^^^^^^^^^^^^^
  File "/usr/lib/python3/dist-packages/urllib3/connectionpool.py", line 492, in _make_request
    raise new_e
  File "/usr/lib/python3/dist-packages/urllib3/connectionpool.py", line 468, in _make_request
    self._validate_conn(conn)
  File "/usr/lib/python3/dist-packages/urllib3/connectionpool.py", line 1097, in _validate_conn
    conn.connect()
  File "/usr/lib/python3/dist-packages/urllib3/connection.py", line 611, in connect
    self.sock = sock = self._new_conn()
                       ^^^^^^^^^^^^^^^^
  File "/usr/lib/python3/dist-packages/urllib3/connection.py", line 210, in _new_conn
    raise NameResolutionError(self.host, self, e) from e
urllib3.exceptions.NameResolutionError: <urllib3.connection.HTTPSConnection object at 0x704d618fde80>: Failed to resolve 'rsgrijks.zportal.nl' ([Errno -3] Temporary failure in name resolution)

The above exception was the direct cause of the following exception:

Traceback (most recent call last):
  File "/usr/lib/python3/dist-packages/requests/adapters.py", line 486, in send
    resp = conn.urlopen(
           ^^^^^^^^^^^^^
  File "/usr/lib/python3/dist-packages/urllib3/connectionpool.py", line 845, in urlopen
    retries = retries.increment(
              ^^^^^^^^^^^^^^^^^^
  File "/usr/lib/python3/dist-packages/urllib3/util/retry.py", line 517, in increment
    raise MaxRetryError(_pool, url, reason) from reason  # type: ignore[arg-type]
    ^^^^^^^^^^^^^^^^^^^^^^^^^^^^^^^^^^^^^^^^^^^^^^^^^^^
urllib3.exceptions.MaxRetryError: HTTPSConnectionPool(host='rsgrijks.zportal.nl', port=443): Max retries exceeded with url: /api/v3/ical?access_token=mc24jkscuoqntcvkuqom8nt8uh&startWeekOffset=0&endWeekOffset=1&valid=true&user=~me (Caused by NameResolutionError("<urllib3.connection.HTTPSConnection object at 0x704d618fde80>: Failed to resolve 'rsgrijks.zportal.nl' ([Errno -3] Temporary failure in name resolution)"))

During handling of the above exception, another exception occurred:

Traceback (most recent call last):
  File "/home/laurens/Somtoday_Agendas/Loukas/main.py", line 36, in <module>
    r = requests.get(url, allow_redirects=True)
        ^^^^^^^^^^^^^^^^^^^^^^^^^^^^^^^^^^^^^^^
  File "/usr/lib/python3/dist-packages/requests/api.py", line 73, in get
    return request("get", url, params=params, **kwargs)
           ^^^^^^^^^^^^^^^^^^^^^^^^^^^^^^^^^^^^^^^^^^^^
  File "/usr/lib/python3/dist-packages/requests/api.py", line 59, in request
    return session.request(method=method, url=url, **kwargs)
           ^^^^^^^^^^^^^^^^^^^^^^^^^^^^^^^^^^^^^^^^^^^^^^^^^
  File "/usr/lib/python3/dist-packages/requests/sessions.py", line 589, in request
    resp = self.send(prep, **send_kwargs)
           ^^^^^^^^^^^^^^^^^^^^^^^^^^^^^^
  File "/usr/lib/python3/dist-packages/requests/sessions.py", line 703, in send
    r = adapter.send(request, **kwargs)
        ^^^^^^^^^^^^^^^^^^^^^^^^^^^^^^^
  File "/usr/lib/python3/dist-packages/requests/adapters.py", line 519, in send
    raise ConnectionError(e, request=request)
requests.exceptions.ConnectionError: HTTPSConnectionPool(host='rsgrijks.zportal.nl', port=443): Max retries exceeded with url: /api/v3/ical?access_token=mc24jkscuoqntcvkuqom8nt8uh&startWeekOffset=0&endWeekOffset=1&valid=true&user=~me (Caused by NameResolutionError("<urllib3.connection.HTTPSConnection object at 0x704d618fde80>: Failed to resolve 'rsgrijks.zportal.nl' ([Errno -3] Temporary failure in name resolution)"))
Done


11:31 26-10-2025

# Get in right directory

# Get up to date
fatal: unable to access 'https://github.com/LaurensGamet/Somtoday_Agendas.git/': Could not resolve host: github.com

# Run main file
The file does not exist
Traceback (most recent call last):
  File "/usr/lib/python3/dist-packages/urllib3/connection.py", line 203, in _new_conn
    sock = connection.create_connection(
           ^^^^^^^^^^^^^^^^^^^^^^^^^^^^^
  File "/usr/lib/python3/dist-packages/urllib3/util/connection.py", line 60, in create_connection
    for res in socket.getaddrinfo(host, port, family, socket.SOCK_STREAM):
               ^^^^^^^^^^^^^^^^^^^^^^^^^^^^^^^^^^^^^^^^^^^^^^^^^^^^^^^^^^
  File "/usr/lib/python3.12/socket.py", line 963, in getaddrinfo
    for res in _socket.getaddrinfo(host, port, family, type, proto, flags):
               ^^^^^^^^^^^^^^^^^^^^^^^^^^^^^^^^^^^^^^^^^^^^^^^^^^^^^^^^^^^
socket.gaierror: [Errno -3] Temporary failure in name resolution

The above exception was the direct cause of the following exception:

Traceback (most recent call last):
  File "/usr/lib/python3/dist-packages/urllib3/connectionpool.py", line 791, in urlopen
    response = self._make_request(
               ^^^^^^^^^^^^^^^^^^^
  File "/usr/lib/python3/dist-packages/urllib3/connectionpool.py", line 492, in _make_request
    raise new_e
  File "/usr/lib/python3/dist-packages/urllib3/connectionpool.py", line 468, in _make_request
    self._validate_conn(conn)
  File "/usr/lib/python3/dist-packages/urllib3/connectionpool.py", line 1097, in _validate_conn
    conn.connect()
  File "/usr/lib/python3/dist-packages/urllib3/connection.py", line 611, in connect
    self.sock = sock = self._new_conn()
                       ^^^^^^^^^^^^^^^^
  File "/usr/lib/python3/dist-packages/urllib3/connection.py", line 210, in _new_conn
    raise NameResolutionError(self.host, self, e) from e
urllib3.exceptions.NameResolutionError: <urllib3.connection.HTTPSConnection object at 0x70f82a01c8c0>: Failed to resolve 'rsgrijks.zportal.nl' ([Errno -3] Temporary failure in name resolution)

The above exception was the direct cause of the following exception:

Traceback (most recent call last):
  File "/usr/lib/python3/dist-packages/requests/adapters.py", line 486, in send
    resp = conn.urlopen(
           ^^^^^^^^^^^^^
  File "/usr/lib/python3/dist-packages/urllib3/connectionpool.py", line 845, in urlopen
    retries = retries.increment(
              ^^^^^^^^^^^^^^^^^^
  File "/usr/lib/python3/dist-packages/urllib3/util/retry.py", line 517, in increment
    raise MaxRetryError(_pool, url, reason) from reason  # type: ignore[arg-type]
    ^^^^^^^^^^^^^^^^^^^^^^^^^^^^^^^^^^^^^^^^^^^^^^^^^^^
urllib3.exceptions.MaxRetryError: HTTPSConnectionPool(host='rsgrijks.zportal.nl', port=443): Max retries exceeded with url: /api/v3/ical?access_token=mc24jkscuoqntcvkuqom8nt8uh&startWeekOffset=0&endWeekOffset=1&valid=true&user=~me (Caused by NameResolutionError("<urllib3.connection.HTTPSConnection object at 0x70f82a01c8c0>: Failed to resolve 'rsgrijks.zportal.nl' ([Errno -3] Temporary failure in name resolution)"))

During handling of the above exception, another exception occurred:

Traceback (most recent call last):
  File "/home/laurens/Somtoday_Agendas/Loukas/main.py", line 36, in <module>
    r = requests.get(url, allow_redirects=True)
        ^^^^^^^^^^^^^^^^^^^^^^^^^^^^^^^^^^^^^^^
  File "/usr/lib/python3/dist-packages/requests/api.py", line 73, in get
    return request("get", url, params=params, **kwargs)
           ^^^^^^^^^^^^^^^^^^^^^^^^^^^^^^^^^^^^^^^^^^^^
  File "/usr/lib/python3/dist-packages/requests/api.py", line 59, in request
    return session.request(method=method, url=url, **kwargs)
           ^^^^^^^^^^^^^^^^^^^^^^^^^^^^^^^^^^^^^^^^^^^^^^^^^
  File "/usr/lib/python3/dist-packages/requests/sessions.py", line 589, in request
    resp = self.send(prep, **send_kwargs)
           ^^^^^^^^^^^^^^^^^^^^^^^^^^^^^^
  File "/usr/lib/python3/dist-packages/requests/sessions.py", line 703, in send
    r = adapter.send(request, **kwargs)
        ^^^^^^^^^^^^^^^^^^^^^^^^^^^^^^^
  File "/usr/lib/python3/dist-packages/requests/adapters.py", line 519, in send
    raise ConnectionError(e, request=request)
requests.exceptions.ConnectionError: HTTPSConnectionPool(host='rsgrijks.zportal.nl', port=443): Max retries exceeded with url: /api/v3/ical?access_token=mc24jkscuoqntcvkuqom8nt8uh&startWeekOffset=0&endWeekOffset=1&valid=true&user=~me (Caused by NameResolutionError("<urllib3.connection.HTTPSConnection object at 0x70f82a01c8c0>: Failed to resolve 'rsgrijks.zportal.nl' ([Errno -3] Temporary failure in name resolution)"))
Done


12:01 26-10-2025

# Get in right directory

# Get up to date
fatal: unable to access 'https://github.com/LaurensGamet/Somtoday_Agendas.git/': Could not resolve host: github.com

# Run main file
The file does not exist
Traceback (most recent call last):
  File "/usr/lib/python3/dist-packages/urllib3/connection.py", line 203, in _new_conn
    sock = connection.create_connection(
           ^^^^^^^^^^^^^^^^^^^^^^^^^^^^^
  File "/usr/lib/python3/dist-packages/urllib3/util/connection.py", line 60, in create_connection
    for res in socket.getaddrinfo(host, port, family, socket.SOCK_STREAM):
               ^^^^^^^^^^^^^^^^^^^^^^^^^^^^^^^^^^^^^^^^^^^^^^^^^^^^^^^^^^
  File "/usr/lib/python3.12/socket.py", line 963, in getaddrinfo
    for res in _socket.getaddrinfo(host, port, family, type, proto, flags):
               ^^^^^^^^^^^^^^^^^^^^^^^^^^^^^^^^^^^^^^^^^^^^^^^^^^^^^^^^^^^
socket.gaierror: [Errno -3] Temporary failure in name resolution

The above exception was the direct cause of the following exception:

Traceback (most recent call last):
  File "/usr/lib/python3/dist-packages/urllib3/connectionpool.py", line 791, in urlopen
    response = self._make_request(
               ^^^^^^^^^^^^^^^^^^^
  File "/usr/lib/python3/dist-packages/urllib3/connectionpool.py", line 492, in _make_request
    raise new_e
  File "/usr/lib/python3/dist-packages/urllib3/connectionpool.py", line 468, in _make_request
    self._validate_conn(conn)
  File "/usr/lib/python3/dist-packages/urllib3/connectionpool.py", line 1097, in _validate_conn
    conn.connect()
  File "/usr/lib/python3/dist-packages/urllib3/connection.py", line 611, in connect
    self.sock = sock = self._new_conn()
                       ^^^^^^^^^^^^^^^^
  File "/usr/lib/python3/dist-packages/urllib3/connection.py", line 210, in _new_conn
    raise NameResolutionError(self.host, self, e) from e
urllib3.exceptions.NameResolutionError: <urllib3.connection.HTTPSConnection object at 0x784e9edb0a10>: Failed to resolve 'rsgrijks.zportal.nl' ([Errno -3] Temporary failure in name resolution)

The above exception was the direct cause of the following exception:

Traceback (most recent call last):
  File "/usr/lib/python3/dist-packages/requests/adapters.py", line 486, in send
    resp = conn.urlopen(
           ^^^^^^^^^^^^^
  File "/usr/lib/python3/dist-packages/urllib3/connectionpool.py", line 845, in urlopen
    retries = retries.increment(
              ^^^^^^^^^^^^^^^^^^
  File "/usr/lib/python3/dist-packages/urllib3/util/retry.py", line 517, in increment
    raise MaxRetryError(_pool, url, reason) from reason  # type: ignore[arg-type]
    ^^^^^^^^^^^^^^^^^^^^^^^^^^^^^^^^^^^^^^^^^^^^^^^^^^^
urllib3.exceptions.MaxRetryError: HTTPSConnectionPool(host='rsgrijks.zportal.nl', port=443): Max retries exceeded with url: /api/v3/ical?access_token=mc24jkscuoqntcvkuqom8nt8uh&startWeekOffset=0&endWeekOffset=1&valid=true&user=~me (Caused by NameResolutionError("<urllib3.connection.HTTPSConnection object at 0x784e9edb0a10>: Failed to resolve 'rsgrijks.zportal.nl' ([Errno -3] Temporary failure in name resolution)"))

During handling of the above exception, another exception occurred:

Traceback (most recent call last):
  File "/home/laurens/Somtoday_Agendas/Loukas/main.py", line 36, in <module>
    r = requests.get(url, allow_redirects=True)
        ^^^^^^^^^^^^^^^^^^^^^^^^^^^^^^^^^^^^^^^
  File "/usr/lib/python3/dist-packages/requests/api.py", line 73, in get
    return request("get", url, params=params, **kwargs)
           ^^^^^^^^^^^^^^^^^^^^^^^^^^^^^^^^^^^^^^^^^^^^
  File "/usr/lib/python3/dist-packages/requests/api.py", line 59, in request
    return session.request(method=method, url=url, **kwargs)
           ^^^^^^^^^^^^^^^^^^^^^^^^^^^^^^^^^^^^^^^^^^^^^^^^^
  File "/usr/lib/python3/dist-packages/requests/sessions.py", line 589, in request
    resp = self.send(prep, **send_kwargs)
           ^^^^^^^^^^^^^^^^^^^^^^^^^^^^^^
  File "/usr/lib/python3/dist-packages/requests/sessions.py", line 703, in send
    r = adapter.send(request, **kwargs)
        ^^^^^^^^^^^^^^^^^^^^^^^^^^^^^^^
  File "/usr/lib/python3/dist-packages/requests/adapters.py", line 519, in send
    raise ConnectionError(e, request=request)
requests.exceptions.ConnectionError: HTTPSConnectionPool(host='rsgrijks.zportal.nl', port=443): Max retries exceeded with url: /api/v3/ical?access_token=mc24jkscuoqntcvkuqom8nt8uh&startWeekOffset=0&endWeekOffset=1&valid=true&user=~me (Caused by NameResolutionError("<urllib3.connection.HTTPSConnection object at 0x784e9edb0a10>: Failed to resolve 'rsgrijks.zportal.nl' ([Errno -3] Temporary failure in name resolution)"))
Done


12:31 26-10-2025

# Get in right directory

# Get up to date
fatal: unable to access 'https://github.com/LaurensGamet/Somtoday_Agendas.git/': Could not resolve host: github.com

# Run main file
The file does not exist
Traceback (most recent call last):
  File "/usr/lib/python3/dist-packages/urllib3/connection.py", line 203, in _new_conn
    sock = connection.create_connection(
           ^^^^^^^^^^^^^^^^^^^^^^^^^^^^^
  File "/usr/lib/python3/dist-packages/urllib3/util/connection.py", line 60, in create_connection
    for res in socket.getaddrinfo(host, port, family, socket.SOCK_STREAM):
               ^^^^^^^^^^^^^^^^^^^^^^^^^^^^^^^^^^^^^^^^^^^^^^^^^^^^^^^^^^
  File "/usr/lib/python3.12/socket.py", line 963, in getaddrinfo
    for res in _socket.getaddrinfo(host, port, family, type, proto, flags):
               ^^^^^^^^^^^^^^^^^^^^^^^^^^^^^^^^^^^^^^^^^^^^^^^^^^^^^^^^^^^
socket.gaierror: [Errno -3] Temporary failure in name resolution

The above exception was the direct cause of the following exception:

Traceback (most recent call last):
  File "/usr/lib/python3/dist-packages/urllib3/connectionpool.py", line 791, in urlopen
    response = self._make_request(
               ^^^^^^^^^^^^^^^^^^^
  File "/usr/lib/python3/dist-packages/urllib3/connectionpool.py", line 492, in _make_request
    raise new_e
  File "/usr/lib/python3/dist-packages/urllib3/connectionpool.py", line 468, in _make_request
    self._validate_conn(conn)
  File "/usr/lib/python3/dist-packages/urllib3/connectionpool.py", line 1097, in _validate_conn
    conn.connect()
  File "/usr/lib/python3/dist-packages/urllib3/connection.py", line 611, in connect
    self.sock = sock = self._new_conn()
                       ^^^^^^^^^^^^^^^^
  File "/usr/lib/python3/dist-packages/urllib3/connection.py", line 210, in _new_conn
    raise NameResolutionError(self.host, self, e) from e
urllib3.exceptions.NameResolutionError: <urllib3.connection.HTTPSConnection object at 0x7759c8952b40>: Failed to resolve 'rsgrijks.zportal.nl' ([Errno -3] Temporary failure in name resolution)

The above exception was the direct cause of the following exception:

Traceback (most recent call last):
  File "/usr/lib/python3/dist-packages/requests/adapters.py", line 486, in send
    resp = conn.urlopen(
           ^^^^^^^^^^^^^
  File "/usr/lib/python3/dist-packages/urllib3/connectionpool.py", line 845, in urlopen
    retries = retries.increment(
              ^^^^^^^^^^^^^^^^^^
  File "/usr/lib/python3/dist-packages/urllib3/util/retry.py", line 517, in increment
    raise MaxRetryError(_pool, url, reason) from reason  # type: ignore[arg-type]
    ^^^^^^^^^^^^^^^^^^^^^^^^^^^^^^^^^^^^^^^^^^^^^^^^^^^
urllib3.exceptions.MaxRetryError: HTTPSConnectionPool(host='rsgrijks.zportal.nl', port=443): Max retries exceeded with url: /api/v3/ical?access_token=mc24jkscuoqntcvkuqom8nt8uh&startWeekOffset=0&endWeekOffset=1&valid=true&user=~me (Caused by NameResolutionError("<urllib3.connection.HTTPSConnection object at 0x7759c8952b40>: Failed to resolve 'rsgrijks.zportal.nl' ([Errno -3] Temporary failure in name resolution)"))

During handling of the above exception, another exception occurred:

Traceback (most recent call last):
  File "/home/laurens/Somtoday_Agendas/Loukas/main.py", line 36, in <module>
    r = requests.get(url, allow_redirects=True)
        ^^^^^^^^^^^^^^^^^^^^^^^^^^^^^^^^^^^^^^^
  File "/usr/lib/python3/dist-packages/requests/api.py", line 73, in get
    return request("get", url, params=params, **kwargs)
           ^^^^^^^^^^^^^^^^^^^^^^^^^^^^^^^^^^^^^^^^^^^^
  File "/usr/lib/python3/dist-packages/requests/api.py", line 59, in request
    return session.request(method=method, url=url, **kwargs)
           ^^^^^^^^^^^^^^^^^^^^^^^^^^^^^^^^^^^^^^^^^^^^^^^^^
  File "/usr/lib/python3/dist-packages/requests/sessions.py", line 589, in request
    resp = self.send(prep, **send_kwargs)
           ^^^^^^^^^^^^^^^^^^^^^^^^^^^^^^
  File "/usr/lib/python3/dist-packages/requests/sessions.py", line 703, in send
    r = adapter.send(request, **kwargs)
        ^^^^^^^^^^^^^^^^^^^^^^^^^^^^^^^
  File "/usr/lib/python3/dist-packages/requests/adapters.py", line 519, in send
    raise ConnectionError(e, request=request)
requests.exceptions.ConnectionError: HTTPSConnectionPool(host='rsgrijks.zportal.nl', port=443): Max retries exceeded with url: /api/v3/ical?access_token=mc24jkscuoqntcvkuqom8nt8uh&startWeekOffset=0&endWeekOffset=1&valid=true&user=~me (Caused by NameResolutionError("<urllib3.connection.HTTPSConnection object at 0x7759c8952b40>: Failed to resolve 'rsgrijks.zportal.nl' ([Errno -3] Temporary failure in name resolution)"))
Done


13:01 26-10-2025

# Get in right directory

# Get up to date
fatal: unable to access 'https://github.com/LaurensGamet/Somtoday_Agendas.git/': Could not resolve host: github.com

# Run main file
The file does not exist
Traceback (most recent call last):
  File "/usr/lib/python3/dist-packages/urllib3/connection.py", line 203, in _new_conn
    sock = connection.create_connection(
           ^^^^^^^^^^^^^^^^^^^^^^^^^^^^^
  File "/usr/lib/python3/dist-packages/urllib3/util/connection.py", line 60, in create_connection
    for res in socket.getaddrinfo(host, port, family, socket.SOCK_STREAM):
               ^^^^^^^^^^^^^^^^^^^^^^^^^^^^^^^^^^^^^^^^^^^^^^^^^^^^^^^^^^
  File "/usr/lib/python3.12/socket.py", line 963, in getaddrinfo
    for res in _socket.getaddrinfo(host, port, family, type, proto, flags):
               ^^^^^^^^^^^^^^^^^^^^^^^^^^^^^^^^^^^^^^^^^^^^^^^^^^^^^^^^^^^
socket.gaierror: [Errno -3] Temporary failure in name resolution

The above exception was the direct cause of the following exception:

Traceback (most recent call last):
  File "/usr/lib/python3/dist-packages/urllib3/connectionpool.py", line 791, in urlopen
    response = self._make_request(
               ^^^^^^^^^^^^^^^^^^^
  File "/usr/lib/python3/dist-packages/urllib3/connectionpool.py", line 492, in _make_request
    raise new_e
  File "/usr/lib/python3/dist-packages/urllib3/connectionpool.py", line 468, in _make_request
    self._validate_conn(conn)
  File "/usr/lib/python3/dist-packages/urllib3/connectionpool.py", line 1097, in _validate_conn
    conn.connect()
  File "/usr/lib/python3/dist-packages/urllib3/connection.py", line 611, in connect
    self.sock = sock = self._new_conn()
                       ^^^^^^^^^^^^^^^^
  File "/usr/lib/python3/dist-packages/urllib3/connection.py", line 210, in _new_conn
    raise NameResolutionError(self.host, self, e) from e
urllib3.exceptions.NameResolutionError: <urllib3.connection.HTTPSConnection object at 0x74c1363ce0f0>: Failed to resolve 'rsgrijks.zportal.nl' ([Errno -3] Temporary failure in name resolution)

The above exception was the direct cause of the following exception:

Traceback (most recent call last):
  File "/usr/lib/python3/dist-packages/requests/adapters.py", line 486, in send
    resp = conn.urlopen(
           ^^^^^^^^^^^^^
  File "/usr/lib/python3/dist-packages/urllib3/connectionpool.py", line 845, in urlopen
    retries = retries.increment(
              ^^^^^^^^^^^^^^^^^^
  File "/usr/lib/python3/dist-packages/urllib3/util/retry.py", line 517, in increment
    raise MaxRetryError(_pool, url, reason) from reason  # type: ignore[arg-type]
    ^^^^^^^^^^^^^^^^^^^^^^^^^^^^^^^^^^^^^^^^^^^^^^^^^^^
urllib3.exceptions.MaxRetryError: HTTPSConnectionPool(host='rsgrijks.zportal.nl', port=443): Max retries exceeded with url: /api/v3/ical?access_token=mc24jkscuoqntcvkuqom8nt8uh&startWeekOffset=0&endWeekOffset=1&valid=true&user=~me (Caused by NameResolutionError("<urllib3.connection.HTTPSConnection object at 0x74c1363ce0f0>: Failed to resolve 'rsgrijks.zportal.nl' ([Errno -3] Temporary failure in name resolution)"))

During handling of the above exception, another exception occurred:

Traceback (most recent call last):
  File "/home/laurens/Somtoday_Agendas/Loukas/main.py", line 36, in <module>
    r = requests.get(url, allow_redirects=True)
        ^^^^^^^^^^^^^^^^^^^^^^^^^^^^^^^^^^^^^^^
  File "/usr/lib/python3/dist-packages/requests/api.py", line 73, in get
    return request("get", url, params=params, **kwargs)
           ^^^^^^^^^^^^^^^^^^^^^^^^^^^^^^^^^^^^^^^^^^^^
  File "/usr/lib/python3/dist-packages/requests/api.py", line 59, in request
    return session.request(method=method, url=url, **kwargs)
           ^^^^^^^^^^^^^^^^^^^^^^^^^^^^^^^^^^^^^^^^^^^^^^^^^
  File "/usr/lib/python3/dist-packages/requests/sessions.py", line 589, in request
    resp = self.send(prep, **send_kwargs)
           ^^^^^^^^^^^^^^^^^^^^^^^^^^^^^^
  File "/usr/lib/python3/dist-packages/requests/sessions.py", line 703, in send
    r = adapter.send(request, **kwargs)
        ^^^^^^^^^^^^^^^^^^^^^^^^^^^^^^^
  File "/usr/lib/python3/dist-packages/requests/adapters.py", line 519, in send
    raise ConnectionError(e, request=request)
requests.exceptions.ConnectionError: HTTPSConnectionPool(host='rsgrijks.zportal.nl', port=443): Max retries exceeded with url: /api/v3/ical?access_token=mc24jkscuoqntcvkuqom8nt8uh&startWeekOffset=0&endWeekOffset=1&valid=true&user=~me (Caused by NameResolutionError("<urllib3.connection.HTTPSConnection object at 0x74c1363ce0f0>: Failed to resolve 'rsgrijks.zportal.nl' ([Errno -3] Temporary failure in name resolution)"))
Done


13:31 26-10-2025

# Get in right directory

# Get up to date
fatal: unable to access 'https://github.com/LaurensGamet/Somtoday_Agendas.git/': Could not resolve host: github.com

# Run main file
The file does not exist
Traceback (most recent call last):
  File "/usr/lib/python3/dist-packages/urllib3/connection.py", line 203, in _new_conn
    sock = connection.create_connection(
           ^^^^^^^^^^^^^^^^^^^^^^^^^^^^^
  File "/usr/lib/python3/dist-packages/urllib3/util/connection.py", line 60, in create_connection
    for res in socket.getaddrinfo(host, port, family, socket.SOCK_STREAM):
               ^^^^^^^^^^^^^^^^^^^^^^^^^^^^^^^^^^^^^^^^^^^^^^^^^^^^^^^^^^
  File "/usr/lib/python3.12/socket.py", line 963, in getaddrinfo
    for res in _socket.getaddrinfo(host, port, family, type, proto, flags):
               ^^^^^^^^^^^^^^^^^^^^^^^^^^^^^^^^^^^^^^^^^^^^^^^^^^^^^^^^^^^
socket.gaierror: [Errno -3] Temporary failure in name resolution

The above exception was the direct cause of the following exception:

Traceback (most recent call last):
  File "/usr/lib/python3/dist-packages/urllib3/connectionpool.py", line 791, in urlopen
    response = self._make_request(
               ^^^^^^^^^^^^^^^^^^^
  File "/usr/lib/python3/dist-packages/urllib3/connectionpool.py", line 492, in _make_request
    raise new_e
  File "/usr/lib/python3/dist-packages/urllib3/connectionpool.py", line 468, in _make_request
    self._validate_conn(conn)
  File "/usr/lib/python3/dist-packages/urllib3/connectionpool.py", line 1097, in _validate_conn
    conn.connect()
  File "/usr/lib/python3/dist-packages/urllib3/connection.py", line 611, in connect
    self.sock = sock = self._new_conn()
                       ^^^^^^^^^^^^^^^^
  File "/usr/lib/python3/dist-packages/urllib3/connection.py", line 210, in _new_conn
    raise NameResolutionError(self.host, self, e) from e
urllib3.exceptions.NameResolutionError: <urllib3.connection.HTTPSConnection object at 0x7456c96b40b0>: Failed to resolve 'rsgrijks.zportal.nl' ([Errno -3] Temporary failure in name resolution)

The above exception was the direct cause of the following exception:

Traceback (most recent call last):
  File "/usr/lib/python3/dist-packages/requests/adapters.py", line 486, in send
    resp = conn.urlopen(
           ^^^^^^^^^^^^^
  File "/usr/lib/python3/dist-packages/urllib3/connectionpool.py", line 845, in urlopen
    retries = retries.increment(
              ^^^^^^^^^^^^^^^^^^
  File "/usr/lib/python3/dist-packages/urllib3/util/retry.py", line 517, in increment
    raise MaxRetryError(_pool, url, reason) from reason  # type: ignore[arg-type]
    ^^^^^^^^^^^^^^^^^^^^^^^^^^^^^^^^^^^^^^^^^^^^^^^^^^^
urllib3.exceptions.MaxRetryError: HTTPSConnectionPool(host='rsgrijks.zportal.nl', port=443): Max retries exceeded with url: /api/v3/ical?access_token=mc24jkscuoqntcvkuqom8nt8uh&startWeekOffset=0&endWeekOffset=1&valid=true&user=~me (Caused by NameResolutionError("<urllib3.connection.HTTPSConnection object at 0x7456c96b40b0>: Failed to resolve 'rsgrijks.zportal.nl' ([Errno -3] Temporary failure in name resolution)"))

During handling of the above exception, another exception occurred:

Traceback (most recent call last):
  File "/home/laurens/Somtoday_Agendas/Loukas/main.py", line 36, in <module>
    r = requests.get(url, allow_redirects=True)
        ^^^^^^^^^^^^^^^^^^^^^^^^^^^^^^^^^^^^^^^
  File "/usr/lib/python3/dist-packages/requests/api.py", line 73, in get
    return request("get", url, params=params, **kwargs)
           ^^^^^^^^^^^^^^^^^^^^^^^^^^^^^^^^^^^^^^^^^^^^
  File "/usr/lib/python3/dist-packages/requests/api.py", line 59, in request
    return session.request(method=method, url=url, **kwargs)
           ^^^^^^^^^^^^^^^^^^^^^^^^^^^^^^^^^^^^^^^^^^^^^^^^^
  File "/usr/lib/python3/dist-packages/requests/sessions.py", line 589, in request
    resp = self.send(prep, **send_kwargs)
           ^^^^^^^^^^^^^^^^^^^^^^^^^^^^^^
  File "/usr/lib/python3/dist-packages/requests/sessions.py", line 703, in send
    r = adapter.send(request, **kwargs)
        ^^^^^^^^^^^^^^^^^^^^^^^^^^^^^^^
  File "/usr/lib/python3/dist-packages/requests/adapters.py", line 519, in send
    raise ConnectionError(e, request=request)
requests.exceptions.ConnectionError: HTTPSConnectionPool(host='rsgrijks.zportal.nl', port=443): Max retries exceeded with url: /api/v3/ical?access_token=mc24jkscuoqntcvkuqom8nt8uh&startWeekOffset=0&endWeekOffset=1&valid=true&user=~me (Caused by NameResolutionError("<urllib3.connection.HTTPSConnection object at 0x7456c96b40b0>: Failed to resolve 'rsgrijks.zportal.nl' ([Errno -3] Temporary failure in name resolution)"))
Done


14:01 26-10-2025

# Get in right directory

# Get up to date
fatal: unable to access 'https://github.com/LaurensGamet/Somtoday_Agendas.git/': Could not resolve host: github.com

# Run main file
The file does not exist
Traceback (most recent call last):
  File "/usr/lib/python3/dist-packages/urllib3/connection.py", line 203, in _new_conn
    sock = connection.create_connection(
           ^^^^^^^^^^^^^^^^^^^^^^^^^^^^^
  File "/usr/lib/python3/dist-packages/urllib3/util/connection.py", line 60, in create_connection
    for res in socket.getaddrinfo(host, port, family, socket.SOCK_STREAM):
               ^^^^^^^^^^^^^^^^^^^^^^^^^^^^^^^^^^^^^^^^^^^^^^^^^^^^^^^^^^
  File "/usr/lib/python3.12/socket.py", line 963, in getaddrinfo
    for res in _socket.getaddrinfo(host, port, family, type, proto, flags):
               ^^^^^^^^^^^^^^^^^^^^^^^^^^^^^^^^^^^^^^^^^^^^^^^^^^^^^^^^^^^
socket.gaierror: [Errno -3] Temporary failure in name resolution

The above exception was the direct cause of the following exception:

Traceback (most recent call last):
  File "/usr/lib/python3/dist-packages/urllib3/connectionpool.py", line 791, in urlopen
    response = self._make_request(
               ^^^^^^^^^^^^^^^^^^^
  File "/usr/lib/python3/dist-packages/urllib3/connectionpool.py", line 492, in _make_request
    raise new_e
  File "/usr/lib/python3/dist-packages/urllib3/connectionpool.py", line 468, in _make_request
    self._validate_conn(conn)
  File "/usr/lib/python3/dist-packages/urllib3/connectionpool.py", line 1097, in _validate_conn
    conn.connect()
  File "/usr/lib/python3/dist-packages/urllib3/connection.py", line 611, in connect
    self.sock = sock = self._new_conn()
                       ^^^^^^^^^^^^^^^^
  File "/usr/lib/python3/dist-packages/urllib3/connection.py", line 210, in _new_conn
    raise NameResolutionError(self.host, self, e) from e
urllib3.exceptions.NameResolutionError: <urllib3.connection.HTTPSConnection object at 0x7fbde17fe0f0>: Failed to resolve 'rsgrijks.zportal.nl' ([Errno -3] Temporary failure in name resolution)

The above exception was the direct cause of the following exception:

Traceback (most recent call last):
  File "/usr/lib/python3/dist-packages/requests/adapters.py", line 486, in send
    resp = conn.urlopen(
           ^^^^^^^^^^^^^
  File "/usr/lib/python3/dist-packages/urllib3/connectionpool.py", line 845, in urlopen
    retries = retries.increment(
              ^^^^^^^^^^^^^^^^^^
  File "/usr/lib/python3/dist-packages/urllib3/util/retry.py", line 517, in increment
    raise MaxRetryError(_pool, url, reason) from reason  # type: ignore[arg-type]
    ^^^^^^^^^^^^^^^^^^^^^^^^^^^^^^^^^^^^^^^^^^^^^^^^^^^
urllib3.exceptions.MaxRetryError: HTTPSConnectionPool(host='rsgrijks.zportal.nl', port=443): Max retries exceeded with url: /api/v3/ical?access_token=mc24jkscuoqntcvkuqom8nt8uh&startWeekOffset=0&endWeekOffset=1&valid=true&user=~me (Caused by NameResolutionError("<urllib3.connection.HTTPSConnection object at 0x7fbde17fe0f0>: Failed to resolve 'rsgrijks.zportal.nl' ([Errno -3] Temporary failure in name resolution)"))

During handling of the above exception, another exception occurred:

Traceback (most recent call last):
  File "/home/laurens/Somtoday_Agendas/Loukas/main.py", line 36, in <module>
    r = requests.get(url, allow_redirects=True)
        ^^^^^^^^^^^^^^^^^^^^^^^^^^^^^^^^^^^^^^^
  File "/usr/lib/python3/dist-packages/requests/api.py", line 73, in get
    return request("get", url, params=params, **kwargs)
           ^^^^^^^^^^^^^^^^^^^^^^^^^^^^^^^^^^^^^^^^^^^^
  File "/usr/lib/python3/dist-packages/requests/api.py", line 59, in request
    return session.request(method=method, url=url, **kwargs)
           ^^^^^^^^^^^^^^^^^^^^^^^^^^^^^^^^^^^^^^^^^^^^^^^^^
  File "/usr/lib/python3/dist-packages/requests/sessions.py", line 589, in request
    resp = self.send(prep, **send_kwargs)
           ^^^^^^^^^^^^^^^^^^^^^^^^^^^^^^
  File "/usr/lib/python3/dist-packages/requests/sessions.py", line 703, in send
    r = adapter.send(request, **kwargs)
        ^^^^^^^^^^^^^^^^^^^^^^^^^^^^^^^
  File "/usr/lib/python3/dist-packages/requests/adapters.py", line 519, in send
    raise ConnectionError(e, request=request)
requests.exceptions.ConnectionError: HTTPSConnectionPool(host='rsgrijks.zportal.nl', port=443): Max retries exceeded with url: /api/v3/ical?access_token=mc24jkscuoqntcvkuqom8nt8uh&startWeekOffset=0&endWeekOffset=1&valid=true&user=~me (Caused by NameResolutionError("<urllib3.connection.HTTPSConnection object at 0x7fbde17fe0f0>: Failed to resolve 'rsgrijks.zportal.nl' ([Errno -3] Temporary failure in name resolution)"))
Done


14:30 26-10-2025

# Get in right directory

# Get up to date
Already up to date.

# Run main file
The file does not exist
Done


15:00 26-10-2025

# Get in right directory

# Get up to date
Already up to date.

# Run main file
Done


15:30 26-10-2025

# Get in right directory

# Get up to date
Already up to date.

# Run main file
Done


16:00 26-10-2025

# Get in right directory

# Get up to date
Already up to date.

# Run main file
Done


16:30 26-10-2025

# Get in right directory

# Get up to date
Already up to date.

# Run main file
Done


17:00 26-10-2025

# Get in right directory

# Get up to date
Already up to date.

# Run main file
Done


17:30 26-10-2025

# Get in right directory

# Get up to date
Already up to date.

# Run main file
Done


18:00 26-10-2025

# Get in right directory

# Get up to date
Already up to date.

# Run main file
Done


18:30 26-10-2025

# Get in right directory

# Get up to date
Already up to date.

# Run main file
Done


19:00 26-10-2025

# Get in right directory

# Get up to date
Already up to date.

# Run main file
Done


19:30 26-10-2025

# Get in right directory

# Get up to date
Already up to date.

# Run main file
Done


