09:05 24-08-2025

# Get in right directory

# Get up to date
Already up to date.

# Run main file
Done


09:05 24-08-2025

# Get in right directory

# Get up to date
Already up to date.

# Run main file
Done


09:35 24-08-2025

# Get in right directory

# Get up to date
Already up to date.

# Run main file
Done


10:05 24-08-2025

# Get in right directory

# Get up to date
Already up to date.

# Run main file
Done


10:35 24-08-2025

# Get in right directory

# Get up to date
Already up to date.

# Run main file
Done


11:05 24-08-2025

# Get in right directory

# Get up to date
Already up to date.

# Run main file
Done


11:35 24-08-2025

# Get in right directory

# Get up to date
Already up to date.

# Run main file
Done


12:05 24-08-2025

# Get in right directory

# Get up to date
Already up to date.

# Run main file
Done


12:35 24-08-2025

# Get in right directory

# Get up to date
Already up to date.

# Run main file
Done


13:05 24-08-2025

# Get in right directory

# Get up to date
Already up to date.

# Run main file
Done


13:35 24-08-2025

# Get in right directory

# Get up to date
Already up to date.

# Run main file
Done


14:06 24-08-2025

# Get in right directory

# Get up to date
Already up to date.

# Run main file
Done


14:35 24-08-2025

# Get in right directory

# Get up to date
Already up to date.

# Run main file
Done


15:05 24-08-2025

# Get in right directory

# Get up to date
Already up to date.

# Run main file
Done


15:28 24-08-2025

# Get in right directory

# Get up to date
Already up to date.

# Run main file
Done


15:35 24-08-2025

# Get in right directory

# Get up to date
Already up to date.

# Run main file
Done


16:05 24-08-2025

# Get in right directory

# Get up to date
Already up to date.

# Run main file
Done


16:35 24-08-2025

# Get in right directory

# Get up to date
Already up to date.

# Run main file
Done


17:05 24-08-2025

# Get in right directory

# Get up to date
Already up to date.

# Run main file
Done


17:35 24-08-2025

# Get in right directory

# Get up to date
Already up to date.

# Run main file
Done


18:05 24-08-2025

# Get in right directory

# Get up to date
Already up to date.

# Run main file
Done


18:35 24-08-2025

# Get in right directory

# Get up to date
Already up to date.

# Run main file
Done


19:05 24-08-2025

# Get in right directory

# Get up to date
Already up to date.

# Run main file
Done


19:35 24-08-2025

# Get in right directory

# Get up to date
warning: fetch updated the current branch head.
fast-forwarding your working tree from
commit ab18249c42a5f692e0754997d8036ff8c01efe2b.
error: Your local changes to the following files would be overwritten by merge:
	Logs/Madelief.log
Please commit your changes or stash them before you merge.
Aborting
fatal: Cannot fast-forward your working tree.
After making sure that you saved anything precious from
$ git diff ab18249c42a5f692e0754997d8036ff8c01efe2b
output, run
$ git reset --hard
to recover.

# Run main file
Done


20:05 24-08-2025

# Get in right directory

# Get up to date
Already up to date.

# Run main file
Done


20:35 24-08-2025

# Get in right directory

# Get up to date
Already up to date.

# Run main file
Done


21:14 24-08-2025

# Get in right directory

# Get up to date
Already up to date.

# Run main file
Done


21:35 24-08-2025

# Get in right directory

# Get up to date
Already up to date.

# Run main file
Done


22:05 24-08-2025

# Get in right directory

# Get up to date
Already up to date.

# Run main file
Traceback (most recent call last):
  File "/usr/lib/python3/dist-packages/urllib3/connection.py", line 169, in _new_conn
    conn = connection.create_connection(
  File "/usr/lib/python3/dist-packages/urllib3/util/connection.py", line 73, in create_connection
    for res in socket.getaddrinfo(host, port, family, socket.SOCK_STREAM):
  File "/usr/lib/python3.9/socket.py", line 953, in getaddrinfo
    for res in _socket.getaddrinfo(host, port, family, type, proto, flags):
socket.gaierror: [Errno -3] Temporary failure in name resolution

During handling of the above exception, another exception occurred:

Traceback (most recent call last):
  File "/usr/lib/python3/dist-packages/urllib3/connectionpool.py", line 700, in urlopen
    httplib_response = self._make_request(
  File "/usr/lib/python3/dist-packages/urllib3/connectionpool.py", line 383, in _make_request
    self._validate_conn(conn)
  File "/usr/lib/python3/dist-packages/urllib3/connectionpool.py", line 1017, in _validate_conn
    conn.connect()
  File "/usr/lib/python3/dist-packages/urllib3/connection.py", line 353, in connect
    conn = self._new_conn()
  File "/usr/lib/python3/dist-packages/urllib3/connection.py", line 181, in _new_conn
    raise NewConnectionError(
urllib3.exceptions.NewConnectionError: <urllib3.connection.HTTPSConnection object at 0xb5efe250>: Failed to establish a new connection: [Errno -3] Temporary failure in name resolution

During handling of the above exception, another exception occurred:

Traceback (most recent call last):
  File "/usr/lib/python3/dist-packages/requests/adapters.py", line 439, in send
    resp = conn.urlopen(
  File "/usr/lib/python3/dist-packages/urllib3/connectionpool.py", line 756, in urlopen
    retries = retries.increment(
  File "/usr/lib/python3/dist-packages/urllib3/util/retry.py", line 576, in increment
    raise MaxRetryError(_pool, url, error or ResponseError(cause))
urllib3.exceptions.MaxRetryError: HTTPSConnectionPool(host='api.somtoday.nl', port=443): Max retries exceeded with url: /rest/v1/icalendar/stream/58405be0-5611-4aba-be66-9894a1009f12/c5490491-11eb-4aca-a8f1-ea3f58e75d54 (Caused by NewConnectionError('<urllib3.connection.HTTPSConnection object at 0xb5efe250>: Failed to establish a new connection: [Errno -3] Temporary failure in name resolution'))

During handling of the above exception, another exception occurred:

Traceback (most recent call last):
  File "/home/laurens/Somtoday_Agendas/Madelief/main.py", line 22, in <module>
    r = requests.get(url, allow_redirects=True)
  File "/usr/lib/python3/dist-packages/requests/api.py", line 76, in get
    return request('get', url, params=params, **kwargs)
  File "/usr/lib/python3/dist-packages/requests/api.py", line 61, in request
    return session.request(method=method, url=url, **kwargs)
  File "/usr/lib/python3/dist-packages/requests/sessions.py", line 542, in request
    resp = self.send(prep, **send_kwargs)
  File "/usr/lib/python3/dist-packages/requests/sessions.py", line 655, in send
    r = adapter.send(request, **kwargs)
  File "/usr/lib/python3/dist-packages/requests/adapters.py", line 516, in send
    raise ConnectionError(e, request=request)
requests.exceptions.ConnectionError: HTTPSConnectionPool(host='api.somtoday.nl', port=443): Max retries exceeded with url: /rest/v1/icalendar/stream/58405be0-5611-4aba-be66-9894a1009f12/c5490491-11eb-4aca-a8f1-ea3f58e75d54 (Caused by NewConnectionError('<urllib3.connection.HTTPSConnection object at 0xb5efe250>: Failed to establish a new connection: [Errno -3] Temporary failure in name resolution'))
Done


